Workbook

Sheet Annahmen
A1: LADEKLAR – Finanzmodell: Annahmen
A2: Alle Beträge netto in Euro (zzgl. 19 % USt.). Blaue Schrift auf gelbem Grund = Eingabe/Annahme; schwarze Zellen = Formel. Monat 1 = Startmonat (siehe unten). Stand 16.10.2026.
A3: Legende: | B3: Eingabe | C3: Formel
A5: A Allgemein | B5: Wert | C5: Einheit | G5: Quelle / Begründung
A6: Startmonat des Modells (Monat 1) | B6: 46388 | C6: Datum | G6: Annahme: Pilotphase Nov./Dez. 2026, regulärer Verkaufsstart Januar 2027
A7: Zahlende Pilotkunden zum Start | B7: 5 | C7: Kunden | G7: Annahme: 5 Pilotbetriebe aus der Testphase Q4/2026 wandeln zum 01.01.2027 um
A9: B Preise (lt. PLAN.md, netto je Monat) | B9: Wert | C9: Einheit | G9: Quelle / Begründung
A10: Tarif Start | B10: 49 | C10: €/Monat | G10: PLAN.md Kap. 6: 3 Fahrer, 6 Fahrzeuge, 1 Disponent
A11: Tarif Flotte | B11: 129 | C11: €/Monat | G11: PLAN.md Kap. 6: 15 Fahrer, 40 Fahrzeuge, 5 Disponenten
A12: Tarif Premium | B12: 299 | C12: €/Monat | G12: PLAN.md Kap. 6: 40 Fahrer, unbegrenzt Fahrzeuge/Disponenten, API, SLA
A13: Zusatzfahrer Flotte | B13: 7 | C13: €/Fahrer/Monat | G13: PLAN.md Kap. 6
A14: Zusatzfahrer Premium | B14: 6 | C14: €/Fahrer/Monat | G14: PLAN.md Kap. 6
A15: White-Label-Store-App: Einrichtung | B15: 1990 | C15: € einmalig | G15: PLAN.md Kap. 6 (Premium-Zusatz)
A16: White-Label-Store-App: laufend | B16: 99 | C16: €/Monat | G16: PLAN.md Kap. 6 (Premium-Zusatz)
A18: C Tarifmix der Neukunden und Nutzung | B18: Wert | C18: Einheit | G18: Quelle / Begründung
A19: Anteil Start an Neukunden | B19: 0.5 | C19: % | G19: Annahme; 53 % der Betriebe haben 1–3 Fahrzeuge (BAG-Strukturbericht), digitale Tools werden von größeren Betrieben eher gekauft
A20: Anteil Flotte an Neukunden | B20: 0.38 | C20: % | G20: Annahme; 30 % der Betriebe haben 4–10 Fahrzeuge (BAG-Strukturbericht)
A21: Anteil Premium an Neukunden | B21: =1-B19-B20 -> 0.12 | C21: % | G21: Rest auf 100 %
A22: Ø Zusatzfahrer je Flotte-Kunde | B22: 1.5 | C22: Fahrer | G22: Annahme (Flotte enthält 15 Fahrer; nur ein Teil der Kunden liegt darüber)
A23: Ø Zusatzfahrer je Premium-Kunde | B23: 5 | C23: Fahrer | G23: Annahme (Premium enthält 40 Fahrer)
A24: Store-App-Quote (Anteil neuer Premium-Kunden) | B24: 0.2 | C24: % | G24: Annahme
A25: Anteil Jahreszahler | B25: 0.3 | C25: % | G25: Annahme; Jahreszahlung = 2 Monate geschenkt (PLAN.md)
A26: Geschenkte Monate bei Jahreszahlung | B26: 2 | C26: Monate | G26: PLAN.md Kap. 6
A27: Effektiver Rabatt auf den MRR | B27: =B25*B26/12 -> 0.05 | C27: % | G27: Formel: Anteil Jahreszahler × 2/12. Vorauszahlungen der Jahreszahler werden konservativ NICHT als Liquiditätsvorteil gerechnet
A28: Umwandlung Test (30 Tage) → zahlend | B28: 0.35 | C28: % | G28: Annahme; nur zur Berechnung der nötigen Testzugänge
A30: D Kündigungen (Churn) je Monat | B30: Wert | C30: Einheit | G30: Quelle / Begründung
A31: Churn Start | B31: 0.03 | C31: % je Monat | G31: Annahme; SMB-SaaS 3–7 % je Monat (Vena Solutions 2025), entspricht ca. 31 % p. a.
A32: Churn Flotte | B32: 0.02 | C32: % je Monat | G32: Annahme; ca. 22 % p. a.
A33: Churn Premium | B33: 0.012 | C33: % je Monat | G33: Annahme; ca. 13 % p. a.
A35: E Neue zahlende Kunden je Monat (nach 30-Tage-Test) | B35: Wert | C35: Einheit | G35: Quelle / Begründung
A36: Jahr 1 (2027), Quartal 1: Neukunden je Monat | B36: 3 | C36: Kunden/Monat | G36: Annahme; Jahr 1 gründergetriebener Vertrieb, ab Jahr 2 Partner und Vertriebsteam
A37: Jahr 1 (2027), Quartal 2: Neukunden je Monat | B37: 6 | C37: Kunden/Monat | G37: Annahme
A38: Jahr 1 (2027), Quartal 3: Neukunden je Monat | B38: 9 | C38: Kunden/Monat | G38: Annahme
A39: Jahr 1 (2027), Quartal 4: Neukunden je Monat | B39: 12 | C39: Kunden/Monat | G39: Annahme
A40: Jahr 2 (2028), Quartal 1: Neukunden je Monat | B40: 16 | C40: Kunden/Monat | G40: Annahme
A41: Jahr 2 (2028), Quartal 2: Neukunden je Monat | B41: 20 | C41: Kunden/Monat | G41: Annahme
A42: Jahr 2 (2028), Quartal 3: Neukunden je Monat | B42: 24 | C42: Kunden/Monat | G42: Annahme
A43: Jahr 2 (2028), Quartal 4: Neukunden je Monat | B43: 28 | C43: Kunden/Monat | G43: Annahme
A44: Jahr 3 (2029), Quartal 1: Neukunden je Monat | B44: 30 | C44: Kunden/Monat | G44: Annahme
A45: Jahr 3 (2029), Quartal 2: Neukunden je Monat | B45: 33 | C45: Kunden/Monat | G45: Annahme
...

Sheet Monat 1–36
A1: LADEKLAR – Monatsplan Monat 1–36 | B1: Anfang
A2: Monat-Nr. | B2: 0 | C2: =B2+1 -> 1 | D2: =C2+1 -> 2 | E2: =D2+1 -> 3 | F2: =E2+1 -> 4 | G2: =F2+1 -> 5 | H2: =G2+1 -> 6 | I2: =H2+1 -> 7 | J2: =I2+1 -> 8 | ... AL2: =AK2+1 -> 36
A3: Monat | C3: =EDATE(Annahmen!$B$6,C$2-1) -> 46388 | D3: =EDATE(Annahmen!$B$6,D$2-1) -> 46419 | E3: =EDATE(Annahmen!$B$6,E$2-1) -> 46447 | F3: =EDATE(Annahmen!$B$6,F$2-1) -> 46478 | G3: =EDATE(Annahmen!$B$6,G$2-1) -> 46508 | H3: =EDATE(Annahmen!$B$6,H$2-1) -> 46539 | I3: =EDATE(Annahmen!$B$6,I$2-1) -> 46569 | J3: =EDATE(Annahmen!$B$6,J$2-1) -> 46600 | ... AL3: =EDATE(Annahmen!$B$6,AL$2-1) -> 47453
A4: Modelljahr | C4: =INT((C$2-1)/12)+1 -> 1 | D4: =INT((D$2-1)/12)+1 -> 1 | E4: =INT((E$2-1)/12)+1 -> 1 | F4: =INT((F$2-1)/12)+1 -> 1 | G4: =INT((G$2-1)/12)+1 -> 1 | H4: =INT((H$2-1)/12)+1 -> 1 | I4: =INT((I$2-1)/12)+1 -> 1 | J4: =INT((J$2-1)/12)+1 -> 1 | ... AL4: =INT((AL$2-1)/12)+1 -> 3
A5: Kunden
A6: Neukunden zahlend | C6: =IF(C$2<=36,INDEX(Annahmen!$B$36:$B$47,INT((C$2-1)/3)+1,1),IF(C$2<=48,Annahmen!$B$48,Annahmen!$B$49)) -> 3 | D6: =IF(D$2<=36,INDEX(Annahmen!$B$36:$B$47,INT((D$2-1)/3)+1,1),IF(D$2<=48,Annahmen!$B$48,Annahmen!$B$49)) -> 3 | E6: =IF(E$2<=36,INDEX(Annahmen!$B$36:$B$47,INT((E$2-1)/3)+1,1),IF(E$2<=48,Annahmen!$B$48,Annahmen!$B$49)) -> 3 | F6: =IF(F$2<=36,INDEX(Annahmen!$B$36:$B$47,INT((F$2-1)/3)+1,1),IF(F$2<=48,Annahmen!$B$48,Annahmen!$B$49)) -> 6 | G6: =IF(G$2<=36,INDEX(Annahmen!$B$36:$B$47,INT((G$2-1)/3)+1,1),IF(G$2<=48,Annahmen!$B$48,Annahmen!$B$49)) -> 6 | H6: =IF(H$2<=36,INDEX(Annahmen!$B$36:$B$47,INT((H$2-1)/3)+1,1),IF(H$2<=48,Annahmen!$B$48,Annahmen!$B$49)) -> 6 | I6: =IF(I$2<=36,INDEX(Annahmen!$B$36:$B$47,INT((I$2-1)/3)+1,1),IF(I$2<=48,Annahmen!$B$48,Annahmen!$B$49)) -> 9 | J6: =IF(J$2<=36,INDEX(Annahmen!$B$36:$B$47,INT((J$2-1)/3)+1,1),IF(J$2<=48,Annahmen!$B$48,Annahmen!$B$49)) -> 9 | ... AL6: =IF(AL$2<=36,INDEX(Annahmen!$B$36:$B$47,INT((AL$2-1)/3)+1,1),IF(AL$2<=48,Annahmen!$B$48,Annahmen!$B$49)) -> 40
A7: davon Start | C7: =C6*Annahmen!$B$19 -> 1.5 | D7: =D6*Annahmen!$B$19 -> 1.5 | E7: =E6*Annahmen!$B$19 -> 1.5 | F7: =F6*Annahmen!$B$19 -> 3 | G7: =G6*Annahmen!$B$19 -> 3 | H7: =H6*Annahmen!$B$19 -> 3 | I7: =I6*Annahmen!$B$19 -> 4.5 | J7: =J6*Annahmen!$B$19 -> 4.5 | ... AL7: =AL6*Annahmen!$B$19 -> 20
A8: davon Flotte | C8: =C6*Annahmen!$B$20 -> 1.14 | D8: =D6*Annahmen!$B$20 -> 1.14 | E8: =E6*Annahmen!$B$20 -> 1.14 | F8: =F6*Annahmen!$B$20 -> 2.28 | G8: =G6*Annahmen!$B$20 -> 2.28 | H8: =H6*Annahmen!$B$20 -> 2.28 | I8: =I6*Annahmen!$B$20 -> 3.42 | J8: =J6*Annahmen!$B$20 -> 3.42 | ... AL8: =AL6*Annahmen!$B$20 -> 15.2
A9: davon Premium | C9: =C6*Annahmen!$B$21 -> 0.36 | D9: =D6*Annahmen!$B$21 -> 0.36 | E9: =E6*Annahmen!$B$21 -> 0.36 | F9: =F6*Annahmen!$B$21 -> 0.72 | G9: =G6*Annahmen!$B$21 -> 0.72 | H9: =H6*Annahmen!$B$21 -> 0.72 | I9: =I6*Annahmen!$B$21 -> 1.08 | J9: =J6*Annahmen!$B$21 -> 1.08 | ... AL9: =AL6*Annahmen!$B$21 -> 4.8
A10: Kunden Start (Monatsende) | B10: =Annahmen!$B$7*Annahmen!$B$19 -> 2.5 | C10: =B10*(1-Annahmen!$B$31)+C7 -> 3.925 | D10: =C10*(1-Annahmen!$B$31)+D7 -> 5.30725 | E10: =D10*(1-Annahmen!$B$31)+E7 -> 6.6480325 | F10: =E10*(1-Annahmen!$B$31)+F7 -> 9.4485915 | G10: =F10*(1-Annahmen!$B$31)+G7 -> 12.165134 | H10: =G10*(1-Annahmen!$B$31)+H7 -> 14.80018 | I10: =H10*(1-Annahmen!$B$31)+I7 -> 18.856174 | J10: =I10*(1-Annahmen!$B$31)+J7 -> 22.790489 | ... AL10: =AK10*(1-Annahmen!$B$31)+AL7 -> 278.84198
A11: Kunden Flotte (Monatsende) | B11: =Annahmen!$B$7*Annahmen!$B$20 -> 1.9 | C11: =B11*(1-Annahmen!$B$32)+C8 -> 3.002 | D11: =C11*(1-Annahmen!$B$32)+D8 -> 4.08196 | E11: =D11*(1-Annahmen!$B$32)+E8 -> 5.1403208 | F11: =E11*(1-Annahmen!$B$32)+F8 -> 7.3175144 | G11: =F11*(1-Annahmen!$B$32)+G8 -> 9.4511641 | H11: =G11*(1-Annahmen!$B$32)+H8 -> 11.542141 | I11: =H11*(1-Annahmen!$B$32)+I8 -> 14.731298 | J11: =I11*(1-Annahmen!$B$32)+J8 -> 17.856672 | ... AL11: =AK11*(1-Annahmen!$B$32)+AL8 -> 235.13214
A12: Kunden Premium (Monatsende) | B12: =Annahmen!$B$7*Annahmen!$B$21 -> 0.6 | C12: =B12*(1-Annahmen!$B$33)+C9 -> 0.9528 | D12: =C12*(1-Annahmen!$B$33)+D9 -> 1.3013664 | E12: =D12*(1-Annahmen!$B$33)+E9 -> 1.64575 | F12: =E12*(1-Annahmen!$B$33)+F9 -> 2.346001 | G12: =F12*(1-Annahmen!$B$33)+G9 -> 3.037849 | H12: =G12*(1-Annahmen!$B$33)+H9 -> 3.7213948 | I12: =H12*(1-Annahmen!$B$33)+I9 -> 4.7567381 | J12: =I12*(1-Annahmen!$B$33)+J9 -> 5.7796572 | ... AL12: =AK12*(1-Annahmen!$B$33)+AL9 -> 81.043962
A13: Kunden gesamt | B13: =B10+B11+B12 -> 5 | C13: =C10+C11+C12 -> 7.8798 | D13: =D10+D11+D12 -> 10.690576 | E13: =E10+E11+E12 -> 13.434103 | F13: =F10+F11+F12 -> 19.112107 | G13: =G10+G11+G12 -> 24.654147 | H13: =H10+H11+H12 -> 30.063715 | I13: =I10+I11+I12 -> 38.34421 | ... AL13: =AL10+AL11+AL12 -> 595.01808
A14: Kündigungen im Monat | C14: =B10*Annahmen!$B$31+B11*Annahmen!$B$32+B12*Annahmen!$B$33 -> 0.1202 | D14: =C10*Annahmen!$B$31+C11*Annahmen!$B$32+C12*Annahmen!$B$33 -> 0.1892236 | E14: =D10*Annahmen!$B$31+D11*Annahmen!$B$32+D12*Annahmen!$B$33 -> 0.2564731 | F14: =E10*Annahmen!$B$31+E11*Annahmen!$B$32+E12*Annahmen!$B$33 -> 0.32199639 | G14: =F10*Annahmen!$B$31+F11*Annahmen!$B$32+F12*Annahmen!$B$33 -> 0.45796005 | H14: =G10*Annahmen!$B$31+G11*Annahmen!$B$32+G12*Annahmen!$B$33 -> 0.59043148 | I14: =H10*Annahmen!$B$31+H11*Annahmen!$B$32+H12*Annahmen!$B$33 -> 0.71950495 | J14: =I10*Annahmen!$B$31+I11*Annahmen!$B$32+I12*Annahmen!$B$33 -> 0.91739205 | ... AL14: =AK10*Annahmen!$B$31+AK11*Annahmen!$B$32+AK12*Annahmen!$B$33 -> 13.419873
A15: Neue Store-Apps | C15: =C9*Annahmen!$B$24 -> 0.072 | D15: =D9*Annahmen!$B$24 -> 0.072 | E15: =E9*Annahmen!$B$24 -> 0.072 | F15: =F9*Annahmen!$B$24 -> 0.144 | G15: =G9*Annahmen!$B$24 -> 0.144 | H15: =H9*Annahmen!$B$24 -> 0.144 | I15: =I9*Annahmen!$B$24 -> 0.216 | J15: =J9*Annahmen!$B$24 -> 0.216 | ... AL15: =AL9*Annahmen!$B$24 -> 0.96
A16: Store-Apps aktiv | B16: =Annahmen!$B$7*Annahmen!$B$21*Annahmen!$B$24 -> 0.12 | C16: =B16*(1-Annahmen!$B$33)+C15 -> 0.19056 | D16: =C16*(1-Annahmen!$B$33)+D15 -> 0.26027328 | E16: =D16*(1-Annahmen!$B$33)+E15 -> 0.32915 | F16: =E16*(1-Annahmen!$B$33)+F15 -> 0.4692002 | G16: =F16*(1-Annahmen!$B$33)+G15 -> 0.6075698 | H16: =G16*(1-Annahmen!$B$33)+H15 -> 0.74427896 | I16: =H16*(1-Annahmen!$B$33)+I15 -> 0.95134761 | J16: =I16*(1-Annahmen!$B$33)+J15 -> 1.1559314 | ... AL16: =AK16*(1-Annahmen!$B$33)+AL15 -> 16.208792
A17: Nötige Testzugänge (Info) | C17: =C6/Annahmen!$B$28 -> 8.5714286 | D17: =D6/Annahmen!$B$28 -> 8.5714286 | E17: =E6/Annahmen!$B$28 -> 8.5714286 | F17: =F6/Annahmen!$B$28 -> 17.142857 | G17: =G6/Annahmen!$B$28 -> 17.142857 | H17: =H6/Annahmen!$B$28 -> 17.142857 | I17: =I6/Annahmen!$B$28 -> 25.714286 | J17: =J6/Annahmen!$B$28 -> 25.714286 | ... AL17: =AL6/Annahmen!$B$28 -> 114.28571
A18: Umsatz
A19: MRR Start | C19: =C10*Annahmen!$B$10 -> 192.325 | D19: =D10*Annahmen!$B$10 -> 260.05525 | E19: =E10*Annahmen!$B$10 -> 325.75359 | F19: =F10*Annahmen!$B$10 -> 462.98098 | G19: =G10*Annahmen!$B$10 -> 596.09156 | H19: =H10*Annahmen!$B$10 -> 725.20881 | I19: =I10*Annahmen!$B$10 -> 923.95254 | J19: =J10*Annahmen!$B$10 -> 1116.734 | ... AL19: =AL10*Annahmen!$B$10 -> 13663.257
A20: MRR Flotte inkl. Zusatzfahrer | C20: =C11*(Annahmen!$B$11+Annahmen!$B$13*Annahmen!$B$22) -> 418.779 | D20: =D11*(Annahmen!$B$11+Annahmen!$B$13*Annahmen!$B$22) -> 569.43342 | E20: =E11*(Annahmen!$B$11+Annahmen!$B$13*Annahmen!$B$22) -> 717.07475 | F20: =F11*(Annahmen!$B$11+Annahmen!$B$13*Annahmen!$B$22) -> 1020.7933 | G20: =G11*(Annahmen!$B$11+Annahmen!$B$13*Annahmen!$B$22) -> 1318.4374 | H20: =H11*(Annahmen!$B$11+Annahmen!$B$13*Annahmen!$B$22) -> 1610.1286 | I20: =I11*(Annahmen!$B$11+Annahmen!$B$13*Annahmen!$B$22) -> 2055.0161 | J20: =J11*(Annahmen!$B$11+Annahmen!$B$13*Annahmen!$B$22) -> 2491.0057 | ... AL20: =AL11*(Annahmen!$B$11+Annahmen!$B$13*Annahmen!$B$22) -> 32800.933
A21: MRR Premium inkl. Zusatzfahrer | C21: =C12*(Annahmen!$B$12+Annahmen!$B$14*Annahmen!$B$23) -> 313.4712 | D21: =D12*(Annahmen!$B$12+Annahmen!$B$14*Annahmen!$B$23) -> 428.14955 | E21: =E12*(Annahmen!$B$12+Annahmen!$B$14*Annahmen!$B$23) -> 541.45175 | F21: =F12*(Annahmen!$B$12+Annahmen!$B$14*Annahmen!$B$23) -> 771.83433 | G21: =G12*(Annahmen!$B$12+Annahmen!$B$14*Annahmen!$B$23) -> 999.45232 | H21: =H12*(Annahmen!$B$12+Annahmen!$B$14*Annahmen!$B$23) -> 1224.3389 | I21: =I12*(Annahmen!$B$12+Annahmen!$B$14*Annahmen!$B$23) -> 1564.9668 | J21: =J12*(Annahmen!$B$12+Annahmen!$B$14*Annahmen!$B$23) -> 1901.5072 | ... AL21: =AL12*(Annahmen!$B$12+Annahmen!$B$14*Annahmen!$B$23) -> 26663.464
A22: MRR Store-App | C22: =C16*Annahmen!$B$16 -> 18.86544 | D22: =D16*Annahmen!$B$16 -> 25.767055 | E22: =E16*Annahmen!$B$16 -> 32.58585 | F22: =F16*Annahmen!$B$16 -> 46.45082 | G22: =G16*Annahmen!$B$16 -> 60.14941 | H22: =H16*Annahmen!$B$16 -> 73.683617 | I22: =I16*Annahmen!$B$16 -> 94.183414 | J22: =J16*Annahmen!$B$16 -> 114.43721 | ... AL22: =AL16*Annahmen!$B$16 -> 1604.6704
A23: MRR gesamt (Listenpreis) | C23: =SUM(C19:C22) -> 943.44064 | D23: =SUM(D19:D22) -> 1283.4053 | E23: =SUM(E19:E22) -> 1616.8659 | F23: =SUM(F19:F22) -> 2302.0594 | G23: =SUM(G19:G22) -> 2974.1307 | H23: =SUM(H19:H22) -> 3633.36 | I23: =SUM(I19:I22) -> 4638.1189 | J23: =SUM(J19:J22) -> 5623.6842 | ... AL23: =SUM(AL19:AL22) -> 74732.324
A24: Rabatt Jahreszahler | C24: =-C23*Annahmen!$B$27 -> -47.172032 | D24: =-D23*Annahmen!$B$27 -> -64.170264 | E24: =-E23*Annahmen!$B$27 -> -80.843297 | F24: =-F23*Annahmen!$B$27 -> -115.10297 | G24: =-G23*Annahmen!$B$27 -> -148.70653 | H24: =-H23*Annahmen!$B$27 -> -181.668 | I24: =-I23*Annahmen!$B$27 -> -231.90594 | J24: =-J23*Annahmen!$B$27 -> -281.18421 | ... AL24: =-AL23*Annahmen!$B$27 -> -3736.6162
A25: Einrichtung Store-App (einmalig) | C25: =C15*Annahmen!$B$15 -> 143.28 | D25: =D15*Annahmen!$B$15 -> 143.28 | E25: =E15*Annahmen!$B$15 -> 143.28 | F25: =F15*Annahmen!$B$15 -> 286.56 | G25: =G15*Annahmen!$B$15 -> 286.56 | H25: =H15*Annahmen!$B$15 -> 286.56 | I25: =I15*Annahmen!$B$15 -> 429.84 | J25: =J15*Annahmen!$B$15 -> 429.84 | ... AL25: =AL15*Annahmen!$B$15 -> 1910.4
A26: Umsatz gesamt | C26: =C23+C24+C25 -> 1039.5486 | D26: =D23+D24+D25 -> 1362.515 | E26: =E23+E24+E25 -> 1679.3026 | F26: =F23+F24+F25 -> 2473.5164 | G26: =G23+G24+G25 -> 3111.9841 | H26: =H23+H24+H25 -> 3738.252 | I26: =I23+I24+I25 -> 4836.0529 | J26: =J23+J24+J25 -> 5772.3399 | ... AL26: =AL23+AL24+AL25 -> 72906.108
A27: ARR (MRR × 12) | C27: =C23*12 -> 11321.288 | D27: =D23*12 -> 15400.863 | E27: =E23*12 -> 19402.391 | F27: =F23*12 -> 27624.713 | G27: =G23*12 -> 35689.568 | H27: =H23*12 -> 43600.32 | I27: =I23*12 -> 55657.426 | J27: =J23*12 -> 67484.21 | ... AL27: =AL23*12 -> 896787.89
A28: ARPA (MRR je Kunde) | C28: =IF(C13>0,C23/C13,0) -> 119.72901 | D28: =IF(D13>0,D23/D13,0) -> 120.05015 | E28: =IF(E13>0,E23/E13,0) -> 120.35533 | F28: =IF(F13>0,F23/F13,0) -> 120.45032 | G28: =IF(G13>0,G23/G13,0) -> 120.63409 | H28: =IF(H13>0,H23/H13,0) -> 120.85532 | I28: =IF(I13>0,I23/I13,0) -> 120.96008 | J28: =IF(J13>0,J23/J13,0) -> 121.13008 | ... AL28: =IF(AL13>0,AL23/AL13,0) -> 125.59673
A29: Variable Kosten
A30: Hosting/Speicher variabel | C30: =C10*Annahmen!$B$52+C11*Annahmen!$B$53+C12*Annahmen!$B$54 -> 13.908 | D30: =D10*Annahmen!$B$52+D11*Annahmen!$B$53+D12*Annahmen!$B$54 -> 18.916552 | E30: =E10*Annahmen!$B$52+E11*Annahmen!$B$53+E12*Annahmen!$B$54 -> 23.827818 | F30: =F10*Annahmen!$B$52+F11*Annahmen!$B$53+F12*Annahmen!$B$54 -> 33.923907 | G30: =G10*Annahmen!$B$52+G11*Annahmen!$B$53+G12*Annahmen!$B$54 -> 43.82368 | H30: =H10*Annahmen!$B$52+H11*Annahmen!$B$53+H12*Annahmen!$B$54 -> 53.531399 | I30: =I10*Annahmen!$B$52+I11*Annahmen!$B$53+I12*Annahmen!$B$54 -> 68.331226 | J30: =J10*Annahmen!$B$52+J11*Annahmen!$B$53+J12*Annahmen!$B$54 -> 82.844021 | ... AL30: =AL10*Annahmen!$B$52+AL11*Annahmen!$B$53+AL12*Annahmen!$B$54 -> 1098.5577
A31: Zahlungsgebühren | C31: =C26*Annahmen!$B$55+C13*Annahmen!$B$56 -> 11.074319 | D31: =D26*Annahmen!$B$55+D13*Annahmen!$B$56 -> 14.641822 | E31: =E26*Annahmen!$B$55+E13*Annahmen!$B$56 -> 18.136357 | F31: =F26*Annahmen!$B$55+F13*Annahmen!$B$56 -> 26.477369 | G31: =G26*Annahmen!$B$55+G13*Annahmen!$B$56 -> 33.524825 | H31: =H26*Annahmen!$B$55+H13*Annahmen!$B$56 -> 40.428316 | I31: =I26*Annahmen!$B$55+I13*Annahmen!$B$56 -> 52.108897 | J31: =J26*Annahmen!$B$55+J13*Annahmen!$B$56 -> 62.428106 | ... AL31: =AL26*Annahmen!$B$55+AL13*Annahmen!$B$56 -> 791.50519
A32: Partnerprovision | C32: =C26*INDEX(Annahmen!$B$58:$F$58,1,C$4)*Annahmen!$B$57 -> 0 | D32: =D26*INDEX(Annahmen!$B$58:$F$58,1,D$4)*Annahmen!$B$57 -> 0 | E32: =E26*INDEX(Annahmen!$B$58:$F$58,1,E$4)*Annahmen!$B$57 -> 0 | F32: =F26*INDEX(Annahmen!$B$58:$F$58,1,F$4)*Annahmen!$B$57 -> 0 | G32: =G26*INDEX(Annahmen!$B$58:$F$58,1,G$4)*Annahmen!$B$57 -> 0 | H32: =H26*INDEX(Annahmen!$B$58:$F$58,1,H$4)*Annahmen!$B$57 -> 0 | I32: =I26*INDEX(Annahmen!$B$58:$F$58,1,I$4)*Annahmen!$B$57 -> 0 | J32: =J26*INDEX(Annahmen!$B$58:$F$58,1,J$4)*Annahmen!$B$57 -> 0 | ... AL32: =AL26*INDEX(Annahmen!$B$58:$F$58,1,AL$4)*Annahmen!$B$57 -> 3645.3054
A33: Fremdkosten Store-App-Einrichtung | C33: =C15*Annahmen!$B$59 -> 10.8 | D33: =D15*Annahmen!$B$59 -> 10.8 | E33: =E15*Annahmen!$B$59 -> 10.8 | F33: =F15*Annahmen!$B$59 -> 21.6 | G33: =G15*Annahmen!$B$59 -> 21.6 | H33: =H15*Annahmen!$B$59 -> 21.6 | I33: =I15*Annahmen!$B$59 -> 32.4 | J33: =J15*Annahmen!$B$59 -> 32.4 | ... AL33: =AL15*Annahmen!$B$59 -> 144
A34: Variable Kosten gesamt | C34: =SUM(C30:C33) -> 35.782319 | D34: =SUM(D30:D33) -> 44.358374 | E34: =SUM(E30:E33) -> 52.764175 | F34: =SUM(F30:F33) -> 82.001276 | G34: =SUM(G30:G33) -> 98.948505 | H34: =SUM(H30:H33) -> 115.55972 | I34: =SUM(I30:I33) -> 152.84012 | J34: =SUM(J30:J33) -> 177.67213 | ... AL34: =SUM(AL30:AL33) -> 5679.3683
A35: Deckungsbeitrag | C35: =C26-C34 -> 1003.7663 | D35: =D26-D34 -> 1318.1566 | E35: =E26-E34 -> 1626.5385 | F35: =F26-F34 -> 2391.5151 | G35: =G26-G34 -> 3013.0356 | H35: =H26-H34 -> 3622.6922 | I35: =I26-I34 -> 4683.2128 | J35: =J26-J34 -> 5594.6678 | ... AL35: =AL26-AL34 -> 67226.74
A36: Personal
A37: Gründer/Geschäftsführer | C37: =INDEX(Annahmen!$B$90:$F$90,1,C$4)*Annahmen!$B$91 -> 2500 | D37: =INDEX(Annahmen!$B$90:$F$90,1,D$4)*Annahmen!$B$91 -> 2500 | E37: =INDEX(Annahmen!$B$90:$F$90,1,E$4)*Annahmen!$B$91 -> 2500 | F37: =INDEX(Annahmen!$B$90:$F$90,1,F$4)*Annahmen!$B$91 -> 2500 | G37: =INDEX(Annahmen!$B$90:$F$90,1,G$4)*Annahmen!$B$91 -> 2500 | H37: =INDEX(Annahmen!$B$90:$F$90,1,H$4)*Annahmen!$B$91 -> 2500 | I37: =INDEX(Annahmen!$B$90:$F$90,1,I$4)*Annahmen!$B$91 -> 2500 | J37: =INDEX(Annahmen!$B$90:$F$90,1,J$4)*Annahmen!$B$91 -> 2500 | ... AL37: =INDEX(Annahmen!$B$90:$F$90,1,AL$4)*Annahmen!$B$91 -> 5500
A38: Vertrieb & Kundenerfolg 1 (mehrsprachig, Ex-Disposition) | C38: =IF(C$2>=Annahmen!$C$94,Annahmen!$D$94*(1+Annahmen!$B$92)^(C$4-1)*Annahmen!$E$94,0) -> 0 | D38: =IF(D$2>=Annahmen!$C$94,Annahmen!$D$94*(1+Annahmen!$B$92)^(D$4-1)*Annahmen!$E$94,0) -> 0 | E38: =IF(E$2>=Annahmen!$C$94,Annahmen!$D$94*(1+Annahmen!$B$92)^(E$4-1)*Annahmen!$E$94,0) -> 0 | F38: =IF(F$2>=Annahmen!$C$94,Annahmen!$D$94*(1+Annahmen!$B$92)^(F$4-1)*Annahmen!$E$94,0) -> 0 | G38: =IF(G$2>=Annahmen!$C$94,Annahmen!$D$94*(1+Annahmen!$B$92)^(G$4-1)*Annahmen!$E$94,0) -> 0 | H38: =IF(H$2>=Annahmen!$C$94,Annahmen!$D$94*(1+Annahmen!$B$92)^(H$4-1)*Annahmen!$E$94,0) -> 0 | I38: =IF(I$2>=Annahmen!$C$94,Annahmen!$D$94*(1+Annahmen!$B$92)^(I$4-1)*Annahmen!$E$94,0) -> 4598 | J38: =IF(J$2>=Annahmen!$C$94,Annahmen!$D$94*(1+Annahmen!$B$92)^(J$4-1)*Annahmen!$E$94,0) -> 4598 | ... AL38: =IF(AL$2>=Annahmen!$C$94,Annahmen!$D$94*(1+Annahmen!$B$92)^(AL$4-1)*Annahmen!$E$94,0) -> 4878.0182
A39: Softwareentwicklung 1 (Full-Stack) | C39: =IF(C$2>=Annahmen!$C$95,Annahmen!$D$95*(1+Annahmen!$B$92)^(C$4-1)*Annahmen!$E$95,0) -> 0 | D39: =IF(D$2>=Annahmen!$C$95,Annahmen!$D$95*(1+Annahmen!$B$92)^(D$4-1)*Annahmen!$E$95,0) -> 0 | E39: =IF(E$2>=Annahmen!$C$95,Annahmen!$D$95*(1+Annahmen!$B$92)^(E$4-1)*Annahmen!$E$95,0) -> 0 | F39: =IF(F$2>=Annahmen!$C$95,Annahmen!$D$95*(1+Annahmen!$B$92)^(F$4-1)*Annahmen!$E$95,0) -> 0 | G39: =IF(G$2>=Annahmen!$C$95,Annahmen!$D$95*(1+Annahmen!$B$92)^(G$4-1)*Annahmen!$E$95,0) -> 0 | H39: =IF(H$2>=Annahmen!$C$95,Annahmen!$D$95*(1+Annahmen!$B$92)^(H$4-1)*Annahmen!$E$95,0) -> 0 | I39: =IF(I$2>=Annahmen!$C$95,Annahmen!$D$95*(1+Annahmen!$B$92)^(I$4-1)*Annahmen!$E$95,0) -> 0 | J39: =IF(J$2>=Annahmen!$C$95,Annahmen!$D$95*(1+Annahmen!$B$92)^(J$4-1)*Annahmen!$E$95,0) -> 0 | ... AL39: =IF(AL$2>=Annahmen!$C$95,Annahmen!$D$95*(1+Annahmen!$B$92)^(AL$4-1)*Annahmen!$E$95,0) -> 6675.1828
A40: Vertrieb 2 / Partnermanagement | C40: =IF(C$2>=Annahmen!$C$96,Annahmen!$D$96*(1+Annahmen!$B$92)^(C$4-1)*Annahmen!$E$96,0) -> 0 | D40: =IF(D$2>=Annahmen!$C$96,Annahmen!$D$96*(1+Annahmen!$B$92)^(D$4-1)*Annahmen!$E$96,0) -> 0 | E40: =IF(E$2>=Annahmen!$C$96,Annahmen!$D$96*(1+Annahmen!$B$92)^(E$4-1)*Annahmen!$E$96,0) -> 0 | F40: =IF(F$2>=Annahmen!$C$96,Annahmen!$D$96*(1+Annahmen!$B$92)^(F$4-1)*Annahmen!$E$96,0) -> 0 | G40: =IF(G$2>=Annahmen!$C$96,Annahmen!$D$96*(1+Annahmen!$B$92)^(G$4-1)*Annahmen!$E$96,0) -> 0 | H40: =IF(H$2>=Annahmen!$C$96,Annahmen!$D$96*(1+Annahmen!$B$92)^(H$4-1)*Annahmen!$E$96,0) -> 0 | I40: =IF(I$2>=Annahmen!$C$96,Annahmen!$D$96*(1+Annahmen!$B$92)^(I$4-1)*Annahmen!$E$96,0) -> 0 | J40: =IF(J$2>=Annahmen!$C$96,Annahmen!$D$96*(1+Annahmen!$B$92)^(J$4-1)*Annahmen!$E$96,0) -> 0 | ... AL40: =IF(AL$2>=Annahmen!$C$96,Annahmen!$D$96*(1+Annahmen!$B$92)^(AL$4-1)*Annahmen!$E$96,0) -> 5391.4938
...

Sheet Monat 37–60
A1: LADEKLAR – Monatsplan Monat 37–60 | B1: Anfang
A2: Monat-Nr. | B2: ='Monat 1–36'!$AL$2 -> 36 | C2: =B2+1 -> 37 | D2: =C2+1 -> 38 | E2: =D2+1 -> 39 | F2: =E2+1 -> 40 | G2: =F2+1 -> 41 | H2: =G2+1 -> 42 | I2: =H2+1 -> 43 | J2: =I2+1 -> 44 | ... Z2: =Y2+1 -> 60
A3: Monat | C3: =EDATE(Annahmen!$B$6,C$2-1) -> 47484 | D3: =EDATE(Annahmen!$B$6,D$2-1) -> 47515 | E3: =EDATE(Annahmen!$B$6,E$2-1) -> 47543 | F3: =EDATE(Annahmen!$B$6,F$2-1) -> 47574 | G3: =EDATE(Annahmen!$B$6,G$2-1) -> 47604 | H3: =EDATE(Annahmen!$B$6,H$2-1) -> 47635 | I3: =EDATE(Annahmen!$B$6,I$2-1) -> 47665 | J3: =EDATE(Annahmen!$B$6,J$2-1) -> 47696 | ... Z3: =EDATE(Annahmen!$B$6,Z$2-1) -> 48183
A4: Modelljahr | C4: =INT((C$2-1)/12)+1 -> 4 | D4: =INT((D$2-1)/12)+1 -> 4 | E4: =INT((E$2-1)/12)+1 -> 4 | F4: =INT((F$2-1)/12)+1 -> 4 | G4: =INT((G$2-1)/12)+1 -> 4 | H4: =INT((H$2-1)/12)+1 -> 4 | I4: =INT((I$2-1)/12)+1 -> 4 | J4: =INT((J$2-1)/12)+1 -> 4 | ... Z4: =INT((Z$2-1)/12)+1 -> 5
A5: Kunden
A6: Neukunden zahlend | C6: =IF(C$2<=36,INDEX(Annahmen!$B$36:$B$47,INT((C$2-1)/3)+1,1),IF(C$2<=48,Annahmen!$B$48,Annahmen!$B$49)) -> 45 | D6: =IF(D$2<=36,INDEX(Annahmen!$B$36:$B$47,INT((D$2-1)/3)+1,1),IF(D$2<=48,Annahmen!$B$48,Annahmen!$B$49)) -> 45 | E6: =IF(E$2<=36,INDEX(Annahmen!$B$36:$B$47,INT((E$2-1)/3)+1,1),IF(E$2<=48,Annahmen!$B$48,Annahmen!$B$49)) -> 45 | F6: =IF(F$2<=36,INDEX(Annahmen!$B$36:$B$47,INT((F$2-1)/3)+1,1),IF(F$2<=48,Annahmen!$B$48,Annahmen!$B$49)) -> 45 | G6: =IF(G$2<=36,INDEX(Annahmen!$B$36:$B$47,INT((G$2-1)/3)+1,1),IF(G$2<=48,Annahmen!$B$48,Annahmen!$B$49)) -> 45 | H6: =IF(H$2<=36,INDEX(Annahmen!$B$36:$B$47,INT((H$2-1)/3)+1,1),IF(H$2<=48,Annahmen!$B$48,Annahmen!$B$49)) -> 45 | I6: =IF(I$2<=36,INDEX(Annahmen!$B$36:$B$47,INT((I$2-1)/3)+1,1),IF(I$2<=48,Annahmen!$B$48,Annahmen!$B$49)) -> 45 | J6: =IF(J$2<=36,INDEX(Annahmen!$B$36:$B$47,INT((J$2-1)/3)+1,1),IF(J$2<=48,Annahmen!$B$48,Annahmen!$B$49)) -> 45 | ... Z6: =IF(Z$2<=36,INDEX(Annahmen!$B$36:$B$47,INT((Z$2-1)/3)+1,1),IF(Z$2<=48,Annahmen!$B$48,Annahmen!$B$49)) -> 55
A7: davon Start | C7: =C6*Annahmen!$B$19 -> 22.5 | D7: =D6*Annahmen!$B$19 -> 22.5 | E7: =E6*Annahmen!$B$19 -> 22.5 | F7: =F6*Annahmen!$B$19 -> 22.5 | G7: =G6*Annahmen!$B$19 -> 22.5 | H7: =H6*Annahmen!$B$19 -> 22.5 | I7: =I6*Annahmen!$B$19 -> 22.5 | J7: =J6*Annahmen!$B$19 -> 22.5 | ... Z7: =Z6*Annahmen!$B$19 -> 27.5
A8: davon Flotte | C8: =C6*Annahmen!$B$20 -> 17.1 | D8: =D6*Annahmen!$B$20 -> 17.1 | E8: =E6*Annahmen!$B$20 -> 17.1 | F8: =F6*Annahmen!$B$20 -> 17.1 | G8: =G6*Annahmen!$B$20 -> 17.1 | H8: =H6*Annahmen!$B$20 -> 17.1 | I8: =I6*Annahmen!$B$20 -> 17.1 | J8: =J6*Annahmen!$B$20 -> 17.1 | ... Z8: =Z6*Annahmen!$B$20 -> 20.9
A9: davon Premium | C9: =C6*Annahmen!$B$21 -> 5.4 | D9: =D6*Annahmen!$B$21 -> 5.4 | E9: =E6*Annahmen!$B$21 -> 5.4 | F9: =F6*Annahmen!$B$21 -> 5.4 | G9: =G6*Annahmen!$B$21 -> 5.4 | H9: =H6*Annahmen!$B$21 -> 5.4 | I9: =I6*Annahmen!$B$21 -> 5.4 | J9: =J6*Annahmen!$B$21 -> 5.4 | ... Z9: =Z6*Annahmen!$B$21 -> 6.6
A10: Kunden Start (Monatsende) | B10: ='Monat 1–36'!$AL$10 -> 278.84198 | C10: =B10*(1-Annahmen!$B$31)+C7 -> 292.97672 | D10: =C10*(1-Annahmen!$B$31)+D7 -> 306.68742 | E10: =D10*(1-Annahmen!$B$31)+E7 -> 319.9868 | F10: =E10*(1-Annahmen!$B$31)+F7 -> 332.88719 | G10: =F10*(1-Annahmen!$B$31)+G7 -> 345.40058 | H10: =G10*(1-Annahmen!$B$31)+H7 -> 357.53856 | I10: =H10*(1-Annahmen!$B$31)+I7 -> 369.3124 | J10: =I10*(1-Annahmen!$B$31)+J7 -> 380.73303 | ... Z10: =Y10*(1-Annahmen!$B$31)+Z7 -> 574.20269
A11: Kunden Flotte (Monatsende) | B11: ='Monat 1–36'!$AL$11 -> 235.13214 | C11: =B11*(1-Annahmen!$B$32)+C8 -> 247.5295 | D11: =C11*(1-Annahmen!$B$32)+D8 -> 259.67891 | E11: =D11*(1-Annahmen!$B$32)+E8 -> 271.58533 | F11: =E11*(1-Annahmen!$B$32)+F8 -> 283.25362 | G11: =F11*(1-Annahmen!$B$32)+G8 -> 294.68855 | H11: =G11*(1-Annahmen!$B$32)+H8 -> 305.89478 | I11: =H11*(1-Annahmen!$B$32)+I8 -> 316.87688 | J11: =I11*(1-Annahmen!$B$32)+J8 -> 327.63935 | ... Z11: =Y11*(1-Annahmen!$B$32)+Z8 -> 514.20138
A12: Kunden Premium (Monatsende) | B12: ='Monat 1–36'!$AL$12 -> 81.043962 | C12: =B12*(1-Annahmen!$B$33)+C9 -> 85.471434 | D12: =C12*(1-Annahmen!$B$33)+D9 -> 89.845777 | E12: =D12*(1-Annahmen!$B$33)+E9 -> 94.167628 | F12: =E12*(1-Annahmen!$B$33)+F9 -> 98.437616 | G12: =F12*(1-Annahmen!$B$33)+G9 -> 102.65637 | H12: =G12*(1-Annahmen!$B$33)+H9 -> 106.82449 | I12: =H12*(1-Annahmen!$B$33)+I9 -> 110.94259 | J12: =I12*(1-Annahmen!$B$33)+J9 -> 115.01128 | ... Z12: =Y12*(1-Annahmen!$B$33)+Z9 -> 187.339
A13: Kunden gesamt | B13: =B10+B11+B12 -> 595.01808 | C13: =C10+C11+C12 -> 625.97765 | D13: =D10+D11+D12 -> 656.2121 | E13: =E10+E11+E12 -> 685.73975 | F13: =F10+F11+F12 -> 714.57843 | G13: =G10+G11+G12 -> 742.74549 | H13: =H10+H11+H12 -> 770.25783 | I13: =I10+I11+I12 -> 797.13188 | ... Z13: =Z10+Z11+Z12 -> 1275.7431
A14: Kündigungen im Monat | C14: =B10*Annahmen!$B$31+B11*Annahmen!$B$32+B12*Annahmen!$B$33 -> 14.04043 | D14: =C10*Annahmen!$B$31+C11*Annahmen!$B$32+C12*Annahmen!$B$33 -> 14.765549 | E14: =D10*Annahmen!$B$31+D11*Annahmen!$B$32+D12*Annahmen!$B$33 -> 15.47235 | F14: =E10*Annahmen!$B$31+E11*Annahmen!$B$32+E12*Annahmen!$B$33 -> 16.161322 | G14: =F10*Annahmen!$B$31+F11*Annahmen!$B$32+F12*Annahmen!$B$33 -> 16.83294 | H14: =G10*Annahmen!$B$31+G11*Annahmen!$B$32+G12*Annahmen!$B$33 -> 17.487665 | I14: =H10*Annahmen!$B$31+H11*Annahmen!$B$32+H12*Annahmen!$B$33 -> 18.125946 | J14: =I10*Annahmen!$B$31+I11*Annahmen!$B$32+I12*Annahmen!$B$33 -> 18.748221 | ... Z14: =Y10*Annahmen!$B$31+Y11*Annahmen!$B$32+Y12*Annahmen!$B$33 -> 29.170916
A15: Neue Store-Apps | C15: =C9*Annahmen!$B$24 -> 1.08 | D15: =D9*Annahmen!$B$24 -> 1.08 | E15: =E9*Annahmen!$B$24 -> 1.08 | F15: =F9*Annahmen!$B$24 -> 1.08 | G15: =G9*Annahmen!$B$24 -> 1.08 | H15: =H9*Annahmen!$B$24 -> 1.08 | I15: =I9*Annahmen!$B$24 -> 1.08 | J15: =J9*Annahmen!$B$24 -> 1.08 | ... Z15: =Z9*Annahmen!$B$24 -> 1.32
A16: Store-Apps aktiv | B16: ='Monat 1–36'!$AL$16 -> 16.208792 | C16: =B16*(1-Annahmen!$B$33)+C15 -> 17.094287 | D16: =C16*(1-Annahmen!$B$33)+D15 -> 17.969155 | E16: =D16*(1-Annahmen!$B$33)+E15 -> 18.833526 | F16: =E16*(1-Annahmen!$B$33)+F15 -> 19.687523 | G16: =F16*(1-Annahmen!$B$33)+G15 -> 20.531273 | H16: =G16*(1-Annahmen!$B$33)+H15 -> 21.364898 | I16: =H16*(1-Annahmen!$B$33)+I15 -> 22.188519 | J16: =I16*(1-Annahmen!$B$33)+J15 -> 23.002257 | ... Z16: =Y16*(1-Annahmen!$B$33)+Z15 -> 37.467799
A17: Nötige Testzugänge (Info) | C17: =C6/Annahmen!$B$28 -> 128.57143 | D17: =D6/Annahmen!$B$28 -> 128.57143 | E17: =E6/Annahmen!$B$28 -> 128.57143 | F17: =F6/Annahmen!$B$28 -> 128.57143 | G17: =G6/Annahmen!$B$28 -> 128.57143 | H17: =H6/Annahmen!$B$28 -> 128.57143 | I17: =I6/Annahmen!$B$28 -> 128.57143 | J17: =J6/Annahmen!$B$28 -> 128.57143 | ... Z17: =Z6/Annahmen!$B$28 -> 157.14286
A18: Umsatz
A19: MRR Start | C19: =C10*Annahmen!$B$10 -> 14355.859 | D19: =D10*Annahmen!$B$10 -> 15027.684 | E19: =E10*Annahmen!$B$10 -> 15679.353 | F19: =F10*Annahmen!$B$10 -> 16311.472 | G19: =G10*Annahmen!$B$10 -> 16924.628 | H19: =H10*Annahmen!$B$10 -> 17519.389 | I19: =I10*Annahmen!$B$10 -> 18096.308 | J19: =J10*Annahmen!$B$10 -> 18655.919 | ... Z19: =Z10*Annahmen!$B$10 -> 28135.932
A20: MRR Flotte inkl. Zusatzfahrer | C20: =C11*(Annahmen!$B$11+Annahmen!$B$13*Annahmen!$B$22) -> 34530.365 | D20: =D11*(Annahmen!$B$11+Annahmen!$B$13*Annahmen!$B$22) -> 36225.207 | E20: =E11*(Annahmen!$B$11+Annahmen!$B$13*Annahmen!$B$22) -> 37886.153 | F20: =F11*(Annahmen!$B$11+Annahmen!$B$13*Annahmen!$B$22) -> 39513.88 | G20: =G11*(Annahmen!$B$11+Annahmen!$B$13*Annahmen!$B$22) -> 41109.053 | H20: =H11*(Annahmen!$B$11+Annahmen!$B$13*Annahmen!$B$22) -> 42672.322 | I20: =I11*(Annahmen!$B$11+Annahmen!$B$13*Annahmen!$B$22) -> 44204.325 | J20: =J11*(Annahmen!$B$11+Annahmen!$B$13*Annahmen!$B$22) -> 45705.689 | ... Z20: =Z11*(Annahmen!$B$11+Annahmen!$B$13*Annahmen!$B$22) -> 71731.093
A21: MRR Premium inkl. Zusatzfahrer | C21: =C12*(Annahmen!$B$12+Annahmen!$B$14*Annahmen!$B$23) -> 28120.102 | D21: =D12*(Annahmen!$B$12+Annahmen!$B$14*Annahmen!$B$23) -> 29559.261 | E21: =E12*(Annahmen!$B$12+Annahmen!$B$14*Annahmen!$B$23) -> 30981.15 | F21: =F12*(Annahmen!$B$12+Annahmen!$B$14*Annahmen!$B$23) -> 32385.976 | G21: =G12*(Annahmen!$B$12+Annahmen!$B$14*Annahmen!$B$23) -> 33773.944 | H21: =H12*(Annahmen!$B$12+Annahmen!$B$14*Annahmen!$B$23) -> 35145.257 | I21: =I12*(Annahmen!$B$12+Annahmen!$B$14*Annahmen!$B$23) -> 36500.114 | J21: =J12*(Annahmen!$B$12+Annahmen!$B$14*Annahmen!$B$23) -> 37838.712 | ... Z21: =Z12*(Annahmen!$B$12+Annahmen!$B$14*Annahmen!$B$23) -> 61634.53
A22: MRR Store-App | C22: =C16*Annahmen!$B$16 -> 1692.3344 | D22: =D16*Annahmen!$B$16 -> 1778.9464 | E22: =E16*Annahmen!$B$16 -> 1864.519 | F22: =F16*Annahmen!$B$16 -> 1949.0648 | G22: =G16*Annahmen!$B$16 -> 2032.596 | H22: =H16*Annahmen!$B$16 -> 2115.1249 | I22: =I16*Annahmen!$B$16 -> 2196.6634 | J22: =J16*Annahmen!$B$16 -> 2277.2234 | ... Z22: =Z16*Annahmen!$B$16 -> 3709.3121
A23: MRR gesamt (Listenpreis) | C23: =SUM(C19:C22) -> 78698.66 | D23: =SUM(D19:D22) -> 82591.098 | E23: =SUM(E19:E22) -> 86411.175 | F23: =SUM(F19:F22) -> 90160.393 | G23: =SUM(G19:G22) -> 93840.221 | H23: =SUM(H19:H22) -> 97452.093 | I23: =SUM(I19:I22) -> 100997.41 | J23: =SUM(J19:J22) -> 104477.54 | ... Z23: =SUM(Z19:Z22) -> 165210.87
A24: Rabatt Jahreszahler | C24: =-C23*Annahmen!$B$27 -> -3934.933 | D24: =-D23*Annahmen!$B$27 -> -4129.5549 | E24: =-E23*Annahmen!$B$27 -> -4320.5587 | F24: =-F23*Annahmen!$B$27 -> -4508.0197 | G24: =-G23*Annahmen!$B$27 -> -4692.0111 | H24: =-H23*Annahmen!$B$27 -> -4872.6046 | I24: =-I23*Annahmen!$B$27 -> -5049.8705 | J24: =-J23*Annahmen!$B$27 -> -5223.8771 | ... Z24: =-Z23*Annahmen!$B$27 -> -8260.5433
A25: Einrichtung Store-App (einmalig) | C25: =C15*Annahmen!$B$15 -> 2149.2 | D25: =D15*Annahmen!$B$15 -> 2149.2 | E25: =E15*Annahmen!$B$15 -> 2149.2 | F25: =F15*Annahmen!$B$15 -> 2149.2 | G25: =G15*Annahmen!$B$15 -> 2149.2 | H25: =H15*Annahmen!$B$15 -> 2149.2 | I25: =I15*Annahmen!$B$15 -> 2149.2 | J25: =J15*Annahmen!$B$15 -> 2149.2 | ... Z25: =Z15*Annahmen!$B$15 -> 2626.8
A26: Umsatz gesamt | C26: =C23+C24+C25 -> 76912.927 | D26: =D23+D24+D25 -> 80610.743 | E26: =E23+E24+E25 -> 84239.816 | F26: =F23+F24+F25 -> 87801.574 | G26: =G23+G24+G25 -> 91297.41 | H26: =H23+H24+H25 -> 94728.688 | I26: =I23+I24+I25 -> 98096.739 | J26: =J23+J24+J25 -> 101402.87 | ... Z26: =Z23+Z24+Z25 -> 159577.12
A27: ARR (MRR × 12) | C27: =C23*12 -> 944383.93 | D27: =D23*12 -> 991093.18 | E27: =E23*12 -> 1036934.1 | F27: =F23*12 -> 1081924.7 | G27: =G23*12 -> 1126082.7 | H27: =H23*12 -> 1169425.1 | I27: =I23*12 -> 1211968.9 | J27: =J23*12 -> 1253730.5 | ... Z27: =Z23*12 -> 1982530.4
A28: ARPA (MRR je Kunde) | C28: =IF(C13>0,C23/C13,0) -> 125.7212 | D28: =IF(D13>0,D23/D13,0) -> 125.86037 | E28: =IF(E13>0,E23/E13,0) -> 126.01162 | F28: =IF(F13>0,F23/F13,0) -> 126.17284 | G28: =IF(G13>0,G23/G13,0) -> 126.34236 | H28: =IF(H13>0,H23/H13,0) -> 126.5188 | I28: =IF(I13>0,I23/I13,0) -> 126.701 | J28: =IF(J13>0,J23/J13,0) -> 126.88805 | ... Z28: =IF(Z13>0,Z23/Z13,0) -> 129.50168
A29: Variable Kosten
A30: Hosting/Speicher variabel | C30: =C10*Annahmen!$B$52+C11*Annahmen!$B$53+C12*Annahmen!$B$54 -> 1156.7975 | D30: =D10*Annahmen!$B$52+D11*Annahmen!$B$53+D12*Annahmen!$B$54 -> 1213.9366 | E30: =E10*Annahmen!$B$52+E11*Annahmen!$B$53+E12*Annahmen!$B$54 -> 1269.9982 | F30: =F10*Annahmen!$B$52+F11*Annahmen!$B$53+F12*Annahmen!$B$54 -> 1325.0051 | G30: =G10*Annahmen!$B$52+G11*Annahmen!$B$53+G12*Annahmen!$B$54 -> 1378.9794 | H30: =H10*Annahmen!$B$52+H11*Annahmen!$B$53+H12*Annahmen!$B$54 -> 1431.9428 | I30: =I10*Annahmen!$B$52+I11*Annahmen!$B$53+I12*Annahmen!$B$54 -> 1483.9167 | J30: =J10*Annahmen!$B$52+J11*Annahmen!$B$53+J12*Annahmen!$B$54 -> 1534.9215 | ... Z30: =Z10*Annahmen!$B$52+Z11*Annahmen!$B$53+Z12*Annahmen!$B$54 -> 2424.4599
A31: Zahlungsgebühren | C31: =C26*Annahmen!$B$55+C13*Annahmen!$B$56 -> 834.3956 | D31: =D26*Annahmen!$B$55+D13*Annahmen!$B$56 -> 874.56018 | E31: =E26*Annahmen!$B$55+E13*Annahmen!$B$56 -> 913.92744 | F31: =F26*Annahmen!$B$55+F13*Annahmen!$B$56 -> 952.51504 | G31: =G26*Annahmen!$B$55+G13*Annahmen!$B$56 -> 990.3402 | H31: =H26*Annahmen!$B$55+H13*Annahmen!$B$56 -> 1027.4197 | I31: =I26*Annahmen!$B$55+I13*Annahmen!$B$56 -> 1063.7701 | J31: =J26*Annahmen!$B$55+J13*Annahmen!$B$56 -> 1099.4072 | ... Z31: =Z26*Annahmen!$B$55+Z13*Annahmen!$B$56 -> 1723.1271
A32: Partnerprovision | C32: =C26*INDEX(Annahmen!$B$58:$F$58,1,C$4)*Annahmen!$B$57 -> 4807.058 | D32: =D26*INDEX(Annahmen!$B$58:$F$58,1,D$4)*Annahmen!$B$57 -> 5038.1715 | E32: =E26*INDEX(Annahmen!$B$58:$F$58,1,E$4)*Annahmen!$B$57 -> 5264.9885 | F32: =F26*INDEX(Annahmen!$B$58:$F$58,1,F$4)*Annahmen!$B$57 -> 5487.5984 | G32: =G26*INDEX(Annahmen!$B$58:$F$58,1,G$4)*Annahmen!$B$57 -> 5706.0881 | H32: =H26*INDEX(Annahmen!$B$58:$F$58,1,H$4)*Annahmen!$B$57 -> 5920.543 | I32: =I26*INDEX(Annahmen!$B$58:$F$58,1,I$4)*Annahmen!$B$57 -> 6131.0462 | J32: =J26*INDEX(Annahmen!$B$58:$F$58,1,J$4)*Annahmen!$B$57 -> 6337.6791 | ... Z32: =Z26*INDEX(Annahmen!$B$58:$F$58,1,Z$4)*Annahmen!$B$57 -> 11968.284
A33: Fremdkosten Store-App-Einrichtung | C33: =C15*Annahmen!$B$59 -> 162 | D33: =D15*Annahmen!$B$59 -> 162 | E33: =E15*Annahmen!$B$59 -> 162 | F33: =F15*Annahmen!$B$59 -> 162 | G33: =G15*Annahmen!$B$59 -> 162 | H33: =H15*Annahmen!$B$59 -> 162 | I33: =I15*Annahmen!$B$59 -> 162 | J33: =J15*Annahmen!$B$59 -> 162 | ... Z33: =Z15*Annahmen!$B$59 -> 198
A34: Variable Kosten gesamt | C34: =SUM(C30:C33) -> 6960.2511 | D34: =SUM(D30:D33) -> 7288.6683 | E34: =SUM(E30:E33) -> 7610.9142 | F34: =SUM(F30:F33) -> 7927.1185 | G34: =SUM(G30:G33) -> 8237.4077 | H34: =SUM(H30:H33) -> 8541.9056 | I34: =SUM(I30:I33) -> 8840.733 | J34: =SUM(J30:J33) -> 9134.0079 | ... Z34: =SUM(Z30:Z33) -> 16313.871
A35: Deckungsbeitrag | C35: =C26-C34 -> 69952.676 | D35: =D26-D34 -> 73322.075 | E35: =E26-E34 -> 76628.902 | F35: =F26-F34 -> 79874.455 | G35: =G26-G34 -> 83060.002 | H35: =H26-H34 -> 86186.782 | I35: =I26-I34 -> 89256.007 | J35: =J26-J34 -> 92268.858 | ... Z35: =Z26-Z34 -> 143263.25
A36: Personal
A37: Gründer/Geschäftsführer | C37: =INDEX(Annahmen!$B$90:$F$90,1,C$4)*Annahmen!$B$91 -> 6500 | D37: =INDEX(Annahmen!$B$90:$F$90,1,D$4)*Annahmen!$B$91 -> 6500 | E37: =INDEX(Annahmen!$B$90:$F$90,1,E$4)*Annahmen!$B$91 -> 6500 | F37: =INDEX(Annahmen!$B$90:$F$90,1,F$4)*Annahmen!$B$91 -> 6500 | G37: =INDEX(Annahmen!$B$90:$F$90,1,G$4)*Annahmen!$B$91 -> 6500 | H37: =INDEX(Annahmen!$B$90:$F$90,1,H$4)*Annahmen!$B$91 -> 6500 | I37: =INDEX(Annahmen!$B$90:$F$90,1,I$4)*Annahmen!$B$91 -> 6500 | J37: =INDEX(Annahmen!$B$90:$F$90,1,J$4)*Annahmen!$B$91 -> 6500 | ... Z37: =INDEX(Annahmen!$B$90:$F$90,1,Z$4)*Annahmen!$B$91 -> 7000
A38: Vertrieb & Kundenerfolg 1 (mehrsprachig, Ex-Disposition) | C38: =IF(C$2>=Annahmen!$C$94,Annahmen!$D$94*(1+Annahmen!$B$92)^(C$4-1)*Annahmen!$E$94,0) -> 5024.3587 | D38: =IF(D$2>=Annahmen!$C$94,Annahmen!$D$94*(1+Annahmen!$B$92)^(D$4-1)*Annahmen!$E$94,0) -> 5024.3587 | E38: =IF(E$2>=Annahmen!$C$94,Annahmen!$D$94*(1+Annahmen!$B$92)^(E$4-1)*Annahmen!$E$94,0) -> 5024.3587 | F38: =IF(F$2>=Annahmen!$C$94,Annahmen!$D$94*(1+Annahmen!$B$92)^(F$4-1)*Annahmen!$E$94,0) -> 5024.3587 | G38: =IF(G$2>=Annahmen!$C$94,Annahmen!$D$94*(1+Annahmen!$B$92)^(G$4-1)*Annahmen!$E$94,0) -> 5024.3587 | H38: =IF(H$2>=Annahmen!$C$94,Annahmen!$D$94*(1+Annahmen!$B$92)^(H$4-1)*Annahmen!$E$94,0) -> 5024.3587 | I38: =IF(I$2>=Annahmen!$C$94,Annahmen!$D$94*(1+Annahmen!$B$92)^(I$4-1)*Annahmen!$E$94,0) -> 5024.3587 | J38: =IF(J$2>=Annahmen!$C$94,Annahmen!$D$94*(1+Annahmen!$B$92)^(J$4-1)*Annahmen!$E$94,0) -> 5024.3587 | ... Z38: =IF(Z$2>=Annahmen!$C$94,Annahmen!$D$94*(1+Annahmen!$B$92)^(Z$4-1)*Annahmen!$E$94,0) -> 5175.0895
A39: Softwareentwicklung 1 (Full-Stack) | C39: =IF(C$2>=Annahmen!$C$95,Annahmen!$D$95*(1+Annahmen!$B$92)^(C$4-1)*Annahmen!$E$95,0) -> 6875.4383 | D39: =IF(D$2>=Annahmen!$C$95,Annahmen!$D$95*(1+Annahmen!$B$92)^(D$4-1)*Annahmen!$E$95,0) -> 6875.4383 | E39: =IF(E$2>=Annahmen!$C$95,Annahmen!$D$95*(1+Annahmen!$B$92)^(E$4-1)*Annahmen!$E$95,0) -> 6875.4383 | F39: =IF(F$2>=Annahmen!$C$95,Annahmen!$D$95*(1+Annahmen!$B$92)^(F$4-1)*Annahmen!$E$95,0) -> 6875.4383 | G39: =IF(G$2>=Annahmen!$C$95,Annahmen!$D$95*(1+Annahmen!$B$92)^(G$4-1)*Annahmen!$E$95,0) -> 6875.4383 | H39: =IF(H$2>=Annahmen!$C$95,Annahmen!$D$95*(1+Annahmen!$B$92)^(H$4-1)*Annahmen!$E$95,0) -> 6875.4383 | I39: =IF(I$2>=Annahmen!$C$95,Annahmen!$D$95*(1+Annahmen!$B$92)^(I$4-1)*Annahmen!$E$95,0) -> 6875.4383 | J39: =IF(J$2>=Annahmen!$C$95,Annahmen!$D$95*(1+Annahmen!$B$92)^(J$4-1)*Annahmen!$E$95,0) -> 6875.4383 | ... Z39: =IF(Z$2>=Annahmen!$C$95,Annahmen!$D$95*(1+Annahmen!$B$92)^(Z$4-1)*Annahmen!$E$95,0) -> 7081.7014
A40: Vertrieb 2 / Partnermanagement | C40: =IF(C$2>=Annahmen!$C$96,Annahmen!$D$96*(1+Annahmen!$B$92)^(C$4-1)*Annahmen!$E$96,0) -> 5553.2386 | D40: =IF(D$2>=Annahmen!$C$96,Annahmen!$D$96*(1+Annahmen!$B$92)^(D$4-1)*Annahmen!$E$96,0) -> 5553.2386 | E40: =IF(E$2>=Annahmen!$C$96,Annahmen!$D$96*(1+Annahmen!$B$92)^(E$4-1)*Annahmen!$E$96,0) -> 5553.2386 | F40: =IF(F$2>=Annahmen!$C$96,Annahmen!$D$96*(1+Annahmen!$B$92)^(F$4-1)*Annahmen!$E$96,0) -> 5553.2386 | G40: =IF(G$2>=Annahmen!$C$96,Annahmen!$D$96*(1+Annahmen!$B$92)^(G$4-1)*Annahmen!$E$96,0) -> 5553.2386 | H40: =IF(H$2>=Annahmen!$C$96,Annahmen!$D$96*(1+Annahmen!$B$92)^(H$4-1)*Annahmen!$E$96,0) -> 5553.2386 | I40: =IF(I$2>=Annahmen!$C$96,Annahmen!$D$96*(1+Annahmen!$B$92)^(I$4-1)*Annahmen!$E$96,0) -> 5553.2386 | J40: =IF(J$2>=Annahmen!$C$96,Annahmen!$D$96*(1+Annahmen!$B$92)^(J$4-1)*Annahmen!$E$96,0) -> 5553.2386 | ... Z40: =IF(Z$2>=Annahmen!$C$96,Annahmen!$D$96*(1+Annahmen!$B$92)^(Z$4-1)*Annahmen!$E$96,0) -> 5719.8358
...

Sheet 5 Jahre
A1: LADEKLAR – GuV-Übersicht 5 Jahre
A3: Kennzahl | B3: Jahr 1 | C3: Jahr 2 | D3: Jahr 3 | E3: Jahr 4 | F3: Jahr 5
A4: Kalenderjahr | B4: =YEAR(Annahmen!$B$6)+0 -> 2027 | C4: =YEAR(Annahmen!$B$6)+1 -> 2028 | D4: =YEAR(Annahmen!$B$6)+2 -> 2029 | E4: =YEAR(Annahmen!$B$6)+3 -> 2030 | F4: =YEAR(Annahmen!$B$6)+4 -> 2031
A5: Modelljahr | B5: 1 | C5: 2 | D5: 3 | E5: 4 | F5: 5
A6: Kunden
A7: Kunden Start (Jahresende) | B7: =IF(B$5<=3,INDEX('Monat 1–36'!$C$10:$AL$10,1,B$5*12),INDEX('Monat 37–60'!$C$10:$Z$10,1,B$5*12-36)) -> 41.748685 | C7: =IF(C$5<=3,INDEX('Monat 1–36'!$C$10:$AL$10,1,C$5*12),INDEX('Monat 37–60'!$C$10:$Z$10,1,C$5*12-36)) -> 143.55064 | D7: =IF(D$5<=3,INDEX('Monat 1–36'!$C$10:$AL$10,1,D$5*12),INDEX('Monat 37–60'!$C$10:$Z$10,1,D$5*12-36)) -> 278.84198 | E7: =IF(E$5<=3,INDEX('Monat 1–36'!$C$10:$AL$10,1,E$5*12),INDEX('Monat 37–60'!$C$10:$Z$10,1,E$5*12-36)) -> 423.09061 | F7: =IF(F$5<=3,INDEX('Monat 1–36'!$C$10:$AL$10,1,F$5*12),INDEX('Monat 37–60'!$C$10:$Z$10,1,F$5*12-36)) -> 574.20269
A8: Kunden Flotte (Jahresende) | B8: =IF(B$5<=3,INDEX('Monat 1–36'!$C$11:$AL$11,1,B$5*12),INDEX('Monat 37–60'!$C$11:$Z$11,1,B$5*12-36)) -> 33.097526 | C8: =IF(C$5<=3,INDEX('Monat 1–36'!$C$11:$AL$11,1,C$5*12),INDEX('Monat 37–60'!$C$11:$Z$11,1,C$5*12-36)) -> 117.19886 | D8: =IF(D$5<=3,INDEX('Monat 1–36'!$C$11:$AL$11,1,D$5*12),INDEX('Monat 37–60'!$C$11:$Z$11,1,D$5*12-36)) -> 235.13214 | E8: =IF(E$5<=3,INDEX('Monat 1–36'!$C$11:$AL$11,1,E$5*12),INDEX('Monat 37–60'!$C$11:$Z$11,1,E$5*12-36)) -> 368.57932 | F8: =IF(F$5<=3,INDEX('Monat 1–36'!$C$11:$AL$11,1,F$5*12),INDEX('Monat 37–60'!$C$11:$Z$11,1,F$5*12-36)) -> 514.20138
A9: Kunden Premium (Jahresende) | B9: =IF(B$5<=3,INDEX('Monat 1–36'!$C$12:$AL$12,1,B$5*12),INDEX('Monat 37–60'!$C$12:$Z$12,1,B$5*12-36)) -> 10.81714 | C9: =IF(C$5<=3,INDEX('Monat 1–36'!$C$12:$AL$12,1,C$5*12),INDEX('Monat 37–60'!$C$12:$Z$12,1,C$5*12-36)) -> 39.272951 | D9: =IF(D$5<=3,INDEX('Monat 1–36'!$C$12:$AL$12,1,D$5*12),INDEX('Monat 37–60'!$C$12:$Z$12,1,D$5*12-36)) -> 81.043962 | E9: =IF(E$5<=3,INDEX('Monat 1–36'!$C$12:$AL$12,1,E$5*12),INDEX('Monat 37–60'!$C$12:$Z$12,1,E$5*12-36)) -> 130.80362 | F9: =IF(F$5<=3,INDEX('Monat 1–36'!$C$12:$AL$12,1,F$5*12),INDEX('Monat 37–60'!$C$12:$Z$12,1,F$5*12-36)) -> 187.339
A10: Kunden gesamt (Jahresende) | B10: =IF(B$5<=3,INDEX('Monat 1–36'!$C$13:$AL$13,1,B$5*12),INDEX('Monat 37–60'!$C$13:$Z$13,1,B$5*12-36)) -> 85.663351 | C10: =IF(C$5<=3,INDEX('Monat 1–36'!$C$13:$AL$13,1,C$5*12),INDEX('Monat 37–60'!$C$13:$Z$13,1,C$5*12-36)) -> 300.02244 | D10: =IF(D$5<=3,INDEX('Monat 1–36'!$C$13:$AL$13,1,D$5*12),INDEX('Monat 37–60'!$C$13:$Z$13,1,D$5*12-36)) -> 595.01808 | E10: =IF(E$5<=3,INDEX('Monat 1–36'!$C$13:$AL$13,1,E$5*12),INDEX('Monat 37–60'!$C$13:$Z$13,1,E$5*12-36)) -> 922.47355 | F10: =IF(F$5<=3,INDEX('Monat 1–36'!$C$13:$AL$13,1,F$5*12),INDEX('Monat 37–60'!$C$13:$Z$13,1,F$5*12-36)) -> 1275.7431
A11: Neukunden im Jahr | B11: =SUMIF('Monat 1–36'!$C$4:$AL$4,B$5,'Monat 1–36'!$C$6:$AL$6)+SUMIF('Monat 37–60'!$C$4:$Z$4,B$5,'Monat 37–60'!$C$6:$Z$6) -> 90 | C11: =SUMIF('Monat 1–36'!$C$4:$AL$4,C$5,'Monat 1–36'!$C$6:$AL$6)+SUMIF('Monat 37–60'!$C$4:$Z$4,C$5,'Monat 37–60'!$C$6:$Z$6) -> 264 | D11: =SUMIF('Monat 1–36'!$C$4:$AL$4,D$5,'Monat 1–36'!$C$6:$AL$6)+SUMIF('Monat 37–60'!$C$4:$Z$4,D$5,'Monat 37–60'!$C$6:$Z$6) -> 417 | E11: =SUMIF('Monat 1–36'!$C$4:$AL$4,E$5,'Monat 1–36'!$C$6:$AL$6)+SUMIF('Monat 37–60'!$C$4:$Z$4,E$5,'Monat 37–60'!$C$6:$Z$6) -> 540 | F11: =SUMIF('Monat 1–36'!$C$4:$AL$4,F$5,'Monat 1–36'!$C$6:$AL$6)+SUMIF('Monat 37–60'!$C$4:$Z$4,F$5,'Monat 37–60'!$C$6:$Z$6) -> 660
A12: Kündigungen im Jahr | B12: =SUMIF('Monat 1–36'!$C$4:$AL$4,B$5,'Monat 1–36'!$C$14:$AL$14)+SUMIF('Monat 37–60'!$C$4:$Z$4,B$5,'Monat 37–60'!$C$14:$Z$14) -> 9.3366494 | C12: =SUMIF('Monat 1–36'!$C$4:$AL$4,C$5,'Monat 1–36'!$C$14:$AL$14)+SUMIF('Monat 37–60'!$C$4:$Z$4,C$5,'Monat 37–60'!$C$14:$Z$14) -> 49.640906 | D12: =SUMIF('Monat 1–36'!$C$4:$AL$4,D$5,'Monat 1–36'!$C$14:$AL$14)+SUMIF('Monat 37–60'!$C$4:$Z$4,D$5,'Monat 37–60'!$C$14:$Z$14) -> 122.00436 | E12: =SUMIF('Monat 1–36'!$C$4:$AL$4,E$5,'Monat 1–36'!$C$14:$AL$14)+SUMIF('Monat 37–60'!$C$4:$Z$4,E$5,'Monat 37–60'!$C$14:$Z$14) -> 212.54453 | F12: =SUMIF('Monat 1–36'!$C$4:$AL$4,F$5,'Monat 1–36'!$C$14:$AL$14)+SUMIF('Monat 37–60'!$C$4:$Z$4,F$5,'Monat 37–60'!$C$14:$Z$14) -> 306.73048
A13: Jahres-Churn (Kündigungen / Ø Kunden) | B13: =IF((B10+'Monat 1–36'!$B$13)>0,B12/((B10+'Monat 1–36'!$B$13)/2),0) -> 0.20596304 | C13: =IF((C10+B10)>0,C12/((C10+B10)/2),0) -> 0.2574163 | D13: =IF((D10+C10)>0,D12/((D10+C10)/2),0) -> 0.2726231 | E13: =IF((E10+D10)>0,E12/((E10+D10)/2),0) -> 0.28012613 | F13: =IF((F10+E10)>0,F12/((F10+E10)/2),0) -> 0.27907212
A14: Store-Apps aktiv (Jahresende) | B14: =IF(B$5<=3,INDEX('Monat 1–36'!$C$16:$AL$16,1,B$5*12),INDEX('Monat 37–60'!$C$16:$Z$16,1,B$5*12-36)) -> 2.1634279 | C14: =IF(C$5<=3,INDEX('Monat 1–36'!$C$16:$AL$16,1,C$5*12),INDEX('Monat 37–60'!$C$16:$Z$16,1,C$5*12-36)) -> 7.8545901 | D14: =IF(D$5<=3,INDEX('Monat 1–36'!$C$16:$AL$16,1,D$5*12),INDEX('Monat 37–60'!$C$16:$Z$16,1,D$5*12-36)) -> 16.208792 | E14: =IF(E$5<=3,INDEX('Monat 1–36'!$C$16:$AL$16,1,E$5*12),INDEX('Monat 37–60'!$C$16:$Z$16,1,E$5*12-36)) -> 26.160724 | F14: =IF(F$5<=3,INDEX('Monat 1–36'!$C$16:$AL$16,1,F$5*12),INDEX('Monat 37–60'!$C$16:$Z$16,1,F$5*12-36)) -> 37.467799
A15: Nötige Testzugänge im Jahr | B15: =SUMIF('Monat 1–36'!$C$4:$AL$4,B$5,'Monat 1–36'!$C$17:$AL$17)+SUMIF('Monat 37–60'!$C$4:$Z$4,B$5,'Monat 37–60'!$C$17:$Z$17) -> 257.14286 | C15: =SUMIF('Monat 1–36'!$C$4:$AL$4,C$5,'Monat 1–36'!$C$17:$AL$17)+SUMIF('Monat 37–60'!$C$4:$Z$4,C$5,'Monat 37–60'!$C$17:$Z$17) -> 754.28571 | D15: =SUMIF('Monat 1–36'!$C$4:$AL$4,D$5,'Monat 1–36'!$C$17:$AL$17)+SUMIF('Monat 37–60'!$C$4:$Z$4,D$5,'Monat 37–60'!$C$17:$Z$17) -> 1191.4286 | E15: =SUMIF('Monat 1–36'!$C$4:$AL$4,E$5,'Monat 1–36'!$C$17:$AL$17)+SUMIF('Monat 37–60'!$C$4:$Z$4,E$5,'Monat 37–60'!$C$17:$Z$17) -> 1542.8571 | F15: =SUMIF('Monat 1–36'!$C$4:$AL$4,F$5,'Monat 1–36'!$C$17:$AL$17)+SUMIF('Monat 37–60'!$C$4:$Z$4,F$5,'Monat 37–60'!$C$17:$Z$17) -> 1885.7143
A16: Umsatz
A17: MRR im Dezember | B17: =IF(B$5<=3,INDEX('Monat 1–36'!$C$23:$AL$23,1,B$5*12),INDEX('Monat 37–60'!$C$23:$Z$23,1,B$5*12-36)) -> 10435.809 | C17: =IF(C$5<=3,INDEX('Monat 1–36'!$C$23:$AL$23,1,C$5*12),INDEX('Monat 37–60'!$C$23:$Z$23,1,C$5*12-36)) -> 37081.627 | D17: =IF(D$5<=3,INDEX('Monat 1–36'!$C$23:$AL$23,1,D$5*12),INDEX('Monat 37–60'!$C$23:$Z$23,1,D$5*12-36)) -> 74732.324 | E17: =IF(E$5<=3,INDEX('Monat 1–36'!$C$23:$AL$23,1,E$5*12),INDEX('Monat 37–60'!$C$23:$Z$23,1,E$5*12-36)) -> 117772.56 | F17: =IF(F$5<=3,INDEX('Monat 1–36'!$C$23:$AL$23,1,F$5*12),INDEX('Monat 37–60'!$C$23:$Z$23,1,F$5*12-36)) -> 165210.87
A18: ARR zum Jahresende (MRR Dez. × 12) | B18: =IF(B$5<=3,INDEX('Monat 1–36'!$C$27:$AL$27,1,B$5*12),INDEX('Monat 37–60'!$C$27:$Z$27,1,B$5*12-36)) -> 125229.7 | C18: =IF(C$5<=3,INDEX('Monat 1–36'!$C$27:$AL$27,1,C$5*12),INDEX('Monat 37–60'!$C$27:$Z$27,1,C$5*12-36)) -> 444979.52 | D18: =IF(D$5<=3,INDEX('Monat 1–36'!$C$27:$AL$27,1,D$5*12),INDEX('Monat 37–60'!$C$27:$Z$27,1,D$5*12-36)) -> 896787.89 | E18: =IF(E$5<=3,INDEX('Monat 1–36'!$C$27:$AL$27,1,E$5*12),INDEX('Monat 37–60'!$C$27:$Z$27,1,E$5*12-36)) -> 1413270.7 | F18: =IF(F$5<=3,INDEX('Monat 1–36'!$C$27:$AL$27,1,F$5*12),INDEX('Monat 37–60'!$C$27:$Z$27,1,F$5*12-36)) -> 1982530.4
A19: ARPA im Dezember | B19: =IF(B$5<=3,INDEX('Monat 1–36'!$C$28:$AL$28,1,B$5*12),INDEX('Monat 37–60'!$C$28:$Z$28,1,B$5*12-36)) -> 121.82349 | C19: =IF(C$5<=3,INDEX('Monat 1–36'!$C$28:$AL$28,1,C$5*12),INDEX('Monat 37–60'!$C$28:$Z$28,1,C$5*12-36)) -> 123.59618 | D19: =IF(D$5<=3,INDEX('Monat 1–36'!$C$28:$AL$28,1,D$5*12),INDEX('Monat 37–60'!$C$28:$Z$28,1,D$5*12-36)) -> 125.59673 | E19: =IF(E$5<=3,INDEX('Monat 1–36'!$C$28:$AL$28,1,E$5*12),INDEX('Monat 37–60'!$C$28:$Z$28,1,E$5*12-36)) -> 127.67039 | F19: =IF(F$5<=3,INDEX('Monat 1–36'!$C$28:$AL$28,1,F$5*12),INDEX('Monat 37–60'!$C$28:$Z$28,1,F$5*12-36)) -> 129.50168
A20: Abo-Umsatz (nach Jahreszahler-Rabatt) | B20: =SUMIF('Monat 1–36'!$C$4:$AL$4,B$5,'Monat 1–36'!$C$23:$AL$23)+SUMIF('Monat 37–60'!$C$4:$Z$4,B$5,'Monat 37–60'!$C$23:$Z$23)+SUMIF('Monat 1–36'!$C$4:$AL$4,B$5,'Monat 1–36'!$C$24:$AL$24)+SUMIF('Monat 37–60'!$C$4:$Z$4,B$5,'Monat 37–60'!$C$24:$Z$24) -> 54261.016 | C20: =SUMIF('Monat 1–36'!$C$4:$AL$4,C$5,'Monat 1–36'!$C$23:$AL$23)+SUMIF('Monat 37–60'!$C$4:$Z$4,C$5,'Monat 37–60'!$C$23:$Z$23)+SUMIF('Monat 1–36'!$C$4:$AL$4,C$5,'Monat 1–36'!$C$24:$AL$24)+SUMIF('Monat 37–60'!$C$4:$Z$4,C$5,'Monat 37–60'!$C$24:$Z$24) -> 268670.4 | D20: =SUMIF('Monat 1–36'!$C$4:$AL$4,D$5,'Monat 1–36'!$C$23:$AL$23)+SUMIF('Monat 37–60'!$C$4:$Z$4,D$5,'Monat 37–60'!$C$23:$Z$23)+SUMIF('Monat 1–36'!$C$4:$AL$4,D$5,'Monat 1–36'!$C$24:$AL$24)+SUMIF('Monat 37–60'!$C$4:$Z$4,D$5,'Monat 37–60'!$C$24:$Z$24) -> 646238.09 | E20: =SUMIF('Monat 1–36'!$C$4:$AL$4,E$5,'Monat 1–36'!$C$23:$AL$23)+SUMIF('Monat 37–60'!$C$4:$Z$4,E$5,'Monat 37–60'!$C$23:$Z$23)+SUMIF('Monat 1–36'!$C$4:$AL$4,E$5,'Monat 1–36'!$C$24:$AL$24)+SUMIF('Monat 37–60'!$C$4:$Z$4,E$5,'Monat 37–60'!$C$24:$Z$24) -> 1126778.5 | F20: =SUMIF('Monat 1–36'!$C$4:$AL$4,F$5,'Monat 1–36'!$C$23:$AL$23)+SUMIF('Monat 37–60'!$C$4:$Z$4,F$5,'Monat 37–60'!$C$23:$Z$23)+SUMIF('Monat 1–36'!$C$4:$AL$4,F$5,'Monat 1–36'!$C$24:$AL$24)+SUMIF('Monat 37–60'!$C$4:$Z$4,F$5,'Monat 37–60'!$C$24:$Z$24) -> 1645421.9
A21: Einrichtung Store-Apps | B21: =SUMIF('Monat 1–36'!$C$4:$AL$4,B$5,'Monat 1–36'!$C$25:$AL$25)+SUMIF('Monat 37–60'!$C$4:$Z$4,B$5,'Monat 37–60'!$C$25:$Z$25) -> 4298.4 | C21: =SUMIF('Monat 1–36'!$C$4:$AL$4,C$5,'Monat 1–36'!$C$25:$AL$25)+SUMIF('Monat 37–60'!$C$4:$Z$4,C$5,'Monat 37–60'!$C$25:$Z$25) -> 12608.64 | D21: =SUMIF('Monat 1–36'!$C$4:$AL$4,D$5,'Monat 1–36'!$C$25:$AL$25)+SUMIF('Monat 37–60'!$C$4:$Z$4,D$5,'Monat 37–60'!$C$25:$Z$25) -> 19915.92 | E21: =SUMIF('Monat 1–36'!$C$4:$AL$4,E$5,'Monat 1–36'!$C$25:$AL$25)+SUMIF('Monat 37–60'!$C$4:$Z$4,E$5,'Monat 37–60'!$C$25:$Z$25) -> 25790.4 | F21: =SUMIF('Monat 1–36'!$C$4:$AL$4,F$5,'Monat 1–36'!$C$25:$AL$25)+SUMIF('Monat 37–60'!$C$4:$Z$4,F$5,'Monat 37–60'!$C$25:$Z$25) -> 31521.6
A22: Umsatz gesamt | B22: =SUMIF('Monat 1–36'!$C$4:$AL$4,B$5,'Monat 1–36'!$C$26:$AL$26)+SUMIF('Monat 37–60'!$C$4:$Z$4,B$5,'Monat 37–60'!$C$26:$Z$26) -> 58559.416 | C22: =SUMIF('Monat 1–36'!$C$4:$AL$4,C$5,'Monat 1–36'!$C$26:$AL$26)+SUMIF('Monat 37–60'!$C$4:$Z$4,C$5,'Monat 37–60'!$C$26:$Z$26) -> 281279.04 | D22: =SUMIF('Monat 1–36'!$C$4:$AL$4,D$5,'Monat 1–36'!$C$26:$AL$26)+SUMIF('Monat 37–60'!$C$4:$Z$4,D$5,'Monat 37–60'!$C$26:$Z$26) -> 666154.01 | E22: =SUMIF('Monat 1–36'!$C$4:$AL$4,E$5,'Monat 1–36'!$C$26:$AL$26)+SUMIF('Monat 37–60'!$C$4:$Z$4,E$5,'Monat 37–60'!$C$26:$Z$26) -> 1152568.9 | F22: =SUMIF('Monat 1–36'!$C$4:$AL$4,F$5,'Monat 1–36'!$C$26:$AL$26)+SUMIF('Monat 37–60'!$C$4:$Z$4,F$5,'Monat 37–60'!$C$26:$Z$26) -> 1676943.5
A23: Umsatzwachstum ggü. Vorjahr | B23: ="–" -> – | C23: =IF(B22>0,C22/B22-1,0) -> 3.8033102 | D23: =IF(C22>0,D22/C22-1,0) -> 1.368303 | E23: =IF(D22>0,E22/D22-1,0) -> 0.73018385 | F23: =IF(E22>0,F22/E22-1,0) -> 0.45496164
A24: Kosten
A25: Variable Kosten | B25: =SUMIF('Monat 1–36'!$C$4:$AL$4,B$5,'Monat 1–36'!$C$34:$AL$34)+SUMIF('Monat 37–60'!$C$4:$Z$4,B$5,'Monat 37–60'!$C$34:$Z$34) -> 1798.7036 | C25: =SUMIF('Monat 1–36'!$C$4:$AL$4,C$5,'Monat 1–36'!$C$34:$AL$34)+SUMIF('Monat 37–60'!$C$4:$Z$4,C$5,'Monat 37–60'!$C$34:$Z$34) -> 15200.294 | D25: =SUMIF('Monat 1–36'!$C$4:$AL$4,D$5,'Monat 1–36'!$C$34:$AL$34)+SUMIF('Monat 37–60'!$C$4:$Z$4,D$5,'Monat 37–60'!$C$34:$Z$34) -> 52049.147 | E25: =SUMIF('Monat 1–36'!$C$4:$AL$4,E$5,'Monat 1–36'!$C$34:$AL$34)+SUMIF('Monat 37–60'!$C$4:$Z$4,E$5,'Monat 37–60'!$C$34:$Z$34) -> 103902.72 | F25: =SUMIF('Monat 1–36'!$C$4:$AL$4,F$5,'Monat 1–36'!$C$34:$AL$34)+SUMIF('Monat 37–60'!$C$4:$Z$4,F$5,'Monat 37–60'!$C$34:$Z$34) -> 171701.19
A26: Deckungsbeitrag | B26: =SUMIF('Monat 1–36'!$C$4:$AL$4,B$5,'Monat 1–36'!$C$35:$AL$35)+SUMIF('Monat 37–60'!$C$4:$Z$4,B$5,'Monat 37–60'!$C$35:$Z$35) -> 56760.712 | C26: =SUMIF('Monat 1–36'!$C$4:$AL$4,C$5,'Monat 1–36'!$C$35:$AL$35)+SUMIF('Monat 37–60'!$C$4:$Z$4,C$5,'Monat 37–60'!$C$35:$Z$35) -> 266078.75 | D26: =SUMIF('Monat 1–36'!$C$4:$AL$4,D$5,'Monat 1–36'!$C$35:$AL$35)+SUMIF('Monat 37–60'!$C$4:$Z$4,D$5,'Monat 37–60'!$C$35:$Z$35) -> 614104.86 | E26: =SUMIF('Monat 1–36'!$C$4:$AL$4,E$5,'Monat 1–36'!$C$35:$AL$35)+SUMIF('Monat 37–60'!$C$4:$Z$4,E$5,'Monat 37–60'!$C$35:$Z$35) -> 1048666.2 | F26: =SUMIF('Monat 1–36'!$C$4:$AL$4,F$5,'Monat 1–36'!$C$35:$AL$35)+SUMIF('Monat 37–60'!$C$4:$Z$4,F$5,'Monat 37–60'!$C$35:$Z$35) -> 1505242.3
A27: Deckungsbeitragsmarge | B27: =IF(B22>0,B26/B22,0) -> 0.96928413 | C27: =IF(C22>0,C26/C22,0) -> 0.94596009 | D27: =IF(D22>0,D26/D22,0) -> 0.92186619 | E27: =IF(E22>0,E26/E22,0) -> 0.90985119 | F27: =IF(F22>0,F26/F22,0) -> 0.89761063
A28: Personal | B28: =SUMIF('Monat 1–36'!$C$4:$AL$4,B$5,'Monat 1–36'!$C$50:$AL$50)+SUMIF('Monat 37–60'!$C$4:$Z$4,B$5,'Monat 37–60'!$C$50:$Z$50) -> 76464 | C28: =SUMIF('Monat 1–36'!$C$4:$AL$4,C$5,'Monat 1–36'!$C$50:$AL$50)+SUMIF('Monat 37–60'!$C$4:$Z$4,C$5,'Monat 37–60'!$C$50:$Z$50) -> 288785.16 | D28: =SUMIF('Monat 1–36'!$C$4:$AL$4,D$5,'Monat 1–36'!$C$50:$AL$50)+SUMIF('Monat 37–60'!$C$4:$Z$4,D$5,'Monat 37–60'!$C$50:$Z$50) -> 448796.06 | E28: =SUMIF('Monat 1–36'!$C$4:$AL$4,E$5,'Monat 1–36'!$C$50:$AL$50)+SUMIF('Monat 37–60'!$C$4:$Z$4,E$5,'Monat 37–60'!$C$50:$Z$50) -> 701549.36 | F28: =SUMIF('Monat 1–36'!$C$4:$AL$4,F$5,'Monat 1–36'!$C$50:$AL$50)+SUMIF('Monat 37–60'!$C$4:$Z$4,F$5,'Monat 37–60'!$C$50:$Z$50) -> 874971.58
A29: davon Vertrieb & Marketing | B29: =SUMIF('Monat 1–36'!$C$4:$AL$4,B$5,'Monat 1–36'!$C$51:$AL$51)+SUMIF('Monat 37–60'!$C$4:$Z$4,B$5,'Monat 37–60'!$C$51:$Z$51) -> 27588 | C29: =SUMIF('Monat 1–36'!$C$4:$AL$4,C$5,'Monat 1–36'!$C$51:$AL$51)+SUMIF('Monat 37–60'!$C$4:$Z$4,C$5,'Monat 37–60'!$C$51:$Z$51) -> 119644.8 | D29: =SUMIF('Monat 1–36'!$C$4:$AL$4,D$5,'Monat 1–36'!$C$51:$AL$51)+SUMIF('Monat 37–60'!$C$4:$Z$4,D$5,'Monat 37–60'!$C$51:$Z$51) -> 154042.68 | E29: =SUMIF('Monat 1–36'!$C$4:$AL$4,E$5,'Monat 1–36'!$C$51:$AL$51)+SUMIF('Monat 37–60'!$C$4:$Z$4,E$5,'Monat 37–60'!$C$51:$Z$51) -> 257035.62 | F29: =SUMIF('Monat 1–36'!$C$4:$AL$4,F$5,'Monat 1–36'!$C$51:$AL$51)+SUMIF('Monat 37–60'!$C$4:$Z$4,F$5,'Monat 37–60'!$C$51:$Z$51) -> 333384.71
A30: Marketing laufend | B30: =SUMIF('Monat 1–36'!$C$4:$AL$4,B$5,'Monat 1–36'!$C$54:$AL$54)+SUMIF('Monat 37–60'!$C$4:$Z$4,B$5,'Monat 37–60'!$C$54:$Z$54) -> 30000 | C30: =SUMIF('Monat 1–36'!$C$4:$AL$4,C$5,'Monat 1–36'!$C$54:$AL$54)+SUMIF('Monat 37–60'!$C$4:$Z$4,C$5,'Monat 37–60'!$C$54:$Z$54) -> 48000 | D30: =SUMIF('Monat 1–36'!$C$4:$AL$4,D$5,'Monat 1–36'!$C$54:$AL$54)+SUMIF('Monat 37–60'!$C$4:$Z$4,D$5,'Monat 37–60'!$C$54:$Z$54) -> 72000 | E30: =SUMIF('Monat 1–36'!$C$4:$AL$4,E$5,'Monat 1–36'!$C$54:$AL$54)+SUMIF('Monat 37–60'!$C$4:$Z$4,E$5,'Monat 37–60'!$C$54:$Z$54) -> 96000 | F30: =SUMIF('Monat 1–36'!$C$4:$AL$4,F$5,'Monat 1–36'!$C$54:$AL$54)+SUMIF('Monat 37–60'!$C$4:$Z$4,F$5,'Monat 37–60'!$C$54:$Z$54) -> 120000
A31: Messen & Veranstaltungen | B31: =SUMIF('Monat 1–36'!$C$4:$AL$4,B$5,'Monat 1–36'!$C$55:$AL$55)+SUMIF('Monat 37–60'!$C$4:$Z$4,B$5,'Monat 37–60'!$C$55:$Z$55) -> 12300 | C31: =SUMIF('Monat 1–36'!$C$4:$AL$4,C$5,'Monat 1–36'!$C$55:$AL$55)+SUMIF('Monat 37–60'!$C$4:$Z$4,C$5,'Monat 37–60'!$C$55:$Z$55) -> 24000 | D31: =SUMIF('Monat 1–36'!$C$4:$AL$4,D$5,'Monat 1–36'!$C$55:$AL$55)+SUMIF('Monat 37–60'!$C$4:$Z$4,D$5,'Monat 37–60'!$C$55:$Z$55) -> 19000 | E31: =SUMIF('Monat 1–36'!$C$4:$AL$4,E$5,'Monat 1–36'!$C$55:$AL$55)+SUMIF('Monat 37–60'!$C$4:$Z$4,E$5,'Monat 37–60'!$C$55:$Z$55) -> 28000 | F31: =SUMIF('Monat 1–36'!$C$4:$AL$4,F$5,'Monat 1–36'!$C$55:$AL$55)+SUMIF('Monat 37–60'!$C$4:$Z$4,F$5,'Monat 37–60'!$C$55:$Z$55) -> 23000
A32: Übrige Fixkosten (Hosting, Miete, Beratung, Reisen …) | B32: =SUMIF('Monat 1–36'!$C$4:$AL$4,B$5,'Monat 1–36'!$C$66:$AL$66)+SUMIF('Monat 37–60'!$C$4:$Z$4,B$5,'Monat 37–60'!$C$66:$Z$66)-B30-B31 -> 39680 | C32: =SUMIF('Monat 1–36'!$C$4:$AL$4,C$5,'Monat 1–36'!$C$66:$AL$66)+SUMIF('Monat 37–60'!$C$4:$Z$4,C$5,'Monat 37–60'!$C$66:$Z$66)-C30-C31 -> 45720 | D32: =SUMIF('Monat 1–36'!$C$4:$AL$4,D$5,'Monat 1–36'!$C$66:$AL$66)+SUMIF('Monat 37–60'!$C$4:$Z$4,D$5,'Monat 37–60'!$C$66:$Z$66)-D30-D31 -> 69720 | E32: =SUMIF('Monat 1–36'!$C$4:$AL$4,E$5,'Monat 1–36'!$C$66:$AL$66)+SUMIF('Monat 37–60'!$C$4:$Z$4,E$5,'Monat 37–60'!$C$66:$Z$66)-E30-E31 -> 94440 | F32: =SUMIF('Monat 1–36'!$C$4:$AL$4,F$5,'Monat 1–36'!$C$66:$AL$66)+SUMIF('Monat 37–60'!$C$4:$Z$4,F$5,'Monat 37–60'!$C$66:$Z$66)-F30-F31 -> 113400
A33: Fixkosten gesamt | B33: =SUMIF('Monat 1–36'!$C$4:$AL$4,B$5,'Monat 1–36'!$C$67:$AL$67)+SUMIF('Monat 37–60'!$C$4:$Z$4,B$5,'Monat 37–60'!$C$67:$Z$67) -> 158444 | C33: =SUMIF('Monat 1–36'!$C$4:$AL$4,C$5,'Monat 1–36'!$C$67:$AL$67)+SUMIF('Monat 37–60'!$C$4:$Z$4,C$5,'Monat 37–60'!$C$67:$Z$67) -> 406505.16 | D33: =SUMIF('Monat 1–36'!$C$4:$AL$4,D$5,'Monat 1–36'!$C$67:$AL$67)+SUMIF('Monat 37–60'!$C$4:$Z$4,D$5,'Monat 37–60'!$C$67:$Z$67) -> 609516.06 | E33: =SUMIF('Monat 1–36'!$C$4:$AL$4,E$5,'Monat 1–36'!$C$67:$AL$67)+SUMIF('Monat 37–60'!$C$4:$Z$4,E$5,'Monat 37–60'!$C$67:$Z$67) -> 919989.36 | F33: =SUMIF('Monat 1–36'!$C$4:$AL$4,F$5,'Monat 1–36'!$C$67:$AL$67)+SUMIF('Monat 37–60'!$C$4:$Z$4,F$5,'Monat 37–60'!$C$67:$Z$67) -> 1131371.6
A34: Kosten gesamt | B34: =SUMIF('Monat 1–36'!$C$4:$AL$4,B$5,'Monat 1–36'!$C$69:$AL$69)+SUMIF('Monat 37–60'!$C$4:$Z$4,B$5,'Monat 37–60'!$C$69:$Z$69) -> 160242.7 | C34: =SUMIF('Monat 1–36'!$C$4:$AL$4,C$5,'Monat 1–36'!$C$69:$AL$69)+SUMIF('Monat 37–60'!$C$4:$Z$4,C$5,'Monat 37–60'!$C$69:$Z$69) -> 421705.45 | D34: =SUMIF('Monat 1–36'!$C$4:$AL$4,D$5,'Monat 1–36'!$C$69:$AL$69)+SUMIF('Monat 37–60'!$C$4:$Z$4,D$5,'Monat 37–60'!$C$69:$Z$69) -> 661565.21 | E34: =SUMIF('Monat 1–36'!$C$4:$AL$4,E$5,'Monat 1–36'!$C$69:$AL$69)+SUMIF('Monat 37–60'!$C$4:$Z$4,E$5,'Monat 37–60'!$C$69:$Z$69) -> 1023892.1 | F34: =SUMIF('Monat 1–36'!$C$4:$AL$4,F$5,'Monat 1–36'!$C$69:$AL$69)+SUMIF('Monat 37–60'!$C$4:$Z$4,F$5,'Monat 37–60'!$C$69:$Z$69) -> 1303072.8
A35: Ergebnis
A36: EBITDA | B36: =SUMIF('Monat 1–36'!$C$4:$AL$4,B$5,'Monat 1–36'!$C$70:$AL$70)+SUMIF('Monat 37–60'!$C$4:$Z$4,B$5,'Monat 37–60'!$C$70:$Z$70) -> -101683.29 | C36: =SUMIF('Monat 1–36'!$C$4:$AL$4,C$5,'Monat 1–36'!$C$70:$AL$70)+SUMIF('Monat 37–60'!$C$4:$Z$4,C$5,'Monat 37–60'!$C$70:$Z$70) -> -140426.41 | D36: =SUMIF('Monat 1–36'!$C$4:$AL$4,D$5,'Monat 1–36'!$C$70:$AL$70)+SUMIF('Monat 37–60'!$C$4:$Z$4,D$5,'Monat 37–60'!$C$70:$Z$70) -> 4588.8008 | E36: =SUMIF('Monat 1–36'!$C$4:$AL$4,E$5,'Monat 1–36'!$C$70:$AL$70)+SUMIF('Monat 37–60'!$C$4:$Z$4,E$5,'Monat 37–60'!$C$70:$Z$70) -> 128676.82 | F36: =SUMIF('Monat 1–36'!$C$4:$AL$4,F$5,'Monat 1–36'!$C$70:$AL$70)+SUMIF('Monat 37–60'!$C$4:$Z$4,F$5,'Monat 37–60'!$C$70:$Z$70) -> 373870.77
A37: EBITDA-Marge | B37: =IF(B22>0,B36/B22,0) -> -1.7364123 | C37: =IF(C22>0,C36/C22,0) -> -0.49924237 | D37: =IF(D22>0,D36/D22,0) -> 0.0068884984 | E37: =IF(E22>0,E36/E22,0) -> 0.11164349 | F37: =IF(F22>0,F36/F22,0) -> 0.22294774
A38: Abschreibungen | B38: =0 -> 0 | C38: =0 -> 0 | D38: =0 -> 0 | E38: =0 -> 0 | F38: =0 -> 0 | G38: keine wesentlichen Investitionen; Hardware sofort Aufwand
A39: Zinsen | B39: =SUMIF('Monat 1–36'!$C$4:$AL$4,B$5,'Monat 1–36'!$C$76:$AL$76)+SUMIF('Monat 37–60'!$C$4:$Z$4,B$5,'Monat 37–60'!$C$76:$Z$76) -> 5000 | C39: =SUMIF('Monat 1–36'!$C$4:$AL$4,C$5,'Monat 1–36'!$C$76:$AL$76)+SUMIF('Monat 37–60'!$C$4:$Z$4,C$5,'Monat 37–60'!$C$76:$Z$76) -> 5000 | D39: =SUMIF('Monat 1–36'!$C$4:$AL$4,D$5,'Monat 1–36'!$C$76:$AL$76)+SUMIF('Monat 37–60'!$C$4:$Z$4,D$5,'Monat 37–60'!$C$76:$Z$76) -> 4713.5417 | E39: =SUMIF('Monat 1–36'!$C$4:$AL$4,E$5,'Monat 1–36'!$C$76:$AL$76)+SUMIF('Monat 37–60'!$C$4:$Z$4,E$5,'Monat 37–60'!$C$76:$Z$76) -> 4088.5417 | F39: =SUMIF('Monat 1–36'!$C$4:$AL$4,F$5,'Monat 1–36'!$C$76:$AL$76)+SUMIF('Monat 37–60'!$C$4:$Z$4,F$5,'Monat 37–60'!$C$76:$Z$76) -> 3463.5417
A40: Ergebnis vor Steuern (EBT) | B40: =B36-B38-B39 -> -106683.29 | C40: =C36-C38-C39 -> -145426.41 | D40: =D36-D38-D39 -> -124.74085 | E40: =E36-E38-E39 -> 124588.28 | F40: =F36-F38-F39 -> 370407.23
A41: Verlustvortrag Jahresanfang | B41: =0 -> 0 | C41: =B43 -> 106683.29 | D41: =C43 -> 252109.7 | E41: =D43 -> 252234.44 | F41: =E43 -> 127646.16
...

Sheet Break-even
A1: LADEKLAR – Break-even und Kapitalbedarf
A3: EBITDA-Break-even
A4: Erster Monat mit EBITDA ≥ 0 (Monat-Nr.) | B4: =MIN('Monat 1–36'!$C$84:$AL$84,'Monat 37–60'!$C$84:$Z$84) -> 30
A5: … als Kalendermonat | B5: =IF(B4<999,EDATE(Annahmen!$B$6,B4-1),"nicht erreicht") -> 47270
A6: Dauerhaft positives EBITDA ab Monat-Nr. | B6: =MAX('Monat 1–36'!$C$85:$AL$85,'Monat 37–60'!$C$85:$Z$85)+1 -> 40 | C6: Monat nach dem letzten Monat mit negativem EBITDA
A7: … als Kalendermonat | B7: =IF(B6<=60,EDATE(Annahmen!$B$6,B6-1),"nach Monat 60") -> 47574
