Workbook

Sheet Annahmen
A1: LiveFX – Finanzmodell Pre-Seed 250.000 € · Annahmen
A2: Alle Werte sind Schätzungen auf Basis von BUSINESSPLAN.md §11 – es gibt noch keine Umsätze. Mittelverwendung, Gates und Bewertung: Vorschlag – mit Steuer-/Rechtsberater prüfen.
A3: Legende: blaue Schrift = Eingabe (änderbar) · schwarz = Formel · grün = Verweis auf anderes Blatt · gelb = Schlüsselannahme. Stand: Oktober 2026, Produkt v2.1. J1 = 2027 (Start Pro-Abo, Closing Jan 2027).
A5: A. Allgemein
A6: Startkasse (Pre-Seed, Closing Monat 1 = Jan 2027) | B6: 250000 | I6: Vom Gründer korrigierte Rundengröße: ca. 250.000 € statt 500.000 € (BP §11.6 alt).
A7: Infrastruktur fix (Server, Domains, Tools) €/Monat | B7: 250 | I7: Schätzung; BP §11.3 Infrastruktur J1 8 T€ – wird hier als fix + variabel modelliert.
A8: Infrastruktur variabel (KI-API nur Pro, Zahlungs-/Store-Gebühren) in % vom Umsatz | B8: 0.08 | I8: Schätzung: Payment-/Store-Gebühren 5–8 % + KI ≈ 0,004 $ je Klassifikation (BP §9). Ergibt J1 ≈ 7 T€ (BP: 8).
A9: Monat im Jahr, in dem B2B-/Pilot-Erlöse zufließen (1–12) | B9: 10 | I9: Annahme: Pilot-/Lizenzzahlung als Einmalbetrag im Oktober des Jahres (J2 → Monat 22).
A10: Ø Preis Creator-Pack (€) | B10: 3.99 | I10: BP §11.1: 1 Pack à Ø 3,99 €.
A11: Agentur-Lizenz €/Monat | B11: 49 | I11: BP §11.1: Agentur-Lizenz à 49 €/Monat (Jahresendbestand × 12, wie im Plan).
A12: Ø zahlende Pro im Jahr J1 (Anteil am Jahresendwert) | B12: 0.5 | I12: BP §11.1: ≈ 50 % des Jahresendwerts in J1.
A13: Ø zahlende Pro im Jahr J2–J5 (Anteil am Jahresendwert) | B13: 0.75 | I13: BP §11.1: 75 % in J2/J3; für J4/J5 fortgeschrieben.
A14: Mindestkasse in Monatskosten (für Folgerunden-Bedarf) | B14: 3 | I14: Annahme: 3 Monatskosten des Jahres J3 als Sicherheitsbestand.
A15: Anteil nachgelagerter Vision-Linien an den Vision-Kosten (Story-Engine, Studio/Auto-Edit, Räume/VR-AR) | B15: 0.6 | I15: INVESTOR-MEMO §10.1 (500-T€-Fassung): Vision 100 T€ = WortBild 40 + Story-Engine 40 + Highlights/Räume 20 → 60 % nicht WortBild.
A16: Vision-Zusatzkosten J2 laut BP §11.5 (€) | B16: 115000 | I16: BP §11.5: Zusatzkosten 30 / 115 / 210 T€.
A17: Vision-Zusatzkosten J3 laut BP §11.5 (€) | B17: 210000 | I17: BP §11.5.
A18: Ausbau-Team startet in Monat (nach Gate 2 / Folgerunde) | B18: 19 | I18: Neu: Einstellungen über das schlanke Pre-Seed-Team hinaus erst nach Gate 2 (Monat 18).
A20: B. Szenarien (Nutzer, Conversion, Preise, Lizenzen, Kosten J3–J5)
A21: Annahme | B21: Einheit | C21: Konservativ | D21: Basis | E21: Optimistisch | I21: Quelle / Begründung
A22: Registrierte Nutzer Ende J1 | B22: Nutzer | C22: 8000 | D22: 20000 | E22: 40000 | I22: BP §11.1
A23: Registrierte Nutzer Ende J2 | B23: Nutzer | C23: 30000 | D23: 80000 | E23: 180000 | I23: BP §11.1
A24: Registrierte Nutzer Ende J3 | B24: Nutzer | C24: 80000 | D24: 250000 | E24: 500000 | I24: BP §11.1 (SOM J3: 5.000–15.000 Zahlende, BP §6)
A25: Nutzerwachstum J4 (ggü. J3) | B25: % | C25: 0.5 | D25: 0.8 | E25: 0.8 | I25: Neu (Fortschreibung): Wachstum verlangsamt sich ggü. J2→J3 (×2,7 / ×3,1 / ×2,8).
A26: Nutzerwachstum J5 (ggü. J4) | B26: % | C26: 0.35 | D26: 0.5 | E26: 0.5 | I26: Neu (Fortschreibung): weitere Verlangsamung; Basis J5 = 675.000 Nutzer ≈ 23–68 % des SAM (1–3 Mio., BP §6).
A27: Conversion Free → Pro J1–J3 | B27: % | C27: 0.03 | D27: 0.04 | E27: 0.05 | I27: BP §11.1
A28: Conversion Free → Pro J4 | B28: % | C28: 0.03 | D28: 0.0425 | E28: 0.0525 | I28: Neu: +0,25 Pkt./Jahr in Basis/Optimistisch (Pro+, Packs, Bindung); konservativ konstant.
A29: Conversion Free → Pro J5 | B29: % | C29: 0.03 | D29: 0.045 | E29: 0.055 | I29: Neu: wie oben.
A30: ARPU Pro (netto, Mix Monat/Jahr) | B30: €/Monat | C30: 8.5 | D30: 8.5 | E30: 8.5 | I30: BP §11.1 (9,99 €/Monat bzw. 79 €/Jahr, netto)
A31: Pack-Käufe pro Jahr (Anteil der Nutzer × 1 Pack) | B31: % | C31: 0.07 | D31: 0.1 | E31: 0.12 | I31: BP §11.1
A32: Agentur-Lizenzen Ende J1 | B32: Anzahl | C32: 2 | D32: 3 | E32: 5 | I32: BP §11.1
A33: Agentur-Lizenzen Ende J2 | B33: Anzahl | C33: 8 | D33: 15 | E33: 30 | I33: BP §11.1
... A46: Referenz: Plan-Kosten J2 (BP 500-T€-Fassung) | B46: € | C46: 230000 | D46: 398000 | E46: 520000 | I46: BP §11.3 – Grundlage für den Ausbau ab Monat 19
A47: Ausbau-Faktor ab Monat 19 (Plan-Kosten J2 Szenario ÷ Basis) | B47: Faktor | C47: =C46/$D$46 -> 0.57788945 | D47: =D46/$D$46 -> 1 | E47: =E46/$D$46 -> 1.3065327 | I47: Formel: Ausbau-Kosten je Szenario skaliert wie die Plan-Kosten J2 (230 / 398 / 520 T€).
A49: C. Kostenlinien Pre-Seed (Monat 1–18) – Vorschlag, schlanker Aufbau mit 250.000 €
A50: Kostenlinie | B50: Budgetbereich | C50: €/Monat | D50: von Monat | E50: bis Monat | F50: Einmalbetrag € | G50: im Monat | H50: Summe M1–18 | I50: Inhalt / Begründung / ersetzt Planzeile
A51: Mobile-/Web-Entwickler:in (Vollzeit, ab Monat 3) | B51: Team/Produkt | C51: 5500 | D51: 3 | E51: 18 | F51: 0 | G51: 1 | H51: =C51*MAX(0,MIN(E51,18)-D51+1)+IF(G51<=18,F51,0) -> 88000 | I51: Erste Einstellung (BP §12). 66 T€/Jahr Vollkosten statt 75 T€ J1 / 160 T€ J2 (BP §11.3: 1 statt 2 Entwickler:innen in J2).
A52: Gründergehalt (anteilig) | B52: Team/Produkt | C52: 2000 | D52: 1 | E52: 18 | F52: 0 | G52: 1 | H52: =C52*MAX(0,MIN(E52,18)-D52+1)+IF(G52<=18,F52,0) -> 36000 | I52: BP §11.3: 30 T€ J1 / 48 T€ J2 → 24 T€/Jahr bis Monat 18.
A53: Entwicklungs-Tools, Testgeräte (iOS/Android) | B53: Team/Produkt | C53: 0 | D53: 1 | E53: 18 | F53: 1000 | G53: 1 | H53: =C53*MAX(0,MIN(E53,18)-D53+1)+IF(G53<=18,F53,0) -> 1000 | I53: Einmalig.
A54: Creator-Programm, Community, Marketing – Phase 1 (TR-Launch) | B54: Markteintritt | C54: 2000 | D54: 1 | E54: 6 | F54: 0 | G54: 1 | H54: =C54*MAX(0,MIN(E54,18)-D54+1)+IF(G54<=18,F54,0) -> 12000 | I54: BP §10 Phase 1; BP §11.3 Marketing 25 T€ J1.
A55: Creator-Programm, Marketing, Marktplätze – Phase 2 (DE/EN, Partner) | B55: Markteintritt | C55: 3000 | D55: 7 | E55: 18 | F55: 0 | G55: 1 | H55: =C55*MAX(0,MIN(E55,18)-D55+1)+IF(G55<=18,F55,0) -> 36000 | I55: BP §10 Phase 2/3: Botschafter:innen, Pack-Drops, OBS/Streamlabs/Stream-Deck-Einträge.
...

Sheet GuV 5 Jahre
A1: GuV 5 Jahre (EBITDA-Sicht) – drei Szenarien
A2: Alle Werte sind Schätzungen auf Basis von BUSINESSPLAN.md §11 – es gibt noch keine Umsätze. Mittelverwendung, Gates und Bewertung: Vorschlag – mit Steuer-/Rechtsberater prüfen. J1–J3 aus BP §11.1, Kosten J1–J2 aus dem Monatsplan (250-T€-Runde), J4–J5 fortgeschrieben.
A4: Szenario Konservativ
A5: Position | B5: Einheit | C5: J1 2027 | D5: J2 2028 | E5: J3 2029 | F5: J4 2030 | G5: J5 2031 | H5: Herleitung
A6: Registrierte Nutzer (Jahresende) | B6: Nutzer | C6: =Annahmen!$C$22 -> 8000 | D6: =Annahmen!$C$23 -> 30000 | E6: =Annahmen!$C$24 -> 80000 | F6: =E6*(1+Annahmen!$C$25) -> 120000 | G6: =F6*(1+Annahmen!$C$26) -> 162000 | H6: J1–J3 BP §11.1; J4–J5 = Vorjahr × (1 + Wachstum)
A7: Conversion Free → Pro | B7: % | C7: =Annahmen!$C$27 -> 0.03 | D7: =Annahmen!$C$27 -> 0.03 | E7: =Annahmen!$C$27 -> 0.03 | F7: =Annahmen!$C$28 -> 0.03 | G7: =Annahmen!$C$29 -> 0.03
A8: Zahlende Pro-Nutzer (Jahresende) | B8: Abos | C8: =C6*C7 -> 240 | D8: =D6*D7 -> 900 | E8: =E6*E7 -> 2400 | F8: =F6*F7 -> 3600 | G8: =G6*G7 -> 4860
A9: Zahlende Pro-Nutzer (Jahresdurchschnitt) | B9: Abos | C9: =C8*Annahmen!$B$12 -> 120 | D9: =D8*Annahmen!$B$13 -> 675 | E9: =E8*Annahmen!$B$13 -> 1800 | F9: =F8*Annahmen!$B$13 -> 2700 | G9: =G8*Annahmen!$B$13 -> 3645 | H9: BP §11.1: 50 % des Jahresendwerts in J1, 75 % ab J2
A10: Umsatz Pro-Abo | B10: € | C10: =C9*Annahmen!$C$30*12 -> 12240 | D10: =D9*Annahmen!$C$30*12 -> 68850 | E10: =E9*Annahmen!$C$30*12 -> 183600 | F10: =F9*Annahmen!$C$30*12 -> 275400 | G10: =G9*Annahmen!$C$30*12 -> 371790
A11: Umsatz Creator-Packs | B11: € | C11: =C6*Annahmen!$C$31*Annahmen!$B$10 -> 2234.4 | D11: =D6*Annahmen!$C$31*Annahmen!$B$10 -> 8379 | E11: =E6*Annahmen!$C$31*Annahmen!$B$10 -> 22344 | F11: =F6*Annahmen!$C$31*Annahmen!$B$10 -> 33516 | G11: =G6*Annahmen!$C$31*Annahmen!$B$10 -> 45246.6
A12: Umsatz Agentur-Lizenz | B12: € | C12: =Annahmen!$C$32*Annahmen!$B$11*12 -> 1176 | D12: =Annahmen!$C$33*Annahmen!$B$11*12 -> 4704 | E12: =Annahmen!$C$34*Annahmen!$B$11*12 -> 14700 | F12: =Annahmen!$C$35*Annahmen!$B$11*12 -> 23520 | G12: =Annahmen!$C$36*Annahmen!$B$11*12 -> 35280 | H12: Jahresendbestand × 49 € × 12 (Methode des Plans)
A13: Zwischensumme wiederkehrender Umsatz | B13: € | C13: =C10+C11+C12 -> 15650.4 | D13: =D10+D11+D12 -> 81933 | E13: =E10+E11+E12 -> 220644 | F13: =F10+F11+F12 -> 332436 | G13: =G10+G11+G12 -> 452316.6
A14: Umsatz B2B / Pilot | B14: € | C14: =Annahmen!$C$37 -> 0 | D14: =Annahmen!$C$38 -> 0 | E14: =Annahmen!$C$39 -> 50000 | F14: =Annahmen!$C$40 -> 100000 | G14: =Annahmen!$C$41 -> 150000
A15: Umsatz gesamt | B15: € | C15: =C13+C14 -> 15650.4 | D15: =D13+D14 -> 81933 | E15: =E13+E14 -> 270644 | F15: =F13+F14 -> 432436 | G15: =G13+G14 -> 602316.6
A16: Kosten gesamt (operativ) | B16: € | C16: ='Liquidität 24M'!$AB$65 -> 163377.03 | D16: ='Liquidität 24M'!$AC$65 -> 195706.02 | E16: =Annahmen!$C$42 -> 330000 | F16: =E16*(1+Annahmen!$C$43) -> 396000 | G16: =F16*(1+Annahmen!$C$44) -> 455400 | H16: J1–J2 = Summe Monatsplan (Liquidität 24M); J3 = BP §11.3; J4–J5 = Vorjahr × (1 + Kostenwachstum)
A17: EBITDA (Ergebnis) | B17: € | C17: =C15-C16 -> -147726.63 | D17: =D15-D16 -> -113773.02 | E17: =E15-E16 -> -59356 | F17: =F15-F16 -> 36436 | G17: =G15-G16 -> 146916.6
A18: EBITDA-Marge | B18: % | C18: =IF(C15=0,0,C17/C15) -> -9.4391601 | D18: =IF(D15=0,0,D17/D15) -> -1.3886105 | E18: =IF(E15=0,0,E17/E15) -> -0.21931393 | F18: =IF(F15=0,0,F17/F15) -> 0.084257555 | G18: =IF(G15=0,0,G17/G15) -> 0.24391923
A19: Kumuliertes Ergebnis | B19: € | C19: =C17 -> -147726.63 | D19: =C19+D17 -> -261499.65 | E19: =D19+E17 -> -320855.65 | F19: =E19+F17 -> -284419.65 | G19: =F19+G17 -> -137503.05
A20: Kasse Jahresende (250 T€ Start, ohne Folgerunde) | B20: € | C20: ='Liquidität 24M'!$O$67 -> 102273.37 | D20: ='Liquidität 24M'!$AA$67 -> -11499.654 | E20: =D20+E17 -> -70855.654 | F20: =E20+F17 -> -34419.654 | G20: =F20+G17 -> 112496.95 | H20: J1/J2 aus dem Monatsplan (Monat 12/24); ab J3 Vorjahr + EBITDA (vereinfacht, ohne Steuern/Working Capital)
A21: Referenz: Umsatz laut Plan BP §11.2 (T€) | C21: =Annahmen!$C$74 -> 15 | D21: =Annahmen!$D$74 -> 81 | E21: =Annahmen!$E$74 -> 268
A22: Abweichung Modell − Plan beim Umsatz (T€) | C22: =C15/1000-C21 -> 0.6504 | D22: =D15/1000-D21 -> 0.933 | E22: =E15/1000-E21 -> 2.644 | H22: Rundung; konservativ J2/J3: Korrektur der Agentur-Zeile (siehe Annahmen F)
A23: Referenz: Ergebnis laut Plan BP §11.4 (T€, 500-T€-Kostenbasis) | C23: =Annahmen!$C$76 -> -105 | D23: =Annahmen!$D$76 -> -149 | E23: =Annahmen!$E$76 -> -62
A25: Szenario Basis
A26: Position | B26: Einheit | C26: J1 2027 | D26: J2 2028 | E26: J3 2029 | F26: J4 2030 | G26: J5 2031 | H26: Herleitung
A27: Registrierte Nutzer (Jahresende) | B27: Nutzer | C27: =Annahmen!$D$22 -> 20000 | D27: =Annahmen!$D$23 -> 80000 | E27: =Annahmen!$D$24 -> 250000 | F27: =E27*(1+Annahmen!$D$25) -> 450000 | G27: =F27*(1+Annahmen!$D$26) -> 675000 | H27: J1–J3 BP §11.1; J4–J5 = Vorjahr × (1 + Wachstum)
A28: Conversion Free → Pro | B28: % | C28: =Annahmen!$D$27 -> 0.04 | D28: =Annahmen!$D$27 -> 0.04 | E28: =Annahmen!$D$27 -> 0.04 | F28: =Annahmen!$D$28 -> 0.0425 | G28: =Annahmen!$D$29 -> 0.045
A29: Zahlende Pro-Nutzer (Jahresende) | B29: Abos | C29: =C27*C28 -> 800 | D29: =D27*D28 -> 3200 | E29: =E27*E28 -> 10000 | F29: =F27*F28 -> 19125 | G29: =G27*G28 -> 30375
A30: Zahlende Pro-Nutzer (Jahresdurchschnitt) | B30: Abos | C30: =C29*Annahmen!$B$12 -> 400 | D30: =D29*Annahmen!$B$13 -> 2400 | E30: =E29*Annahmen!$B$13 -> 7500 | F30: =F29*Annahmen!$B$13 -> 14343.75 | G30: =G29*Annahmen!$B$13 -> 22781.25 | H30: BP §11.1: 50 % des Jahresendwerts in J1, 75 % ab J2
A31: Umsatz Pro-Abo | B31: € | C31: =C30*Annahmen!$D$30*12 -> 40800 | D31: =D30*Annahmen!$D$30*12 -> 244800 | E31: =E30*Annahmen!$D$30*12 -> 765000 | F31: =F30*Annahmen!$D$30*12 -> 1463062.5 | G31: =G30*Annahmen!$D$30*12 -> 2323687.5
A32: Umsatz Creator-Packs | B32: € | C32: =C27*Annahmen!$D$31*Annahmen!$B$10 -> 7980 | D32: =D27*Annahmen!$D$31*Annahmen!$B$10 -> 31920 | E32: =E27*Annahmen!$D$31*Annahmen!$B$10 -> 99750 | F32: =F27*Annahmen!$D$31*Annahmen!$B$10 -> 179550 | G32: =G27*Annahmen!$D$31*Annahmen!$B$10 -> 269325
A33: Umsatz Agentur-Lizenz | B33: € | C33: =Annahmen!$D$32*Annahmen!$B$11*12 -> 1764 | D33: =Annahmen!$D$33*Annahmen!$B$11*12 -> 8820 | E33: =Annahmen!$D$34*Annahmen!$B$11*12 -> 23520 | F33: =Annahmen!$D$35*Annahmen!$B$11*12 -> 41160 | G33: =Annahmen!$D$36*Annahmen!$B$11*12 -> 58800 | H33: Jahresendbestand × 49 € × 12 (Methode des Plans)
A34: Zwischensumme wiederkehrender Umsatz | B34: € | C34: =C31+C32+C33 -> 50544 | D34: =D31+D32+D33 -> 285540 | E34: =E31+E32+E33 -> 888270 | F34: =F31+F32+F33 -> 1683772.5 | G34: =G31+G32+G33 -> 2651812.5
A35: Umsatz B2B / Pilot | B35: € | C35: =Annahmen!$D$37 -> 0 | D35: =Annahmen!$D$38 -> 50000 | E35: =Annahmen!$D$39 -> 150000 | F35: =Annahmen!$D$40 -> 300000 | G35: =Annahmen!$D$41 -> 500000
A36: Umsatz gesamt | B36: € | C36: =C34+C35 -> 50544 | D36: =D34+D35 -> 335540 | E36: =E34+E35 -> 1038270 | F36: =F34+F35 -> 1983772.5 | G36: =G34+G35 -> 3151812.5
A37: Kosten gesamt (operativ) | B37: € | C37: ='Liquidität 24M'!$AB$86 -> 166168.52 | D37: ='Liquidität 24M'!$AC$86 -> 294718.2 | E37: =Annahmen!$D$42 -> 710000 | F37: =E37*(1+Annahmen!$D$43) -> 1065000 | G37: =F37*(1+Annahmen!$D$44) -> 1491000 | H37: J1–J2 = Summe Monatsplan (Liquidität 24M); J3 = BP §11.3; J4–J5 = Vorjahr × (1 + Kostenwachstum)
A38: EBITDA (Ergebnis) | B38: € | C38: =C36-C37 -> -115624.52 | D38: =D36-D37 -> 40821.8 | E38: =E36-E37 -> 328270 | F38: =F36-F37 -> 918772.5 | G38: =G36-G37 -> 1660812.5
A39: EBITDA-Marge | B39: % | C39: =IF(C36=0,0,C38/C36) -> -2.2876013 | D39: =IF(D36=0,0,D38/D36) -> 0.12166001 | E39: =IF(E36=0,0,E38/E36) -> 0.31617017 | F39: =IF(F36=0,0,F38/F36) -> 0.46314409 | G39: =IF(G36=0,0,G38/G36) -> 0.52693886
A40: Kumuliertes Ergebnis | B40: € | C40: =C38 -> -115624.52 | D40: =C40+D38 -> -74802.72 | E40: =D40+E38 -> 253467.28 | F40: =E40+F38 -> 1172239.8 | G40: =F40+G38 -> 2833052.3
A41: Kasse Jahresende (250 T€ Start, ohne Folgerunde) | B41: € | C41: ='Liquidität 24M'!$O$88 -> 134375.48 | D41: ='Liquidität 24M'!$AA$88 -> 175197.28 | E41: =D41+E38 -> 503467.28 | F41: =E41+F38 -> 1422239.8 | G41: =F41+G38 -> 3083052.3 | H41: J1/J2 aus dem Monatsplan (Monat 12/24); ab J3 Vorjahr + EBITDA (vereinfacht, ohne Steuern/Working Capital)
A42: Referenz: Umsatz laut Plan BP §11.2 (T€) | C42: =Annahmen!$C$77 -> 51 | D42: =Annahmen!$D$77 -> 336 | E42: =Annahmen!$E$77 -> 1039
...

Sheet Mittelverwendung
A1: Mittelverwendung 250.000 € über 18 Monate (Vorschlag)
A2: Vorschlag – mit Steuer-/Rechtsberater prüfen. Story-Engine, Auto-Edit/Studio und VR/AR werden aus der Folgerunde finanziert.
A4: Bereich | B4: Anteil | C4: Betrag | D4: Verplant M1–18 (Monatsplan) | E4: Differenz | F4: €/Monat Ø | G4: Inhalt
A5: Team/Produkt: Mobile-/Web-Entwickler:in, Gründergehalt anteilig, Testgeräte | B5: 0.5 | C5: =B5*Annahmen!$B$6 -> 125000 | D5: ='Liquidität 24M'!$AD$31+'Liquidität 24M'!$AD$32+'Liquidität 24M'!$AD$33 -> 125000 | E5: =C5-D5 -> 0 | F5: =C5/18 -> 6944.4444 | G5: Entwickler:in ab Monat 3 (16 × 5.500 € = 88 T€), Gründer 18 × 2.000 € = 36 T€, Testgeräte 1 T€; Ziel: Pro-Abo, Mobile-App/PWA, Stabilität v2.1
A6: Markteintritt: Creator-Programm, Community, Plattform- und Bildungspiloten | B6: 0.2 | C6: =B6*Annahmen!$B$6 -> 50000 | D6: ='Liquidität 24M'!$AD$34+'Liquidität 24M'!$AD$35+'Liquidität 24M'!$AD$36 -> 50000 | E6: =C6-D6 -> 0 | F6: =C6/18 -> 2777.7778 | G6: TR-Launch, 10–20 Botschafter:innen, Pack-Drops, Marktplatz-Einträge, DE/EN-Launch, 1 Plattform- oder Bildungspilot
A7: Erste Vision-Linie WortBild (Sprachenlernen) | B7: 0.15 | C7: =B7*Annahmen!$B$6 -> 37500 | D7: ='Liquidität 24M'!$AD$37 -> 37500 | E7: =C7-D7 -> 0 | F7: =C7/18 -> 2083.3333 | G7: 300 Wörter, Lesehilfe, Sprecher-Audios DE/TR/EN, Didaktik-Prüfung, Kurs-/Klassen-Pilot (M4–M15)
A8: Recht, Marke, Datenschutz | B8: 0.1 | C8: =B8*Annahmen!$B$6 -> 25000 | D8: ='Liquidität 24M'!$AD$38 -> 25000 | E8: =C8-D8 -> 0 | F8: =C8/18 -> 1388.8889 | G8: Marke LiveFX DE/EU/TR, Beteiligungsvertrag, DSGVO/DSFA Schul-/Familienprofil, Jugendschutz, Steuerberatung
A9: Reserve | B9: 0.05 | C9: =B9*Annahmen!$B$6 -> 12500 | D9: =0 -> 0 | E9: =C9-D9 -> 12500 | F9: =C9/18 -> 694.44444 | G9: Nicht verplant: Verzögerungen bei Einstellung, Store-/Plattform-Freigaben; deckt Infrastruktur-Fixkosten im Fall ohne Umsatz
A10: Summe | B10: =SUM(B5:B9) -> 1 | C10: =SUM(C5:C9) -> 250000 | D10: =SUM(D5:D9) -> 237500 | E10: =C10-D10 -> 12500 | F10: =C10/18 -> 13888.889
A11: Prüfung: Summe Anteile = 100 % und Betrag = Startkasse | C11: =IF(AND(ROUND(B10,4)=1,ROUND(C10-Annahmen!$B$6,0)=0),"OK","PRÜFEN") -> OK
A13: Verschoben in die Folgerunde (nicht aus den 250.000 € finanziert)
A14: • Story-Engine / Erzählfilm (Linie A): Scene-Director, Figuren, Welten-Packs TR/EN
A15: • Studio / Auto-Edit (Linie D): Highlights, Datei-Import, MP4-Export, Pro+
A16: • Räume / VR-AR (Linie C): Bühnen-/Klassenzimmer-Preset, WebXR, Brille
A17: • Backend/ML-Entwickler:in (Streaming-ASR < 300 ms), Community/Support, 2. Entwickler:in – ab Monat 19 nach Gate 2
A19: Kostenabgleich Basis: Plan BP §11.3 (500-T€-Fassung) vs. Modell (250-T€-Runde)
A20: Planzeile BP §11.3 | C20: Plan J1 | D20: Modell J1 | E20: Plan J2 | F20: Modell J2 | G20: Was ändert sich
A21: Personal: Mobile-/Web-Entwicklung | C21: 75000 | D21: ='Liquidität 24M'!$AB$31+'Liquidität 24M'!$AB$33+'Liquidität 24M'!$AB$42 -> 56000 | E21: 160000 | F21: ='Liquidität 24M'!$AC$31+'Liquidität 24M'!$AC$33+'Liquidität 24M'!$AC$42 -> 113000 | G21: 1 Entwickler:in ab M3 statt sofort; 2. Person erst ab M19
A22: Personal: Backend/ML, Community/Support | C22: 0 | D22: ='Liquidität 24M'!$AB$43 -> 0 | E22: 60000 | F22: ='Liquidität 24M'!$AC$43 -> 30000 | G22: erst ab M19 (statt ganz J2)
A23: Gründer (Gehalt) | C23: 30000 | D23: ='Liquidität 24M'!$AB$32+'Liquidität 24M'!$AB$44 -> 24000 | E23: 48000 | F23: ='Liquidität 24M'!$AC$32+'Liquidität 24M'!$AC$44 -> 36000 | G23: 2.000 €/Monat bis M18, danach Plan
A24: Freelance Design, Sound, Illustration → WortBild | C24: 15000 | D24: ='Liquidität 24M'!$AB$37+'Liquidität 24M'!$AB$45 -> 28125 | E24: 25000 | F24: ='Liquidität 24M'!$AC$37+'Liquidität 24M'!$AC$45 -> 21875 | G24: WortBild 37,5 T€ (M4–M15) statt Freelance-Pauschale
A25: Marketing, Creator-Programm, Events, Piloten | C25: 25000 | D25: ='Liquidität 24M'!$AB$34+'Liquidität 24M'!$AB$35+'Liquidität 24M'!$AB$36+'Liquidität 24M'!$AB$46 -> 32000 | E25: 60000 | F25: ='Liquidität 24M'!$AC$34+'Liquidität 24M'!$AC$35+'Liquidität 24M'!$AC$36+'Liquidität 24M'!$AC$46 -> 48000 | G25: 50 T€ in 18 Monaten inkl. 1 Pilot
A26: Infrastruktur, KI-API, Store-Gebühren | C26: 8000 | D26: ='Liquidität 24M'!$AB$85 -> 7043.52 | E26: 25000 | F26: ='Liquidität 24M'!$AC$85 -> 29843.2 | G26: fix 250 €/Monat + 8 % vom Umsatz
A27: Recht, Marke, Steuer, Verwaltung | C27: 12000 | D27: ='Liquidität 24M'!$AB$38+'Liquidität 24M'!$AB$47 -> 19000 | E27: 20000 | F27: ='Liquidität 24M'!$AC$38+'Liquidität 24M'!$AC$47 -> 16000 | G27: 25 T€ in 18 Monaten (Marke DE/EU/TR, DSFA)
A28: Summe Kosten Basis | C28: =SUM(C21:C27) -> 165000 | D28: =SUM(D21:D27) -> 166168.52 | E28: =SUM(E21:E27) -> 398000 | F28: =SUM(F21:F27) -> 294718.2
A29: Kontrolle: = Kosten Basis in der GuV (J1 / J2) | D29: =IF(ROUND(D28-'GuV 5 Jahre'!$C$37,0)=0,"OK","PRÜFEN") -> OK | F29: =IF(ROUND(F28-'GuV 5 Jahre'!$D$37,0)=0,"OK","PRÜFEN") -> OK

Sheet Liquidität 24M
A1: Liquidität monatlich, 24 Monate – Startkasse 250.000 € (Closing Jan 2027)
A2: Alle Werte sind Schätzungen auf Basis von BUSINESSPLAN.md §11 – es gibt noch keine Umsätze. Mittelverwendung, Gates und Bewertung: Vorschlag – mit Steuer-/Rechtsberater prüfen.
A4: Kennzahlen (Ziele/Schätzungen) – Runway, Kasse, Break-even, Folgerunde
A5: Kennzahl | B5: Einheit | C5: Konservativ | D5: Basis | E5: Optimistisch | F5: Ohne Umsatz | G5: Formel / Lesart
A6: Kasse Ende Monat 6 | B6: € | C6: =INDEX($D$67:$AA$67,6) -> 182724.59 | D6: =INDEX($D$88:$AA$88,6) -> 190750.12 | E6: =INDEX($D$109:$AA$109,6) -> 207666.16 | F6: =INDEX($D$117:$AA$117,6) -> 179125 | G6: INDEX in die Kassenzeile
A7: Kasse Ende Monat 12 | B7: € | C7: =INDEX($D$67:$AA$67,12) -> 102273.37 | D7: =INDEX($D$88:$AA$88,12) -> 134375.48 | E7: =INDEX($D$109:$AA$109,12) -> 202039.64 | F7: =INDEX($D$117:$AA$117,12) -> 87875
A8: Kasse Ende Monat 18 | B8: € | C8: =INDEX($D$67:$AA$67,18) -> 49061.051 | D8: =INDEX($D$88:$AA$88,18) -> 145794.06 | E8: =INDEX($D$109:$AA$109,18) -> 368913.1 | F8: =INDEX($D$117:$AA$117,18) -> 8000
A9: Kasse Ende Monat 24 | B9: € | C9: =INDEX($D$67:$AA$67,24) -> -11499.654 | D9: =INDEX($D$88:$AA$88,24) -> 175197.28 | E9: =INDEX($D$109:$AA$109,24) -> 697934.38 | F9: =INDEX($D$117:$AA$117,24) -> -62500
A10: Niedrigster Kassenstand M1–24 | B10: € | C10: =MIN($D$67:$AA$67) -> -11499.654 | D10: =MIN($D$88:$AA$88) -> 125383.57 | E10: =MIN($D$109:$AA$109) -> 196717.61 | F10: =MIN($D$117:$AA$117) -> -62500
A11: Monat des niedrigsten Kassenstands | B11: Monat | C11: =MATCH(MIN($D$67:$AA$67),$D$67:$AA$67,0) -> 24 | D11: =MATCH(MIN($D$88:$AA$88),$D$88:$AA$88,0) -> 15 | E11: =MATCH(MIN($D$109:$AA$109),$D$109:$AA$109,0) -> 9 | F11: =MATCH(MIN($D$117:$AA$117),$D$117:$AA$117,0) -> 24
A12: Cash-out-Monat (erster Monat mit Kasse < 0) | B12: Monat | C12: =IFERROR(MATCH(1,$D$68:$AA$68,0),"keiner bis M24") -> 23 | D12: =IFERROR(MATCH(1,$D$89:$AA$89,0),"keiner bis M24") -> keiner bis M24 | E12: =IFERROR(MATCH(1,$D$110:$AA$110,0),"keiner bis M24") -> keiner bis M24 | F12: =IFERROR(MATCH(1,$D$118:$AA$118,0),"keiner bis M24") -> 19 | G12: Text = Kasse bleibt bis Monat 24 positiv
A13: Runway in Monaten (bis Kasse < 0) | B13: Monate | C13: =IFERROR(MATCH(1,$D$68:$AA$68,0)-1,"> 24") -> 22 | D13: =IFERROR(MATCH(1,$D$89:$AA$89,0)-1,"> 24") -> > 24 | E13: =IFERROR(MATCH(1,$D$110:$AA$110,0)-1,"> 24") -> > 24 | F13: =IFERROR(MATCH(1,$D$118:$AA$118,0)-1,"> 24") -> 18 | G13: Monate mit positiver Kasse
A14: Nachhaltiger Break-even (ab diesem Monat Umsatz ≥ Kosten bis M24) | B14: Monat | C14: =IFERROR(MATCH(1,$D$70:$AA$70,0),"nach M24") -> nach M24 | D14: =IFERROR(MATCH(1,$D$91:$AA$91,0),"nach M24") -> 22 | E14: =IFERROR(MATCH(1,$D$112:$AA$112,0),"nach M24") -> 10 | G14: operativer Monats-Break-even inkl. Ausbau-Team ab M19
A15: Ø Kosten pro Monat M1–18 (Burn ohne Umsatz) | B15: €/Monat | F15: =SUM($D$116:$U$116)/18 -> 13444.444
A16: Kasse fällt unter Mindestkasse (3 laufende Monatskosten) in Monat | B16: Monat | C16: =IFERROR(MATCH(1,$D$71:$AA$71,0),"nie bis M24") -> 19 | D16: =IFERROR(MATCH(1,$D$92:$AA$92,0),"nie bis M24") -> nie bis M24 | E16: =IFERROR(MATCH(1,$D$113:$AA$113,0),"nie bis M24") -> nie bis M24
A17: Kasse Ende J3 ohne Folgerunde (Kasse M24 + EBITDA J3) | B17: € | C17: =C9+'GuV 5 Jahre'!$E$17 -> -70855.654 | D17: =D9+'GuV 5 Jahre'!$E$38 -> 503467.28 | E17: =E9+'GuV 5 Jahre'!$E$59 -> 2196874.4
A18: Mindestkasse = 3 Monatskosten J3 | B18: € | C18: =Annahmen!$B$14*'GuV 5 Jahre'!$E$16/12 -> 82500 | D18: =Annahmen!$B$14*'GuV 5 Jahre'!$E$37/12 -> 177500 | E18: =Annahmen!$B$14*'GuV 5 Jahre'!$E$58/12 -> 275000
A19: Liquiditätslücke bis Ende J3 = MAX(0; Mindestkasse − niedrigster Stand) | B19: € | C19: =MAX(0,C18-MIN(C10,C17)) -> 153355.65 | D19: =MAX(0,D18-MIN(D10,D17)) -> 52116.434 | E19: =MAX(0,E18-MIN(E10,E17)) -> 78282.39
A20: Nachgelagerte Linien (Story-Engine, Studio/Auto-Edit, VR/AR) ab M19 bis Ende J3 | B20: € | C20: =Annahmen!$B$15*(Annahmen!$B$16/2+Annahmen!$B$17) -> 160500 | D20: =Annahmen!$B$15*(Annahmen!$B$16/2+Annahmen!$B$17) -> 160500 | E20: =Annahmen!$B$15*(Annahmen!$B$16/2+Annahmen!$B$17) -> 160500 | G20: 60 % der Vision-Kosten BP §11.5 (½ J2 + J3)
A21: Folgerunde (Seed) – Mindestbedarf | B21: € | C21: =C19+C20 -> 313855.65 | D21: =D19+D20 -> 212616.43 | E21: =E19+E20 -> 238782.39
A22: Folgerunde spätestens abschließen bis Monat (Gate 2 = Monat 18) | B22: Monat | C22: =IF(ISNUMBER(C16),MIN(18,C16),18) -> 18 | D22: =IF(ISNUMBER(D16),MIN(18,D16),18) -> 18 | E22: =IF(ISNUMBER(E16),MIN(18,E16),18) -> 18 | G22: frühestens wenn Gate 2 erfüllt; Gespräche ab Monat 12–15 beginnen
A23: Seed-Richtwert für die Planung (deckt das konservative Szenario, auf 50 T€ gerundet) | B23: € | D23: =CEILING(MAX(C21:E21),50000) -> 350000
A27: Monat | D27: 1 | E27: 2 | F27: 3 | G27: 4 | H27: 5 | I27: 6 | J27: 7 | K27: 8 | L27: 9 | M27: 10 | N27: 11 | O27: 12 | P27: 13 | Q27: 14 | R27: 15 | S27: 16 | T27: 17 | U27: 18 | V27: 19 | W27: 20 | X27: 21 | Y27: 22 | Z27: 23 | AA27: 24 | AB27: Summe J1 | AC27: Summe J2 | AD27: Summe M1–18
A28: Kalendermonat | D28: 01/2027 | E28: 02/2027 | F28: 03/2027 | G28: 04/2027 | H28: 05/2027 | I28: 06/2027 | J28: 07/2027 | K28: 08/2027 | L28: 09/2027 | M28: 10/2027 | N28: 11/2027 | O28: 12/2027 | P28: 01/2028 | Q28: 02/2028 | R28: 03/2028 | S28: 04/2028 | T28: 05/2028 | U28: 06/2028 | V28: 07/2028 | W28: 08/2028 | X28: 09/2028 | Y28: 10/2028 | Z28: 11/2028 | AA28: 12/2028
A30: Kosten Pre-Seed (Monat 1–18, in allen Szenarien gleich) – aus Annahmen C
A31: Mobile-/Web-Entwickler:in (Vollzeit, ab Monat 3) | B31: € | D31: =IF(AND(D$27>=Annahmen!$D$51,D$27<=Annahmen!$E$51),Annahmen!$C$51,0)+IF(D$27=Annahmen!$G$51,Annahmen!$F$51,0) -> 0 | E31: =IF(AND(E$27>=Annahmen!$D$51,E$27<=Annahmen!$E$51),Annahmen!$C$51,0)+IF(E$27=Annahmen!$G$51,Annahmen!$F$51,0) -> 0 | F31: =IF(AND(F$27>=Annahmen!$D$51,F$27<=Annahmen!$E$51),Annahmen!$C$51,0)+IF(F$27=Annahmen!$G$51,Annahmen!$F$51,0) -> 5500 | G31: =IF(AND(G$27>=Annahmen!$D$51,G$27<=Annahmen!$E$51),Annahmen!$C$51,0)+IF(G$27=Annahmen!$G$51,Annahmen!$F$51,0) -> 5500 | H31: =IF(AND(H$27>=Annahmen!$D$51,H$27<=Annahmen!$E$51),Annahmen!$C$51,0)+IF(H$27=Annahmen!$G$51,Annahmen!$F$51,0) -> 5500 | I31: =IF(AND(I$27>=Annahmen!$D$51,I$27<=Annahmen!$E$51),Annahmen!$C$51,0)+IF(I$27=Annahmen!$G$51,Annahmen!$F$51,0) -> 5500 | J31: =IF(AND(J$27>=Annahmen!$D$51,J$27<=Annahmen!$E$51),Annahmen!$C$51,0)+IF(J$27=Annahmen!$G$51,Annahmen!$F$51,0) -> 5500 | K31: =IF(AND(K$27>=Annahmen!$D$51,K$27<=Annahmen!$E$51),Annahmen!$C$51,0)+IF(K$27=Annahmen!$G$51,Annahmen!$F$51,0) -> 5500 | ... AA31: =IF(AND(AA$27>=Annahmen!$D$51,AA$27<=Annahmen!$E$51),Annahmen!$C$51,0)+IF(AA$27=Annahmen!$G$51,Annahmen!$F$51,0) -> 0 | AB31: =SUM(D31:O31) -> 55000 | AC31: =SUM(P31:AA31) -> 33000 | AD31: =SUM(D31:U31) -> 88000
A32: Gründergehalt (anteilig) | B32: € | D32: =IF(AND(D$27>=Annahmen!$D$52,D$27<=Annahmen!$E$52),Annahmen!$C$52,0)+IF(D$27=Annahmen!$G$52,Annahmen!$F$52,0) -> 2000 | E32: =IF(AND(E$27>=Annahmen!$D$52,E$27<=Annahmen!$E$52),Annahmen!$C$52,0)+IF(E$27=Annahmen!$G$52,Annahmen!$F$52,0) -> 2000 | F32: =IF(AND(F$27>=Annahmen!$D$52,F$27<=Annahmen!$E$52),Annahmen!$C$52,0)+IF(F$27=Annahmen!$G$52,Annahmen!$F$52,0) -> 2000 | G32: =IF(AND(G$27>=Annahmen!$D$52,G$27<=Annahmen!$E$52),Annahmen!$C$52,0)+IF(G$27=Annahmen!$G$52,Annahmen!$F$52,0) -> 2000 | H32: =IF(AND(H$27>=Annahmen!$D$52,H$27<=Annahmen!$E$52),Annahmen!$C$52,0)+IF(H$27=Annahmen!$G$52,Annahmen!$F$52,0) -> 2000 | I32: =IF(AND(I$27>=Annahmen!$D$52,I$27<=Annahmen!$E$52),Annahmen!$C$52,0)+IF(I$27=Annahmen!$G$52,Annahmen!$F$52,0) -> 2000 | J32: =IF(AND(J$27>=Annahmen!$D$52,J$27<=Annahmen!$E$52),Annahmen!$C$52,0)+IF(J$27=Annahmen!$G$52,Annahmen!$F$52,0) -> 2000 | K32: =IF(AND(K$27>=Annahmen!$D$52,K$27<=Annahmen!$E$52),Annahmen!$C$52,0)+IF(K$27=Annahmen!$G$52,Annahmen!$F$52,0) -> 2000 | ... AA32: =IF(AND(AA$27>=Annahmen!$D$52,AA$27<=Annahmen!$E$52),Annahmen!$C$52,0)+IF(AA$27=Annahmen!$G$52,Annahmen!$F$52,0) -> 0 | AB32: =SUM(D32:O32) -> 24000 | AC32: =SUM(P32:AA32) -> 12000 | AD32: =SUM(D32:U32) -> 36000
A33: Entwicklungs-Tools, Testgeräte (iOS/Android) | B33: € | D33: =IF(AND(D$27>=Annahmen!$D$53,D$27<=Annahmen!$E$53),Annahmen!$C$53,0)+IF(D$27=Annahmen!$G$53,Annahmen!$F$53,0) -> 1000 | E33: =IF(AND(E$27>=Annahmen!$D$53,E$27<=Annahmen!$E$53),Annahmen!$C$53,0)+IF(E$27=Annahmen!$G$53,Annahmen!$F$53,0) -> 0 | F33: =IF(AND(F$27>=Annahmen!$D$53,F$27<=Annahmen!$E$53),Annahmen!$C$53,0)+IF(F$27=Annahmen!$G$53,Annahmen!$F$53,0) -> 0 | G33: =IF(AND(G$27>=Annahmen!$D$53,G$27<=Annahmen!$E$53),Annahmen!$C$53,0)+IF(G$27=Annahmen!$G$53,Annahmen!$F$53,0) -> 0 | H33: =IF(AND(H$27>=Annahmen!$D$53,H$27<=Annahmen!$E$53),Annahmen!$C$53,0)+IF(H$27=Annahmen!$G$53,Annahmen!$F$53,0) -> 0 | I33: =IF(AND(I$27>=Annahmen!$D$53,I$27<=Annahmen!$E$53),Annahmen!$C$53,0)+IF(I$27=Annahmen!$G$53,Annahmen!$F$53,0) -> 0 | J33: =IF(AND(J$27>=Annahmen!$D$53,J$27<=Annahmen!$E$53),Annahmen!$C$53,0)+IF(J$27=Annahmen!$G$53,Annahmen!$F$53,0) -> 0 | K33: =IF(AND(K$27>=Annahmen!$D$53,K$27<=Annahmen!$E$53),Annahmen!$C$53,0)+IF(K$27=Annahmen!$G$53,Annahmen!$F$53,0) -> 0 | ... AA33: =IF(AND(AA$27>=Annahmen!$D$53,AA$27<=Annahmen!$E$53),Annahmen!$C$53,0)+IF(AA$27=Annahmen!$G$53,Annahmen!$F$53,0) -> 0 | AB33: =SUM(D33:O33) -> 1000 | AC33: =SUM(P33:AA33) -> 0 | AD33: =SUM(D33:U33) -> 1000
A34: Creator-Programm, Community, Marketing – Phase 1 (TR-Launch) | B34: € | D34: =IF(AND(D$27>=Annahmen!$D$54,D$27<=Annahmen!$E$54),Annahmen!$C$54,0)+IF(D$27=Annahmen!$G$54,Annahmen!$F$54,0) -> 2000 | E34: =IF(AND(E$27>=Annahmen!$D$54,E$27<=Annahmen!$E$54),Annahmen!$C$54,0)+IF(E$27=Annahmen!$G$54,Annahmen!$F$54,0) -> 2000 | F34: =IF(AND(F$27>=Annahmen!$D$54,F$27<=Annahmen!$E$54),Annahmen!$C$54,0)+IF(F$27=Annahmen!$G$54,Annahmen!$F$54,0) -> 2000 | G34: =IF(AND(G$27>=Annahmen!$D$54,G$27<=Annahmen!$E$54),Annahmen!$C$54,0)+IF(G$27=Annahmen!$G$54,Annahmen!$F$54,0) -> 2000 | H34: =IF(AND(H$27>=Annahmen!$D$54,H$27<=Annahmen!$E$54),Annahmen!$C$54,0)+IF(H$27=Annahmen!$G$54,Annahmen!$F$54,0) -> 2000 | I34: =IF(AND(I$27>=Annahmen!$D$54,I$27<=Annahmen!$E$54),Annahmen!$C$54,0)+IF(I$27=Annahmen!$G$54,Annahmen!$F$54,0) -> 2000 | J34: =IF(AND(J$27>=Annahmen!$D$54,J$27<=Annahmen!$E$54),Annahmen!$C$54,0)+IF(J$27=Annahmen!$G$54,Annahmen!$F$54,0) -> 0 | K34: =IF(AND(K$27>=Annahmen!$D$54,K$27<=Annahmen!$E$54),Annahmen!$C$54,0)+IF(K$27=Annahmen!$G$54,Annahmen!$F$54,0) -> 0 | ... AA34: =IF(AND(AA$27>=Annahmen!$D$54,AA$27<=Annahmen!$E$54),Annahmen!$C$54,0)+IF(AA$27=Annahmen!$G$54,Annahmen!$F$54,0) -> 0 | AB34: =SUM(D34:O34) -> 12000 | AC34: =SUM(P34:AA34) -> 0 | AD34: =SUM(D34:U34) -> 12000
A35: Creator-Programm, Marketing, Marktplätze – Phase 2 (DE/EN, Partner) | B35: € | D35: =IF(AND(D$27>=Annahmen!$D$55,D$27<=Annahmen!$E$55),Annahmen!$C$55,0)+IF(D$27=Annahmen!$G$55,Annahmen!$F$55,0) -> 0 | E35: =IF(AND(E$27>=Annahmen!$D$55,E$27<=Annahmen!$E$55),Annahmen!$C$55,0)+IF(E$27=Annahmen!$G$55,Annahmen!$F$55,0) -> 0 | F35: =IF(AND(F$27>=Annahmen!$D$55,F$27<=Annahmen!$E$55),Annahmen!$C$55,0)+IF(F$27=Annahmen!$G$55,Annahmen!$F$55,0) -> 0 | G35: =IF(AND(G$27>=Annahmen!$D$55,G$27<=Annahmen!$E$55),Annahmen!$C$55,0)+IF(G$27=Annahmen!$G$55,Annahmen!$F$55,0) -> 0 | H35: =IF(AND(H$27>=Annahmen!$D$55,H$27<=Annahmen!$E$55),Annahmen!$C$55,0)+IF(H$27=Annahmen!$G$55,Annahmen!$F$55,0) -> 0 | I35: =IF(AND(I$27>=Annahmen!$D$55,I$27<=Annahmen!$E$55),Annahmen!$C$55,0)+IF(I$27=Annahmen!$G$55,Annahmen!$F$55,0) -> 0 | J35: =IF(AND(J$27>=Annahmen!$D$55,J$27<=Annahmen!$E$55),Annahmen!$C$55,0)+IF(J$27=Annahmen!$G$55,Annahmen!$F$55,0) -> 3000 | K35: =IF(AND(K$27>=Annahmen!$D$55,K$27<=Annahmen!$E$55),Annahmen!$C$55,0)+IF(K$27=Annahmen!$G$55,Annahmen!$F$55,0) -> 3000 | ... AA35: =IF(AND(AA$27>=Annahmen!$D$55,AA$27<=Annahmen!$E$55),Annahmen!$C$55,0)+IF(AA$27=Annahmen!$G$55,Annahmen!$F$55,0) -> 0 | AB35: =SUM(D35:O35) -> 18000 | AC35: =SUM(P35:AA35) -> 18000 | AD35: =SUM(D35:U35) -> 36000
A36: Plattform- oder Bildungspilot (8 Wochen, Material, Reisen) | B36: € | D36: =IF(AND(D$27>=Annahmen!$D$56,D$27<=Annahmen!$E$56),Annahmen!$C$56,0)+IF(D$27=Annahmen!$G$56,Annahmen!$F$56,0) -> 0 | E36: =IF(AND(E$27>=Annahmen!$D$56,E$27<=Annahmen!$E$56),Annahmen!$C$56,0)+IF(E$27=Annahmen!$G$56,Annahmen!$F$56,0) -> 0 | F36: =IF(AND(F$27>=Annahmen!$D$56,F$27<=Annahmen!$E$56),Annahmen!$C$56,0)+IF(F$27=Annahmen!$G$56,Annahmen!$F$56,0) -> 0 | G36: =IF(AND(G$27>=Annahmen!$D$56,G$27<=Annahmen!$E$56),Annahmen!$C$56,0)+IF(G$27=Annahmen!$G$56,Annahmen!$F$56,0) -> 0 | H36: =IF(AND(H$27>=Annahmen!$D$56,H$27<=Annahmen!$E$56),Annahmen!$C$56,0)+IF(H$27=Annahmen!$G$56,Annahmen!$F$56,0) -> 0 | I36: =IF(AND(I$27>=Annahmen!$D$56,I$27<=Annahmen!$E$56),Annahmen!$C$56,0)+IF(I$27=Annahmen!$G$56,Annahmen!$F$56,0) -> 0 | J36: =IF(AND(J$27>=Annahmen!$D$56,J$27<=Annahmen!$E$56),Annahmen!$C$56,0)+IF(J$27=Annahmen!$G$56,Annahmen!$F$56,0) -> 0 | K36: =IF(AND(K$27>=Annahmen!$D$56,K$27<=Annahmen!$E$56),Annahmen!$C$56,0)+IF(K$27=Annahmen!$G$56,Annahmen!$F$56,0) -> 0 | ... AA36: =IF(AND(AA$27>=Annahmen!$D$56,AA$27<=Annahmen!$E$56),Annahmen!$C$56,0)+IF(AA$27=Annahmen!$G$56,Annahmen!$F$56,0) -> 0 | AB36: =SUM(D36:O36) -> 2000 | AC36: =SUM(P36:AA36) -> 0 | AD36: =SUM(D36:U36) -> 2000
A37: Vision-Linie WortBild (Sprachenlernen): Illustration, Sprecher-Audios DE/TR/EN, Didaktik, Kurs-Pilot | B37: € | D37: =IF(AND(D$27>=Annahmen!$D$57,D$27<=Annahmen!$E$57),Annahmen!$C$57,0)+IF(D$27=Annahmen!$G$57,Annahmen!$F$57,0) -> 0 | E37: =IF(AND(E$27>=Annahmen!$D$57,E$27<=Annahmen!$E$57),Annahmen!$C$57,0)+IF(E$27=Annahmen!$G$57,Annahmen!$F$57,0) -> 0 | F37: =IF(AND(F$27>=Annahmen!$D$57,F$27<=Annahmen!$E$57),Annahmen!$C$57,0)+IF(F$27=Annahmen!$G$57,Annahmen!$F$57,0) -> 0 | G37: =IF(AND(G$27>=Annahmen!$D$57,G$27<=Annahmen!$E$57),Annahmen!$C$57,0)+IF(G$27=Annahmen!$G$57,Annahmen!$F$57,0) -> 3125 | H37: =IF(AND(H$27>=Annahmen!$D$57,H$27<=Annahmen!$E$57),Annahmen!$C$57,0)+IF(H$27=Annahmen!$G$57,Annahmen!$F$57,0) -> 3125 | I37: =IF(AND(I$27>=Annahmen!$D$57,I$27<=Annahmen!$E$57),Annahmen!$C$57,0)+IF(I$27=Annahmen!$G$57,Annahmen!$F$57,0) -> 3125 | J37: =IF(AND(J$27>=Annahmen!$D$57,J$27<=Annahmen!$E$57),Annahmen!$C$57,0)+IF(J$27=Annahmen!$G$57,Annahmen!$F$57,0) -> 3125 | K37: =IF(AND(K$27>=Annahmen!$D$57,K$27<=Annahmen!$E$57),Annahmen!$C$57,0)+IF(K$27=Annahmen!$G$57,Annahmen!$F$57,0) -> 3125 | ... AA37: =IF(AND(AA$27>=Annahmen!$D$57,AA$27<=Annahmen!$E$57),Annahmen!$C$57,0)+IF(AA$27=Annahmen!$G$57,Annahmen!$F$57,0) -> 0 | AB37: =SUM(D37:O37) -> 28125 | AC37: =SUM(P37:AA37) -> 9375 | AD37: =SUM(D37:U37) -> 37500
A38: Recht, Marke (DE/EU/TR), Datenschutz/DSFA, Jugendschutz, Steuerberatung | B38: € | D38: =IF(AND(D$27>=Annahmen!$D$58,D$27<=Annahmen!$E$58),Annahmen!$C$58,0)+IF(D$27=Annahmen!$G$58,Annahmen!$F$58,0) -> 8000 | E38: =IF(AND(E$27>=Annahmen!$D$58,E$27<=Annahmen!$E$58),Annahmen!$C$58,0)+IF(E$27=Annahmen!$G$58,Annahmen!$F$58,0) -> 1000 | F38: =IF(AND(F$27>=Annahmen!$D$58,F$27<=Annahmen!$E$58),Annahmen!$C$58,0)+IF(F$27=Annahmen!$G$58,Annahmen!$F$58,0) -> 1000 | G38: =IF(AND(G$27>=Annahmen!$D$58,G$27<=Annahmen!$E$58),Annahmen!$C$58,0)+IF(G$27=Annahmen!$G$58,Annahmen!$F$58,0) -> 1000 | H38: =IF(AND(H$27>=Annahmen!$D$58,H$27<=Annahmen!$E$58),Annahmen!$C$58,0)+IF(H$27=Annahmen!$G$58,Annahmen!$F$58,0) -> 1000 | I38: =IF(AND(I$27>=Annahmen!$D$58,I$27<=Annahmen!$E$58),Annahmen!$C$58,0)+IF(I$27=Annahmen!$G$58,Annahmen!$F$58,0) -> 1000 | J38: =IF(AND(J$27>=Annahmen!$D$58,J$27<=Annahmen!$E$58),Annahmen!$C$58,0)+IF(J$27=Annahmen!$G$58,Annahmen!$F$58,0) -> 1000 | K38: =IF(AND(K$27>=Annahmen!$D$58,K$27<=Annahmen!$E$58),Annahmen!$C$58,0)+IF(K$27=Annahmen!$G$58,Annahmen!$F$58,0) -> 1000 | ... AA38: =IF(AND(AA$27>=Annahmen!$D$58,AA$27<=Annahmen!$E$58),Annahmen!$C$58,0)+IF(AA$27=Annahmen!$G$58,Annahmen!$F$58,0) -> 0 | AB38: =SUM(D38:O38) -> 19000 | AC38: =SUM(P38:AA38) -> 6000 | AD38: =SUM(D38:U38) -> 25000
A39: Summe Pre-Seed-Kosten | D39: =SUM(D31:D38) -> 13000 | E39: =SUM(E31:E38) -> 5000 | F39: =SUM(F31:F38) -> 10500 | G39: =SUM(G31:G38) -> 13625 | H39: =SUM(H31:H38) -> 13625 | I39: =SUM(I31:I38) -> 13625 | J39: =SUM(J31:J38) -> 14625 | K39: =SUM(K31:K38) -> 14625 | ... AA39: =SUM(AA31:AA38) -> 0 | AB39: =SUM(D39:O39) -> 159125 | AC39: =SUM(P39:AA39) -> 78375 | AD39: =SUM(D39:U39) -> 237500
A41: Ausbau-Team ab Monat 19 (Basis; Szenarien × Ausbau-Faktor) – aus Annahmen D
A42: Personal: Mobile-/Web-Entwicklung (2 Personen) | B42: Mobile/Web | D42: =IF(D$27>=Annahmen!$B$18,Annahmen!$D$64,0) -> 0 | E42: =IF(E$27>=Annahmen!$B$18,Annahmen!$D$64,0) -> 0 | F42: =IF(F$27>=Annahmen!$B$18,Annahmen!$D$64,0) -> 0 | G42: =IF(G$27>=Annahmen!$B$18,Annahmen!$D$64,0) -> 0 | H42: =IF(H$27>=Annahmen!$B$18,Annahmen!$D$64,0) -> 0 | I42: =IF(I$27>=Annahmen!$B$18,Annahmen!$D$64,0) -> 0 | J42: =IF(J$27>=Annahmen!$B$18,Annahmen!$D$64,0) -> 0 | K42: =IF(K$27>=Annahmen!$B$18,Annahmen!$D$64,0) -> 0 | ... AA42: =IF(AA$27>=Annahmen!$B$18,Annahmen!$D$64,0) -> 13333.333 | AB42: =SUM(D42:O42) -> 0 | AC42: =SUM(P42:AA42) -> 80000 | AD42: =SUM(D42:U42) -> 0
A43: Personal: Backend/ML, Community/Support | B43: Backend/Community | D43: =IF(D$27>=Annahmen!$B$18,Annahmen!$D$65,0) -> 0 | E43: =IF(E$27>=Annahmen!$B$18,Annahmen!$D$65,0) -> 0 | F43: =IF(F$27>=Annahmen!$B$18,Annahmen!$D$65,0) -> 0 | G43: =IF(G$27>=Annahmen!$B$18,Annahmen!$D$65,0) -> 0 | H43: =IF(H$27>=Annahmen!$B$18,Annahmen!$D$65,0) -> 0 | I43: =IF(I$27>=Annahmen!$B$18,Annahmen!$D$65,0) -> 0 | J43: =IF(J$27>=Annahmen!$B$18,Annahmen!$D$65,0) -> 0 | K43: =IF(K$27>=Annahmen!$B$18,Annahmen!$D$65,0) -> 0 | ... AA43: =IF(AA$27>=Annahmen!$B$18,Annahmen!$D$65,0) -> 5000 | AB43: =SUM(D43:O43) -> 0 | AC43: =SUM(P43:AA43) -> 30000 | AD43: =SUM(D43:U43) -> 0
A44: Gründer (Gehalt) | B44: Gründer | D44: =IF(D$27>=Annahmen!$B$18,Annahmen!$D$66,0) -> 0 | E44: =IF(E$27>=Annahmen!$B$18,Annahmen!$D$66,0) -> 0 | F44: =IF(F$27>=Annahmen!$B$18,Annahmen!$D$66,0) -> 0 | G44: =IF(G$27>=Annahmen!$B$18,Annahmen!$D$66,0) -> 0 | H44: =IF(H$27>=Annahmen!$B$18,Annahmen!$D$66,0) -> 0 | I44: =IF(I$27>=Annahmen!$B$18,Annahmen!$D$66,0) -> 0 | J44: =IF(J$27>=Annahmen!$B$18,Annahmen!$D$66,0) -> 0 | K44: =IF(K$27>=Annahmen!$B$18,Annahmen!$D$66,0) -> 0 | ... AA44: =IF(AA$27>=Annahmen!$B$18,Annahmen!$D$66,0) -> 4000 | AB44: =SUM(D44:O44) -> 0 | AC44: =SUM(P44:AA44) -> 24000 | AD44: =SUM(D44:U44) -> 0
A45: Freelance Design, Sound, Illustration (Packs, WortBild) | B45: Freelance/WortBild | D45: =IF(D$27>=Annahmen!$B$18,Annahmen!$D$67,0) -> 0 | E45: =IF(E$27>=Annahmen!$B$18,Annahmen!$D$67,0) -> 0 | F45: =IF(F$27>=Annahmen!$B$18,Annahmen!$D$67,0) -> 0 | G45: =IF(G$27>=Annahmen!$B$18,Annahmen!$D$67,0) -> 0 | H45: =IF(H$27>=Annahmen!$B$18,Annahmen!$D$67,0) -> 0 | I45: =IF(I$27>=Annahmen!$B$18,Annahmen!$D$67,0) -> 0 | J45: =IF(J$27>=Annahmen!$B$18,Annahmen!$D$67,0) -> 0 | K45: =IF(K$27>=Annahmen!$B$18,Annahmen!$D$67,0) -> 0 | ... AA45: =IF(AA$27>=Annahmen!$B$18,Annahmen!$D$67,0) -> 2083.3333 | AB45: =SUM(D45:O45) -> 0 | AC45: =SUM(P45:AA45) -> 12500 | AD45: =SUM(D45:U45) -> 0
A46: Marketing, Creator-Partnerprogramm, Events | B46: Marketing | D46: =IF(D$27>=Annahmen!$B$18,Annahmen!$D$68,0) -> 0 | E46: =IF(E$27>=Annahmen!$B$18,Annahmen!$D$68,0) -> 0 | F46: =IF(F$27>=Annahmen!$B$18,Annahmen!$D$68,0) -> 0 | G46: =IF(G$27>=Annahmen!$B$18,Annahmen!$D$68,0) -> 0 | H46: =IF(H$27>=Annahmen!$B$18,Annahmen!$D$68,0) -> 0 | I46: =IF(I$27>=Annahmen!$B$18,Annahmen!$D$68,0) -> 0 | J46: =IF(J$27>=Annahmen!$B$18,Annahmen!$D$68,0) -> 0 | K46: =IF(K$27>=Annahmen!$B$18,Annahmen!$D$68,0) -> 0 | ... AA46: =IF(AA$27>=Annahmen!$B$18,Annahmen!$D$68,0) -> 5000 | AB46: =SUM(D46:O46) -> 0 | AC46: =SUM(P46:AA46) -> 30000 | AD46: =SUM(D46:U46) -> 0
...

Sheet Gates 18M
A1: Gates / Meilensteine für 18 Monate – alle Werte sind ZIELE (Basis), Schwelle = konservativ
A2: Vorschlag – mit Investor:innen abstimmen. Nutzer/Pro-Ziele aus dem Modell: J1 linear auf den Jahresendwert, J2 linear zwischen den Jahresendwerten.
A4: Gate | B4: Monat | C4: Thema | D4: KPI | E4: Ziel Basis | F4: Schwelle (kons.) | G4: Optimistisch | H4: Status | I4: Gibt frei
A5: G0 | B5: 3 | C5: Start | D5: Pro-Abo live (Zahlung), Mobile-/Web-Entwickler:in an Bord | H5: Ziel (nicht erreicht) | I5: Budget Markteintritt Phase 2
A6: G1 | B6: 6 | C6: Aktivierung | D6: Registrierte Nutzer | E6: =Annahmen!$D$22*6/12 -> 10000 | F6: =Annahmen!$C$22*6/12 -> 4000 | G6: =Annahmen!$E$22*6/12 -> 20000 | H6: Ziel (nicht erreicht) | I6: Mobile-App/PWA-Release
A7: G1 | B7: 6 | C7: Aktivierung | D7: Zahlende Pro-Nutzer | E7: =Annahmen!$D$22*6/12*Annahmen!$D$27 -> 400 | F7: =Annahmen!$C$22*6/12*Annahmen!$C$27 -> 120 | G7: =Annahmen!$E$22*6/12*Annahmen!$E$27 -> 1000 | H7: Ziel (nicht erreicht)
A8: G1 | B8: 6 | C8: Aktivierung | D8: 20 Beta-Creator TR/DE aktiv, 10–20 Botschafter:innen; WortBild mit 300 Wörtern | H8: Ziel (nicht erreicht)
A9: G1 | B9: 6 | C9: Aktivierung | D9: Woche-4-Retention aktiver Streamer ≥ 30 % (Ziel, erste Kohorten) | H9: Ziel (nicht erreicht)
A10: G2a | B10: 12 | C10: Traktion | D10: Registrierte Nutzer | E10: =Annahmen!$D$22*12/12 -> 20000 | F10: =Annahmen!$C$22*12/12 -> 8000 | G10: =Annahmen!$E$22*12/12 -> 40000 | H10: Ziel (nicht erreicht) | I10: DE/EN-Ausbau, Plattform-Gespräche
A11: G2a | B11: 12 | C11: Traktion | D11: Zahlende Pro-Nutzer (Jahresende J1, BP §11.1) | E11: =Annahmen!$D$22*12/12*Annahmen!$D$27 -> 800 | F11: =Annahmen!$C$22*12/12*Annahmen!$C$27 -> 240 | G11: =Annahmen!$E$22*12/12*Annahmen!$E$27 -> 2000 | H11: Ziel (nicht erreicht)
A12: G2a | B12: 12 | C12: Traktion | D12: Wiederkehrender Umsatz im Monat 12 (MRR, €) | E12: =INDEX('Liquidität 24M'!$D$80:$AA$80,12) -> 8073 | F12: =INDEX('Liquidität 24M'!$D$59:$AA$59,12) -> 2499.7167 | G12: =INDEX('Liquidität 24M'!$D$101:$AA$101,12) -> 19820.25 | H12: Ziel (nicht erreicht)
A13: G2a | B13: 12 | C13: Traktion | D13: 1 Plattform- oder Bildungspilot gestartet; WortBild-Pilot in ≥ 3 Kursen/Klassen | H13: Ziel (nicht erreicht)
A14: G2 | B14: 18 | C14: Folgerunde | D14: Registrierte Nutzer | E14: =(Annahmen!$D$22+(Annahmen!$D$23-Annahmen!$D$22)*6/12) -> 50000 | F14: =(Annahmen!$C$22+(Annahmen!$C$23-Annahmen!$C$22)*6/12) -> 19000 | G14: =(Annahmen!$E$22+(Annahmen!$E$23-Annahmen!$E$22)*6/12) -> 110000 | H14: Ziel (nicht erreicht) | I14: Seed-Runde, Ausbau-Team ab M19, Story-Engine/Studio
A15: G2 | B15: 18 | C15: Folgerunde | D15: Zahlende Pro-Nutzer | E15: =(Annahmen!$D$22+(Annahmen!$D$23-Annahmen!$D$22)*6/12)*Annahmen!$D$27 -> 2000 | F15: =(Annahmen!$C$22+(Annahmen!$C$23-Annahmen!$C$22)*6/12)*Annahmen!$C$27 -> 570 | G15: =(Annahmen!$E$22+(Annahmen!$E$23-Annahmen!$E$22)*6/12)*Annahmen!$E$27 -> 5500 | H15: Ziel (nicht erreicht)
A16: G2 | B16: 18 | C16: Folgerunde | D16: Wiederkehrender Umsatz im Monat 18 (MRR, €) | E16: =INDEX('Liquidität 24M'!$D$80:$AA$80,18) -> 22585.615 | F16: =INDEX('Liquidität 24M'!$D$59:$AA$59,18) -> 6494.8244 | G16: =INDEX('Liquidität 24M'!$D$101:$AA$101,18) -> 62472.635 | H16: Ziel (nicht erreicht)
A17: G2 | B17: 18 | C17: Folgerunde | D17: Monat-3-Retention Pro ≥ 75 %; Conversion Free → Pro ≥ 3 % (Schwelle) / 4 % (Ziel) | H17: Ziel (nicht erreicht)
A18: G2 | B18: 18 | C18: Folgerunde | D18: WortBild-Pilot ausgewertet; ≥ 5 zahlende Schulen oder Kurse (BP §11.5) | H18: Ziel (nicht erreicht)
A20: Lesart: Gate erfüllt, wenn mindestens die Schwelle (konservatives Szenario) erreicht ist; das Ziel ist das Basis-Szenario.

Sheet Bewertung
A1: Bewertung Pre-Seed – Referenzmethoden (Investorensicht) und Angebot der Gründer (Vorschlag – mit Steuer-/Rechtsberater prüfen)
A2: Alle Eingaben blau; Quellen in Spalte G. „Gründer-Sicht“ = bewusst großzügig gerechnet, jede Annahme belegt und als Gründer-Annahme gekennzeichnet; „konservativ“ = frühere Investorensicht zum Vergleich. Keine Umsätze, Produkt v2.1.
A3: Teil A (1–5): Referenzmethoden (Investorensicht) – Berkus, Scorecard, VC-Methode, Risk Factor Summation. Teil B (6–10): Angebot der Gründer, Verhandlungsspanne, 10×-Prüfung, Begründung, Wandeldarlehen/SAFE. $→€ jeweils 1:1 (Annahme).
A5: 1. Referenzmethode (Investorensicht): Berkus – Gründer-Sicht und konservativ
A6: Max. € je Faktor – Gründer-Sicht (moderne „moderate 2×“-Variante) | B6: 1000000 | G6: Gründer-Annahme: moderne Berkus-Anpassung „moderat (2×)“ mit 0–1 Mio. $ je Faktor, max. 5 Mio. $ (valu.vc 2026; icanpitch 2026). Begründung: Berkus zuletzt 2016 aktualisiert, Seed-Bewertungen seitdem deutlich gestiegen.
A7: Max. € je Faktor – konservativ (klassisch, Dave Berkus) | B7: 500000 | G7: Original-Methode: bis 0,5 Mio. $ je Faktor, max. 2,5 Mio. $ (berkus.com).
A8: Faktor | B8: Score Gründer (0–1) | C8: Wert Gründer € | D8: Score konservativ | E8: Wert konservativ € | G8: Begründung (Gründer-Sicht · konservativ)
A9: Idee / Grundwert (Problem, Markt) | B9: 0.7 | C9: =Bewertung!$B$6*B9 -> 700000 | D9: 0.6 | E9: =Bewertung!$B$7*D9 -> 300000 | G9: Hoch: neuer Auslöser Stimme → Effekt, großer Markt (BP §6) · konservativ: Zahlungsbereitschaft unbewiesen.
A10: Prototyp / Produkt (Technologierisiko) | B10: 0.8 | C10: =Bewertung!$B$6*B10 -> 800000 | D10: 0.7 | E10: =Bewertung!$B$7*D10 -> 350000 | G10: Hoch: v2.1 funktionsfähig und getestet (575+ automatisierte Tests, e2e-Suite), 238 Trigger + 143 freie Sticker, Leistungsmodus, sichere GIF-Suche, im Einsatz in eigenen Streams · nicht 1,0: noch keine zahlenden Nutzer.
A11: Team (Umsetzungsqualität) | B11: 0.5 | C11: =Bewertung!$B$6*B11 -> 500000 | D11: 0.3 | E11: =Bewertung!$B$7*D11 -> 150000 | G11: Mittel: Gründer hat Produkt allein bis v2.1 gebaut + Investor Relations · konservativ: Solo-Gründer, Ein-Personen-Risiko (BP §13).
A12: Strategische Beziehungen | B12: 0.25 | C12: =Bewertung!$B$6*B12 -> 250000 | D12: 0.1 | E12: =Bewertung!$B$7*D12 -> 50000 | G12: Niedrig–mittel: eigene TR-Community, Gespräche mit Plattform-/Bildungspartnern geplant · keine Partnerschaft unterzeichnet.
A13: Produkteinführung / Umsatz | B13: 0.1 | C13: =Bewertung!$B$6*B13 -> 100000 | D13: 0.1 | E13: =Bewertung!$B$7*D13 -> 50000 | G13: Niedrig (beide Sichten): noch kein Umsatz; Pro-Abo ab Monat 3.
A14: Berkus-Wert (Pre-Money) | C14: =SUM(C9:C13) -> 2350000 | E14: =SUM(E9:E13) -> 900000
A16: 2. Referenzmethode (Investorensicht): Scorecard (Payne) – Gründer-Sicht und konservativ
A17: Referenz-Pre-Money Pre-Seed – Gründer-Sicht | B17: 2500000 | G17: Gründer-Annahme 2,5 Mio. €: im unteren Teil der DACH-Pre-Seed-Spanne 1,5–5 Mio. € (upxcale; Mitte wäre 3,25 Mio. €) und DE 1–5 Mio. € (capvisory; Mitte 3 Mio. €), deutlich unter dem Europa-Median 4,57 Mio. $ ≈ 4,2 Mio. € (Equidam Q1 2025).
A18: Referenz-Pre-Money Pre-Seed – konservativ (DACH/TR, Solo, pre-revenue) | B18: 1500000 | G18: DE Pre-Seed typ. 0,5–1,5 Mio. € (upxcale); Türkiye niedriger → 1,5 Mio. € (Schätzung, frühere Investorensicht).
A19: Faktor | B19: Gewicht | C19: Vergleich Gründer (100 % = Referenz) | D19: Beitrag Gründer | E19: Vergleich konservativ | F19: Beitrag konservativ | G19: Begründung (Gründer-Sicht · konservativ)
A20: Team | B20: 0.3 | C20: 1 | D20: =B20*C20 -> 0.3 | E20: 0.6 | F20: =B20*E20 -> 0.18 | G20: Durchschnitt: Produkt bis v2.1 allein gebaut, Streamer/Autor mit Community · konservativ: Solo, Hires offen
A21: Marktgröße / Chance | B21: 0.25 | C21: 1.4 | D21: =B21*C21 -> 0.35 | E21: 1.25 | F21: =B21*E21 -> 0.3125 | G21: Stark: Live-Streaming 97–157 Mrd. USD, SAM 1–3 Mio. Creator (BP §6) + Vision-Märkte A–D
A22: Produkt / Technologie | B22: 0.15 | C22: 1.4 | D22: =B22*C22 -> 0.21 | E22: 1.2 | F22: =B22*E22 -> 0.18 | G22: Stark: ausgeliefertes v2.1 mit 575+ Tests und e2e-Suite, lokale Verarbeitung, geringe Grenzkosten
A23: Wettbewerbsumfeld | B23: 0.1 | C23: 1.3 | D23: =B23*C23 -> 0.13 | E23: 0.9 | F23: =B23*E23 -> 0.09 | G23: Günstig: kein direkter Sprach-Trigger-Wettbewerber (Nische) · Risiko: Plattformen können nachbauen
A24: Marketing / Vertrieb / Partner | B24: 0.1 | C24: 0.8 | D24: =B24*C24 -> 0.08 | E24: 0.7 | F24: =B24*E24 -> 0.07 | G24: Unter Durchschnitt: eigene Streams + TR-Community, noch keine Partner/Vertrieb
A25: Bedarf weiterer Finanzierung | B25: 0.05 | C25: 1 | D25: =B25*C25 -> 0.05 | E25: 1 | F25: =B25*E25 -> 0.05 | G25: Neutral: schlanke Runde mit Gates; Folgerunde nötig (siehe Liquidität)
A26: Sonstiges (IP, Bildung, Datenschutz lokal) | B26: 0.05 | C26: 1.2 | D26: =B26*C26 -> 0.06 | E26: 1.1 | F26: =B26*E26 -> 0.055 | G26: Eigene Inhalte/IP, WortBild als zweites Standbein, offline-fähig
A27: Summe Gewichte / Faktor | B27: =SUM(B20:B26) -> 1 | D27: =SUM(D20:D26) -> 1.18 | F27: =SUM(F20:F26) -> 0.9375
A28: Scorecard-Wert (Pre-Money) | D28: =Bewertung!$B$17*D27 -> 2950000 | F28: =Bewertung!$B$18*F27 -> 1406250
A30: 3. Referenzmethode (Investorensicht): VC-Methode (Exit Jahr 5)
A31: Position | B31: Gründer: Optimistisch (Upside) | C31: Gründer: Basis (2. Linie) | D31: Konservativ: Basis | G31: Quelle / Kennzeichnung
A32: Umsatz J5 (aus GuV) | B32: ='GuV 5 Jahre'!$G$57 -> 7444105 | C32: ='GuV 5 Jahre'!$G$36 -> 3151812.5 | D32: ='GuV 5 Jahre'!$G$36 -> 3151812.5 | G32: GuV 5 Jahre, J5 (2031): optimistisches bzw. Basis-Szenario
A33: Exit-Multiple (Umsatz) | B33: 6 | C33: 6 | D33: 4 | G33: Gründer-Annahme 6,0x: SaaS Capital 2025 – VC-finanzierte private SaaS 5,3x (bootstrapped 4,8x) + Wachstumsaufschlag; konservativ 4,0x (B2C-/Creator-Abschlag, unter 2 Mio. USD ARR 2–3,5x).
A34: Exit-Wert Jahr 5 = Umsatz × Multiple | B34: =B32*B33 -> 44664630 | C34: =C32*C33 -> 18910875 | D34: =D32*D33 -> 12607250
A35: Ziel-Rendite (Multiple auf Einsatz) | B35: 10 | C35: 10 | D35: 15 | G35: Gründer-Annahme 10x = Untergrenze der Pre-Seed-üblichen 10–20x; konservativ Mittelwert 15x.
A36: Verwässerung durch spätere Runden (Seed, Series A, ESOP) | B36: 0.4 | C36: 0.4 | D36: 0.45 | G36: Carta 2025: Seed ≈ 20 %, Series A ≈ 18 % → 1 − 0,8 × 0,82 ≈ 34 %; Gründer-Annahme 40 % (ohne vollen ESOP), konservativ 45 % (inkl. ESOP ≈ 10 %).
A37: Post-Money heute = Exit ÷ Ziel-Rendite × (1 − Verwässerung) | B37: =B34/B35*(1-B36) -> 2679877.8 | C37: =C34/C35*(1-C36) -> 1134652.5 | D37: =D34/D35*(1-D36) -> 462265.83
A38: Investition (Pre-Seed) | B38: =Annahmen!$B$6 -> 250000 | C38: =Annahmen!$B$6 -> 250000 | D38: =Annahmen!$B$6 -> 250000
A39: VC-Wert (Pre-Money) = Post-Money − Investition | B39: =MAX(0,B37-B38) -> 2429877.8 | C39: =MAX(0,C37-C38) -> 884652.5 | D39: =MAX(0,D37-D38) -> 212265.83 | G39: Untergrenze 0
A41: VC-Methode (Umsatz J5 Basis, Verwässerung konservativ): Pre-Money bei Exit-Multiple (Zeilen) × Ziel-Rendite (Spalten)
A42: Multiple ↓ / Rendite → | B42: 10 | C42: 15 | D42: 20
A43: 3 | B43: =MAX(0,Bewertung!$D$32*$A43/B$42*(1-Bewertung!$D$36)-Bewertung!$D$38) -> 270049.06 | C43: =MAX(0,Bewertung!$D$32*$A43/C$42*(1-Bewertung!$D$36)-Bewertung!$D$38) -> 96699.375 | D43: =MAX(0,Bewertung!$D$32*$A43/D$42*(1-Bewertung!$D$36)-Bewertung!$D$38) -> 10024.531
A44: 4 | B44: =MAX(0,Bewertung!$D$32*$A44/B$42*(1-Bewertung!$D$36)-Bewertung!$D$38) -> 443398.75 | C44: =MAX(0,Bewertung!$D$32*$A44/C$42*(1-Bewertung!$D$36)-Bewertung!$D$38) -> 212265.83 | D44: =MAX(0,Bewertung!$D$32*$A44/D$42*(1-Bewertung!$D$36)-Bewertung!$D$38) -> 96699.375
...

Sheet Sensitivität
A1: Sensitivität (Basis-Szenario): Umsatz J3 und Runway
A2: Conversion ±1 Pkt., ARPU ±20 %, Nutzer ±30 % – je Fall alle Jahre; Kosten wie Basis (Infrastruktur variabel mit Umsatz).
A4: Fall | B4: Δ Conversion | C4: ARPU-Faktor | D4: Nutzer-Faktor | E4: Umsatz J3 € | F4: Δ zu Basis | G4: Wiederk. J1 € | H4: Wiederk. J2 € | I4: s (Dez J1) | J4: g (Zuwachs J2) | K4: Runway (Monate) | L4: Cash-out-Monat | M4: Kasse M12 € | N4: Kasse M18 € | O4: Kasse M24 € | P4: Min. Kasse €
A5: Basis | B5: 0 | C5: 1 | D5: 1 | E5: =('GuV 5 Jahre'!$E$27*$D5)*('GuV 5 Jahre'!$E$28+$B5)*Annahmen!$B$13*Annahmen!$D$30*$C5*12+('GuV 5 Jahre'!$E$27*$D5)*Annahmen!$D$31*Annahmen!$B$10+'GuV 5 Jahre'!$E$33+'GuV 5 Jahre'!$E$35 -> 1038270 | F5: =E5/$E$5-1 -> 0 | G5: =('GuV 5 Jahre'!$C$27*$D5)*('GuV 5 Jahre'!$C$28+$B5)*Annahmen!$B$12*Annahmen!$D$30*$C5*12+('GuV 5 Jahre'!$C$27*$D5)*Annahmen!$D$31*Annahmen!$B$10+'GuV 5 Jahre'!$C$33 -> 50544 | H5: =('GuV 5 Jahre'!$D$27*$D5)*('GuV 5 Jahre'!$D$28+$B5)*Annahmen!$B$13*Annahmen!$D$30*$C5*12+('GuV 5 Jahre'!$D$27*$D5)*Annahmen!$D$31*Annahmen!$B$10+'GuV 5 Jahre'!$D$33 -> 285540 | I5: =G5*11.5/72 -> 8073 | J5: =(H5-12*I5)/78 -> 2418.7692 | K5: =IFERROR(MATCH(1,$E$18:$AB$18,0)-1,"> 24") -> > 24 | L5: =IFERROR(MATCH(1,$E$18:$AB$18,0),"keiner") -> keiner | M5: =INDEX($E$17:$AB$17,12) -> 134375.48 | N5: =INDEX($E$17:$AB$17,18) -> 145794.06 | O5: =INDEX($E$17:$AB$17,24) -> 175197.28 | P5: =MIN($E$17:$AB$17) -> 125383.57
A6: Conversion −1 Pkt. | B6: -0.01 | C6: 1 | D6: 1 | E6: =('GuV 5 Jahre'!$E$27*$D6)*('GuV 5 Jahre'!$E$28+$B6)*Annahmen!$B$13*Annahmen!$D$30*$C6*12+('GuV 5 Jahre'!$E$27*$D6)*Annahmen!$D$31*Annahmen!$B$10+'GuV 5 Jahre'!$E$33+'GuV 5 Jahre'!$E$35 -> 847020 | F6: =E6/$E$5-1 -> -0.18420064 | G6: =('GuV 5 Jahre'!$C$27*$D6)*('GuV 5 Jahre'!$C$28+$B6)*Annahmen!$B$12*Annahmen!$D$30*$C6*12+('GuV 5 Jahre'!$C$27*$D6)*Annahmen!$D$31*Annahmen!$B$10+'GuV 5 Jahre'!$C$33 -> 40344 | H6: =('GuV 5 Jahre'!$D$27*$D6)*('GuV 5 Jahre'!$D$28+$B6)*Annahmen!$B$13*Annahmen!$D$30*$C6*12+('GuV 5 Jahre'!$D$27*$D6)*Annahmen!$D$31*Annahmen!$B$10+'GuV 5 Jahre'!$D$33 -> 224340 | I6: =G6*11.5/72 -> 6443.8333 | J6: =(H6-12*I6)/78 -> 1884.7949 | K6: =IFERROR(MATCH(1,$E$22:$AB$22,0)-1,"> 24") -> > 24 | L6: =IFERROR(MATCH(1,$E$22:$AB$22,0),"keiner") -> keiner | M6: =INDEX($E$21:$AB$21,12) -> 124991.48 | N6: =INDEX($E$21:$AB$21,18) -> 117100.68 | O6: =INDEX($E$21:$AB$21,24) -> 109509.28 | P6: =MIN($E$21:$AB$21) -> 82501.928
A7: Conversion +1 Pkt. | B7: 0.01 | C7: 1 | D7: 1 | E7: =('GuV 5 Jahre'!$E$27*$D7)*('GuV 5 Jahre'!$E$28+$B7)*Annahmen!$B$13*Annahmen!$D$30*$C7*12+('GuV 5 Jahre'!$E$27*$D7)*Annahmen!$D$31*Annahmen!$B$10+'GuV 5 Jahre'!$E$33+'GuV 5 Jahre'!$E$35 -> 1229520 | F7: =E7/$E$5-1 -> 0.18420064 | G7: =('GuV 5 Jahre'!$C$27*$D7)*('GuV 5 Jahre'!$C$28+$B7)*Annahmen!$B$12*Annahmen!$D$30*$C7*12+('GuV 5 Jahre'!$C$27*$D7)*Annahmen!$D$31*Annahmen!$B$10+'GuV 5 Jahre'!$C$33 -> 60744 | H7: =('GuV 5 Jahre'!$D$27*$D7)*('GuV 5 Jahre'!$D$28+$B7)*Annahmen!$B$13*Annahmen!$D$30*$C7*12+('GuV 5 Jahre'!$D$27*$D7)*Annahmen!$D$31*Annahmen!$B$10+'GuV 5 Jahre'!$D$33 -> 346740 | I7: =G7*11.5/72 -> 9702.1667 | J7: =(H7-12*I7)/78 -> 2952.7436 | K7: =IFERROR(MATCH(1,$E$26:$AB$26,0)-1,"> 24") -> > 24 | L7: =IFERROR(MATCH(1,$E$26:$AB$26,0),"keiner") -> keiner | M7: =INDEX($E$25:$AB$25,12) -> 143759.48 | N7: =INDEX($E$25:$AB$25,18) -> 174487.45 | O7: =INDEX($E$25:$AB$25,24) -> 240885.28 | P7: =MIN($E$25:$AB$25) -> 140011.04
A8: ARPU −20 % | B8: 0 | C8: 0.8 | D8: 1 | E8: =('GuV 5 Jahre'!$E$27*$D8)*('GuV 5 Jahre'!$E$28+$B8)*Annahmen!$B$13*Annahmen!$D$30*$C8*12+('GuV 5 Jahre'!$E$27*$D8)*Annahmen!$D$31*Annahmen!$B$10+'GuV 5 Jahre'!$E$33+'GuV 5 Jahre'!$E$35 -> 885270 | F8: =E8/$E$5-1 -> -0.14736051 | G8: =('GuV 5 Jahre'!$C$27*$D8)*('GuV 5 Jahre'!$C$28+$B8)*Annahmen!$B$12*Annahmen!$D$30*$C8*12+('GuV 5 Jahre'!$C$27*$D8)*Annahmen!$D$31*Annahmen!$B$10+'GuV 5 Jahre'!$C$33 -> 42384 | H8: =('GuV 5 Jahre'!$D$27*$D8)*('GuV 5 Jahre'!$D$28+$B8)*Annahmen!$B$13*Annahmen!$D$30*$C8*12+('GuV 5 Jahre'!$D$27*$D8)*Annahmen!$D$31*Annahmen!$B$10+'GuV 5 Jahre'!$D$33 -> 236580 | I8: =G8*11.5/72 -> 6769.6667 | J8: =(H8-12*I8)/78 -> 1991.5897 | K8: =IFERROR(MATCH(1,$E$30:$AB$30,0)-1,"> 24") -> > 24 | L8: =IFERROR(MATCH(1,$E$30:$AB$30,0),"keiner") -> keiner | M8: =INDEX($E$29:$AB$29,12) -> 126868.28 | N8: =INDEX($E$29:$AB$29,18) -> 122839.35 | O8: =INDEX($E$29:$AB$29,24) -> 122646.88 | P8: =MIN($E$29:$AB$29) -> 91497.935
A9: ARPU +20 % | B9: 0 | C9: 1.2 | D9: 1 | E9: =('GuV 5 Jahre'!$E$27*$D9)*('GuV 5 Jahre'!$E$28+$B9)*Annahmen!$B$13*Annahmen!$D$30*$C9*12+('GuV 5 Jahre'!$E$27*$D9)*Annahmen!$D$31*Annahmen!$B$10+'GuV 5 Jahre'!$E$33+'GuV 5 Jahre'!$E$35 -> 1191270 | F9: =E9/$E$5-1 -> 0.14736051 | G9: =('GuV 5 Jahre'!$C$27*$D9)*('GuV 5 Jahre'!$C$28+$B9)*Annahmen!$B$12*Annahmen!$D$30*$C9*12+('GuV 5 Jahre'!$C$27*$D9)*Annahmen!$D$31*Annahmen!$B$10+'GuV 5 Jahre'!$C$33 -> 58704 | H9: =('GuV 5 Jahre'!$D$27*$D9)*('GuV 5 Jahre'!$D$28+$B9)*Annahmen!$B$13*Annahmen!$D$30*$C9*12+('GuV 5 Jahre'!$D$27*$D9)*Annahmen!$D$31*Annahmen!$B$10+'GuV 5 Jahre'!$D$33 -> 334500 | I9: =G9*11.5/72 -> 9376.3333 | J9: =(H9-12*I9)/78 -> 2845.9487 | K9: =IFERROR(MATCH(1,$E$34:$AB$34,0)-1,"> 24") -> > 24 | L9: =IFERROR(MATCH(1,$E$34:$AB$34,0),"keiner") -> keiner | M9: =INDEX($E$33:$AB$33,12) -> 141882.68 | N9: =INDEX($E$33:$AB$33,18) -> 168748.77 | O9: =INDEX($E$33:$AB$33,24) -> 227747.68 | P9: =MIN($E$33:$AB$33) -> 137239.95
A10: Nutzer −30 % | B10: 0 | C10: 1 | D10: 0.7 | E10: =('GuV 5 Jahre'!$E$27*$D10)*('GuV 5 Jahre'!$E$28+$B10)*Annahmen!$B$13*Annahmen!$D$30*$C10*12+('GuV 5 Jahre'!$E$27*$D10)*Annahmen!$D$31*Annahmen!$B$10+'GuV 5 Jahre'!$E$33+'GuV 5 Jahre'!$E$35 -> 778845 | F10: =E10/$E$5-1 -> -0.24986275 | G10: =('GuV 5 Jahre'!$C$27*$D10)*('GuV 5 Jahre'!$C$28+$B10)*Annahmen!$B$12*Annahmen!$D$30*$C10*12+('GuV 5 Jahre'!$C$27*$D10)*Annahmen!$D$31*Annahmen!$B$10+'GuV 5 Jahre'!$C$33 -> 35910 | H10: =('GuV 5 Jahre'!$D$27*$D10)*('GuV 5 Jahre'!$D$28+$B10)*Annahmen!$B$13*Annahmen!$D$30*$C10*12+('GuV 5 Jahre'!$D$27*$D10)*Annahmen!$D$31*Annahmen!$B$10+'GuV 5 Jahre'!$D$33 -> 202524 | I10: =G10*11.5/72 -> 5735.625 | J10: =(H10-12*I10)/78 -> 1714.0577 | K10: =IFERROR(MATCH(1,$E$38:$AB$38,0)-1,"> 24") -> > 24 | L10: =IFERROR(MATCH(1,$E$38:$AB$38,0),"keiner") -> keiner | M10: =INDEX($E$37:$AB$37,12) -> 120912.2 | N10: =INDEX($E$37:$AB$37,18) -> 105813.44 | O10: =INDEX($E$37:$AB$37,24) -> 85359.28 | P10: =MIN($E$37:$AB$37) -> 65490.163
A11: Nutzer +30 % | B11: 0 | C11: 1 | D11: 1.3 | E11: =('GuV 5 Jahre'!$E$27*$D11)*('GuV 5 Jahre'!$E$28+$B11)*Annahmen!$B$13*Annahmen!$D$30*$C11*12+('GuV 5 Jahre'!$E$27*$D11)*Annahmen!$D$31*Annahmen!$B$10+'GuV 5 Jahre'!$E$33+'GuV 5 Jahre'!$E$35 -> 1297695 | F11: =E11/$E$5-1 -> 0.24986275 | G11: =('GuV 5 Jahre'!$C$27*$D11)*('GuV 5 Jahre'!$C$28+$B11)*Annahmen!$B$12*Annahmen!$D$30*$C11*12+('GuV 5 Jahre'!$C$27*$D11)*Annahmen!$D$31*Annahmen!$B$10+'GuV 5 Jahre'!$C$33 -> 65178 | H11: =('GuV 5 Jahre'!$D$27*$D11)*('GuV 5 Jahre'!$D$28+$B11)*Annahmen!$B$13*Annahmen!$D$30*$C11*12+('GuV 5 Jahre'!$D$27*$D11)*Annahmen!$D$31*Annahmen!$B$10+'GuV 5 Jahre'!$D$33 -> 368556 | I11: =G11*11.5/72 -> 10410.375 | J11: =(H11-12*I11)/78 -> 3123.4808 | K11: =IFERROR(MATCH(1,$E$42:$AB$42,0)-1,"> 24") -> > 24 | L11: =IFERROR(MATCH(1,$E$42:$AB$42,0),"keiner") -> keiner | M11: =INDEX($E$41:$AB$41,12) -> 147838.76 | N11: =INDEX($E$41:$AB$41,18) -> 185774.68 | O11: =INDEX($E$41:$AB$41,24) -> 265035.28 | P11: =MIN($E$41:$AB$41) -> 145414.91
A13: Monat | E13: 1 | F13: 2 | G13: 3 | H13: 4 | I13: 5 | J13: 6 | K13: 7 | L13: 8 | M13: 9 | N13: 10 | O13: 11 | P13: 12 | Q13: 13 | R13: 14 | S13: 15 | T13: 16 | U13: 17 | V13: 18 | W13: 19 | X13: 20 | Y13: 21 | Z13: 22 | AA13: 23 | AB13: 24
A14: Fixkosten Basis (Pre-Seed + Ausbau + Infrastruktur fix) | E14: ='Liquidität 24M'!D$39+'Liquidität 24M'!D$48*Annahmen!$D$47+Annahmen!$B$7 -> 13250 | F14: ='Liquidität 24M'!E$39+'Liquidität 24M'!E$48*Annahmen!$D$47+Annahmen!$B$7 -> 5250 | G14: ='Liquidität 24M'!F$39+'Liquidität 24M'!F$48*Annahmen!$D$47+Annahmen!$B$7 -> 10750 | H14: ='Liquidität 24M'!G$39+'Liquidität 24M'!G$48*Annahmen!$D$47+Annahmen!$B$7 -> 13875 | I14: ='Liquidität 24M'!H$39+'Liquidität 24M'!H$48*Annahmen!$D$47+Annahmen!$B$7 -> 13875 | J14: ='Liquidität 24M'!I$39+'Liquidität 24M'!I$48*Annahmen!$D$47+Annahmen!$B$7 -> 13875 | K14: ='Liquidität 24M'!J$39+'Liquidität 24M'!J$48*Annahmen!$D$47+Annahmen!$B$7 -> 14875 | L14: ='Liquidität 24M'!K$39+'Liquidität 24M'!K$48*Annahmen!$D$47+Annahmen!$B$7 -> 14875 | ... AB14: ='Liquidität 24M'!AA$39+'Liquidität 24M'!AA$48*Annahmen!$D$47+Annahmen!$B$7 -> 31333.333
